Workbook

Sheet Comparison
B2: Astral · Anti-Roll Bar Stiffness | C2: Astral · Anti-Roll Bar Stiffness | D2: Astral · Anti-Roll Bar Stiffness | E2: Astral · Anti-Roll Bar Stiffness | F2: Astral · Anti-Roll Bar Stiffness | G2: Astral · Anti-Roll Bar Stiffness | H2: Astral · Anti-Roll Bar Stiffness | I2: Astral · Anti-Roll Bar Stiffness | J2: Astral · Anti-Roll Bar Stiffness | K2: Astral · Anti-Roll Bar Stiffness | L2: Astral · Anti-Roll Bar Stiffness | M2: Astral · Anti-Roll Bar Stiffness | N2: Astral · Anti-Roll Bar Stiffness
B3: Astral · Anti-Roll Bar Stiffness | C3: Astral · Anti-Roll Bar Stiffness | D3: Astral · Anti-Roll Bar Stiffness | E3: Astral · Anti-Roll Bar Stiffness | F3: Astral · Anti-Roll Bar Stiffness | G3: Astral · Anti-Roll Bar Stiffness | H3: Astral · Anti-Roll Bar Stiffness | I3: Astral · Anti-Roll Bar Stiffness | J3: Astral · Anti-Roll Bar Stiffness | K3: Astral · Anti-Roll Bar Stiffness | L3: Astral · Anti-Roll Bar Stiffness | M3: Astral · Anti-Roll Bar Stiffness | N3: Astral · Anti-Roll Bar Stiffness
B4: 区间等效轮端刚度 · 整段角运动比 · 对侧轮固定 | C4: 区间等效轮端刚度 · 整段角运动比 · 对侧轮固定 | D4: 区间等效轮端刚度 · 整段角运动比 · 对侧轮固定 | E4: 区间等效轮端刚度 · 整段角运动比 · 对侧轮固定 | F4: 区间等效轮端刚度 · 整段角运动比 · 对侧轮固定 | G4: 区间等效轮端刚度 · 整段角运动比 · 对侧轮固定 | H4: 区间等效轮端刚度 · 整段角运动比 · 对侧轮固定 | I4: 区间等效轮端刚度 · 整段角运动比 · 对侧轮固定 | J4: 区间等效轮端刚度 · 整段角运动比 · 对侧轮固定 | K4: 区间等效轮端刚度 · 整段角运动比 · 对侧轮固定 | L4: 区间等效轮端刚度 · 整段角运动比 · 对侧轮固定 | M4: 区间等效轮端刚度 · 整段角运动比 · 对侧轮固定 | N4: 区间等效轮端刚度 · 整段角运动比 · 对侧轮固定
B5: =IF(COUNT(Samples!H6:J17)=0,"待补节点坐标；暂无刚度结果。","")
B49: 整段角运动比换算值；不代表行程内每一位置的瞬时刚度。 | C49: 整段角运动比换算值；不代表行程内每一位置的瞬时刚度。 | D49: 整段角运动比换算值；不代表行程内每一位置的瞬时刚度。 | E49: 整段角运动比换算值；不代表行程内每一位置的瞬时刚度。 | F49: 整段角运动比换算值；不代表行程内每一位置的瞬时刚度。 | G49: 整段角运动比换算值；不代表行程内每一位置的瞬时刚度。 | H49: 整段角运动比换算值；不代表行程内每一位置的瞬时刚度。 | I49: 整段角运动比换算值；不代表行程内每一位置的瞬时刚度。 | J49: 整段角运动比换算值；不代表行程内每一位置的瞬时刚度。 | K49: 整段角运动比换算值；不代表行程内每一位置的瞬时刚度。 | L49: 整段角运动比换算值；不代表行程内每一位置的瞬时刚度。 | M49: 整段角运动比换算值；不代表行程内每一位置的瞬时刚度。 | N49: 整段角运动比换算值；不代表行程内每一位置的瞬时刚度。

Sheet Parameters
B2: Astral · ARB Parameters | C2: Astral · ARB Parameters | D2: Astral · ARB Parameters | E2: Astral · ARB Parameters | F2: Astral · ARB Parameters | G2: Astral · ARB Parameters | H2: Astral · ARB Parameters | I2: Astral · ARB Parameters
B3: Astral · ARB Parameters | C3: Astral · ARB Parameters | D3: Astral · ARB Parameters | E3: Astral · ARB Parameters | F3: Astral · ARB Parameters | G3: Astral · ARB Parameters | H3: Astral · ARB Parameters | I3: Astral · ARB Parameters
B4: 黄色单元格为手动输入。 | C4: 黄色单元格为手动输入。 | D4: 黄色单元格为手动输入。 | E4: 黄色单元格为手动输入。 | F4: 黄色单元格为手动输入。 | G4: 黄色单元格为手动输入。 | H4: 黄色单元格为手动输入。 | I4: 黄色单元格为手动输入。
B6: Axle | C6: Bar | D6: Diameter (mm) | E6: Torsion (N·m/rad)
B7: Front | C7: #1 | D7: 14.6 | E7: =$E$8*(D7/$D$8)^4 -> 941.40637
B8: Front | C8: #2 | D8: 17.6 | E8: 1988
B9: Front | C9: #3 | D9: 20.5 | E9: =$E$8*(D9/$D$8)^4 -> 3659.1579
B10: Rear | C10: #1 | D10: 16.2 | E10: =$E$8*(D10/$D$8)^4 -> 1427.0059
B11: Rear | C11: #2 | D11: 19.4 | E11: =$E$8*(D11/$D$8)^4 -> 2934.7603
B12: Rear | C12: #3 | D12: 22.1 | E12: =$E$8*(D12/$D$8)^4 -> 4942.3649
B14: 固定转轴 | C14: 固定几何 · 生成位置 / 转轴 | D14: 固定几何 · 生成位置 / 转轴 | E14: 固定几何 · 生成位置 / 转轴 | F14: 固定几何 · 生成位置 / 转轴 | G14: 固定几何 · 生成位置 / 转轴 | H14: 固定几何 · 生成位置 / 转轴 | I14: 固定几何 · 生成位置 / 转轴
B15: 节点使用车身相对坐标（m）。 | C15: 节点使用车身相对坐标（m）；旋转半径按 Y/Z 计算。 | D15: 节点使用车身相对坐标（m）；旋转半径按 Y/Z 计算。 | E15: 节点使用车身相对坐标（m）；旋转半径按 Y/Z 计算。 | F15: 节点使用车身相对坐标（m）；旋转半径按 Y/Z 计算。 | G15: 节点使用车身相对坐标（m）；旋转半径按 Y/Z 计算。 | H15: 节点使用车身相对坐标（m）；旋转半径按 Y/Z 计算。 | I15: 节点使用车身相对坐标（m）；旋转半径按 Y/Z 计算。
B16: Axle | C16: arb2 Y (m) | D16: arb2 Z (m)
B17: Front | C17: -0.915 | D17: 0.127
B18: Rear | C18: 1.459 | D18: 0.26
B20: 测量 · 各档起点 / 终点 | C20: 测量 · 每组填写轮行程和 arb1 终点 | D20: 测量 · 每组填写轮行程和 arb1 终点 | E20: 测量 · 每组填写轮行程和 arb1 终点 | F20: 测量 · 每组填写轮行程和 arb1 终点 | G20: 测量 · 每组填写轮行程和 arb1 终点 | H20: 测量 · 每组填写轮行程和 arb1 终点 | I20: 测量 · 每组填写轮行程和 arb1 终点
B21: 起点为 wheeljack 架起、全伸展稳定后的位置；轮行程从同一起点计算。
B22: Surface | C22: Axle | D22: Position | E22: Wheel ΔZ (mm) | F22: arb1 Start Y (m) | G22: arb1 Start Z (m) | H22: arb1 End Y (m) | I22: arb1 End Z (m)
B23: Tarmac | C23: Front | D23: L | E23: 167
B24: Tarmac | C24: Front | D24: M | E24: 167
B25: Tarmac | C25: Front | D25: H | E25: 167
B26: Tarmac | C26: Rear | D26: L | E26: 166
B27: Tarmac | C27: Rear | D27: M | E27: 166
B28: Tarmac | C28: Rear | D28: H | E28: 166
B29: Gravel | C29: Front | D29: L | E29: 259 | F29: -1.084 | G29: 0.161 | H29: -1.034 | I29: 0.252
B30: Gravel | C30: Front | D30: M | E30: 259 | F30: -1.069 | G30: 0.156 | H30: -1.023 | I30: 0.241
B31: Gravel | C31: Front | D31: H | E31: 259 | F31: -1.055 | G31: 0.149 | H31: -1.013 | I31: 0.23
B32: Gravel | C32: Rear | D32: L | E32: 252 | F32: 1.306 | G32: 0.208 | H32: 1.309 | I32: 0.319
B33: Gravel | C33: Rear | D33: M | E33: 252 | F33: 1.322 | G33: 0.208 | H33: 1.326 | I33: 0.319
B34: Gravel | C34: Rear | D34: H | E34: 252 | F34: 1.339 | G34: 0.206 | H34: 1.342 | I34: 0.318
B38: 原 Z 测量记录（不参与刚度计算） | C38: 原 Z 测量记录（不参与刚度计算） | D38: 原 Z 测量记录（不参与刚度计算） | E38: 原 Z 测量记录（不参与刚度计算） | F38: 原 Z 测量记录（不参与刚度计算） | G38: 原 Z 测量记录（不参与刚度计算） | H38: 原 Z 测量记录（不参与刚度计算） | I38: 原 Z 测量记录（不参与刚度计算）
B39: Surface | C39: Axle | D39: Position | E39: ARB ΔZ (mm) | F39: Original arm (mm)
B40: Tarmac | C40: Front | D40: L | E40: 35 | F40: 163
B41: Tarmac | C41: Front | D41: M | E41: 42 | F41: 163
B42: Tarmac | C42: Front | D42: H | E42: 46 | F42: 163
B43: Tarmac | C43: Rear | D43: L | E43: 41 | F43: 154
B44: Tarmac | C44: Rear | D44: M | E44: 49 | F44: 154
B45: Tarmac | C45: Rear | D45: H | E45: 54 | F45: 154
B46: Gravel | C46: Front | D46: L | E46: 32 | F46: 163
B47: Gravel | C47: Front | D47: M | E47: 40 | F47: 163
...

Sheet Samples
B2: Astral · ARB Calculations | C2: Astral · ARB Calculations | D2: Astral · ARB Calculations | E2: Astral · ARB Calculations | F2: Astral · ARB Calculations | G2: Astral · ARB Calculations | H2: Astral · ARB Calculations | I2: Astral · ARB Calculations | J2: Astral · ARB Calculations | K2: Astral · ARB Calculations
B3: Astral · ARB Calculations | C3: Astral · ARB Calculations | D3: Astral · ARB Calculations | E3: Astral · ARB Calculations | F3: Astral · ARB Calculations | G3: Astral · ARB Calculations | H3: Astral · ARB Calculations | I3: Astral · ARB Calculations | J3: Astral · ARB Calculations | K3: Astral · ARB Calculations
B5: Surface | C5: Axle | D5: Position | E5: Wheel ΔZ (mm) | F5: Arm Δθ (°) | G5: Angular MR (rad/mm) | H5: #1 (N/mm) | I5: #2 (N/mm) | J5: #3 (N/mm) | K5: Input | L5: Start angle (°) | M5: End angle (°) | N5: Start radius (mm) | O5: End radius (mm)
B6: Tarmac | C6: Front | D6: L | E6: =IF(ISNUMBER(Parameters!E23),Parameters!E23,"") -> 167 | F6: =IF(COUNT(L6:M6)<2,"",MOD(M6-L6+180,360)-180) | G6: =IF(COUNT(E6:F6)<2,"",IF(E6<=0,"",RADIANS(F6)/E6)) | H6: =IF(ISNUMBER(G6),1000*Parameters!E7*G6^2,"") | I6: =IF(ISNUMBER(G6),1000*Parameters!E8*G6^2,"") | J6: =IF(ISNUMBER(G6),1000*Parameters!E9*G6^2,"") | K6: =IF(COUNT(Parameters!C17:D17,Parameters!F23:I23)<6,"待补坐标",IF(NOT(ISNUMBER(E6)),"待填轮行程",IF(E6<=0,"轮行程须大于0",IF(COUNT(L6:M6)<2,"无效半径","")))) -> 待补坐标 | L6: =IF(COUNT(Parameters!F23,Parameters!G23,Parameters!C17,Parameters!D17)<4,"",IF(N6=0,"",IF(Parameters!G23<Parameters!D17,-1,1)*DEGREES(ACOS(MAX(-1,MIN(1,(Parameters!C17-Parameters!F23)*1000/N6)))))) | M6: =IF(COUNT(Parameters!H23,Parameters!I23,Parameters!C17,Parameters!D17)<4,"",IF(O6=0,"",IF(Parameters!I23<Parameters!D17,-1,1)*DEGREES(ACOS(MAX(-1,MIN(1,(Parameters!C17-Parameters!H23)*1000/O6)))))) | N6: =IF(COUNT(Parameters!F23,Parameters!G23,Parameters!C17,Parameters!D17)<4,"",1000*SQRT((Parameters!F23-Parameters!C17)^2+(Parameters!G23-Parameters!D17)^2)) | O6: =IF(COUNT(Parameters!H23,Parameters!I23,Parameters!C17,Parameters!D17)<4,"",1000*SQRT((Parameters!H23-Parameters!C17)^2+(Parameters!I23-Parameters!D17)^2))
B7: Tarmac | C7: Front | D7: M | E7: =IF(ISNUMBER(Parameters!E24),Parameters!E24,"") -> 167 | F7: =IF(COUNT(L7:M7)<2,"",MOD(M7-L7+180,360)-180) | G7: =IF(COUNT(E7:F7)<2,"",IF(E7<=0,"",RADIANS(F7)/E7)) | H7: =IF(ISNUMBER(G7),1000*Parameters!E7*G7^2,"") | I7: =IF(ISNUMBER(G7),1000*Parameters!E8*G7^2,"") | J7: =IF(ISNUMBER(G7),1000*Parameters!E9*G7^2,"") | K7: =IF(COUNT(Parameters!C17:D17,Parameters!F24:I24)<6,"待补坐标",IF(NOT(ISNUMBER(E7)),"待填轮行程",IF(E7<=0,"轮行程须大于0",IF(COUNT(L7:M7)<2,"无效半径","")))) -> 待补坐标 | L7: =IF(COUNT(Parameters!F24,Parameters!G24,Parameters!C17,Parameters!D17)<4,"",IF(N7=0,"",IF(Parameters!G24<Parameters!D17,-1,1)*DEGREES(ACOS(MAX(-1,MIN(1,(Parameters!C17-Parameters!F24)*1000/N7)))))) | M7: =IF(COUNT(Parameters!H24,Parameters!I24,Parameters!C17,Parameters!D17)<4,"",IF(O7=0,"",IF(Parameters!I24<Parameters!D17,-1,1)*DEGREES(ACOS(MAX(-1,MIN(1,(Parameters!C17-Parameters!H24)*1000/O7)))))) | N7: =IF(COUNT(Parameters!F24,Parameters!G24,Parameters!C17,Parameters!D17)<4,"",1000*SQRT((Parameters!F24-Parameters!C17)^2+(Parameters!G24-Parameters!D17)^2)) | O7: =IF(COUNT(Parameters!H24,Parameters!I24,Parameters!C17,Parameters!D17)<4,"",1000*SQRT((Parameters!H24-Parameters!C17)^2+(Parameters!I24-Parameters!D17)^2))
B8: Tarmac | C8: Front | D8: H | E8: =IF(ISNUMBER(Parameters!E25),Parameters!E25,"") -> 167 | F8: =IF(COUNT(L8:M8)<2,"",MOD(M8-L8+180,360)-180) | G8: =IF(COUNT(E8:F8)<2,"",IF(E8<=0,"",RADIANS(F8)/E8)) | H8: =IF(ISNUMBER(G8),1000*Parameters!E7*G8^2,"") | I8: =IF(ISNUMBER(G8),1000*Parameters!E8*G8^2,"") | J8: =IF(ISNUMBER(G8),1000*Parameters!E9*G8^2,"") | K8: =IF(COUNT(Parameters!C17:D17,Parameters!F25:I25)<6,"待补坐标",IF(NOT(ISNUMBER(E8)),"待填轮行程",IF(E8<=0,"轮行程须大于0",IF(COUNT(L8:M8)<2,"无效半径","")))) -> 待补坐标 | L8: =IF(COUNT(Parameters!F25,Parameters!G25,Parameters!C17,Parameters!D17)<4,"",IF(N8=0,"",IF(Parameters!G25<Parameters!D17,-1,1)*DEGREES(ACOS(MAX(-1,MIN(1,(Parameters!C17-Parameters!F25)*1000/N8)))))) | M8: =IF(COUNT(Parameters!H25,Parameters!I25,Parameters!C17,Parameters!D17)<4,"",IF(O8=0,"",IF(Parameters!I25<Parameters!D17,-1,1)*DEGREES(ACOS(MAX(-1,MIN(1,(Parameters!C17-Parameters!H25)*1000/O8)))))) | N8: =IF(COUNT(Parameters!F25,Parameters!G25,Parameters!C17,Parameters!D17)<4,"",1000*SQRT((Parameters!F25-Parameters!C17)^2+(Parameters!G25-Parameters!D17)^2)) | O8: =IF(COUNT(Parameters!H25,Parameters!I25,Parameters!C17,Parameters!D17)<4,"",1000*SQRT((Parameters!H25-Parameters!C17)^2+(Parameters!I25-Parameters!D17)^2))
B9: Tarmac | C9: Rear | D9: L | E9: =IF(ISNUMBER(Parameters!E26),Parameters!E26,"") -> 166 | F9: =IF(COUNT(L9:M9)<2,"",MOD(M9-L9+180,360)-180) | G9: =IF(COUNT(E9:F9)<2,"",IF(E9<=0,"",RADIANS(F9)/E9)) | H9: =IF(ISNUMBER(G9),1000*Parameters!E10*G9^2,"") | I9: =IF(ISNUMBER(G9),1000*Parameters!E11*G9^2,"") | J9: =IF(ISNUMBER(G9),1000*Parameters!E12*G9^2,"") | K9: =IF(COUNT(Parameters!C18:D18,Parameters!F26:I26)<6,"待补坐标",IF(NOT(ISNUMBER(E9)),"待填轮行程",IF(E9<=0,"轮行程须大于0",IF(COUNT(L9:M9)<2,"无效半径","")))) -> 待补坐标 | L9: =IF(COUNT(Parameters!F26,Parameters!G26,Parameters!C18,Parameters!D18)<4,"",IF(N9=0,"",IF(Parameters!G26<Parameters!D18,-1,1)*DEGREES(ACOS(MAX(-1,MIN(1,(Parameters!C18-Parameters!F26)*1000/N9)))))) | M9: =IF(COUNT(Parameters!H26,Parameters!I26,Parameters!C18,Parameters!D18)<4,"",IF(O9=0,"",IF(Parameters!I26<Parameters!D18,-1,1)*DEGREES(ACOS(MAX(-1,MIN(1,(Parameters!C18-Parameters!H26)*1000/O9)))))) | N9: =IF(COUNT(Parameters!F26,Parameters!G26,Parameters!C18,Parameters!D18)<4,"",1000*SQRT((Parameters!F26-Parameters!C18)^2+(Parameters!G26-Parameters!D18)^2)) | O9: =IF(COUNT(Parameters!H26,Parameters!I26,Parameters!C18,Parameters!D18)<4,"",1000*SQRT((Parameters!H26-Parameters!C18)^2+(Parameters!I26-Parameters!D18)^2))
B10: Tarmac | C10: Rear | D10: M | E10: =IF(ISNUMBER(Parameters!E27),Parameters!E27,"") -> 166 | F10: =IF(COUNT(L10:M10)<2,"",MOD(M10-L10+180,360)-180) | G10: =IF(COUNT(E10:F10)<2,"",IF(E10<=0,"",RADIANS(F10)/E10)) | H10: =IF(ISNUMBER(G10),1000*Parameters!E10*G10^2,"") | I10: =IF(ISNUMBER(G10),1000*Parameters!E11*G10^2,"") | J10: =IF(ISNUMBER(G10),1000*Parameters!E12*G10^2,"") | K10: =IF(COUNT(Parameters!C18:D18,Parameters!F27:I27)<6,"待补坐标",IF(NOT(ISNUMBER(E10)),"待填轮行程",IF(E10<=0,"轮行程须大于0",IF(COUNT(L10:M10)<2,"无效半径","")))) -> 待补坐标 | L10: =IF(COUNT(Parameters!F27,Parameters!G27,Parameters!C18,Parameters!D18)<4,"",IF(N10=0,"",IF(Parameters!G27<Parameters!D18,-1,1)*DEGREES(ACOS(MAX(-1,MIN(1,(Parameters!C18-Parameters!F27)*1000/N10)))))) | M10: =IF(COUNT(Parameters!H27,Parameters!I27,Parameters!C18,Parameters!D18)<4,"",IF(O10=0,"",IF(Parameters!I27<Parameters!D18,-1,1)*DEGREES(ACOS(MAX(-1,MIN(1,(Parameters!C18-Parameters!H27)*1000/O10)))))) | N10: =IF(COUNT(Parameters!F27,Parameters!G27,Parameters!C18,Parameters!D18)<4,"",1000*SQRT((Parameters!F27-Parameters!C18)^2+(Parameters!G27-Parameters!D18)^2)) | O10: =IF(COUNT(Parameters!H27,Parameters!I27,Parameters!C18,Parameters!D18)<4,"",1000*SQRT((Parameters!H27-Parameters!C18)^2+(Parameters!I27-Parameters!D18)^2))
B11: Tarmac | C11: Rear | D11: H | E11: =IF(ISNUMBER(Parameters!E28),Parameters!E28,"") -> 166 | F11: =IF(COUNT(L11:M11)<2,"",MOD(M11-L11+180,360)-180) | G11: =IF(COUNT(E11:F11)<2,"",IF(E11<=0,"",RADIANS(F11)/E11)) | H11: =IF(ISNUMBER(G11),1000*Parameters!E10*G11^2,"") | I11: =IF(ISNUMBER(G11),1000*Parameters!E11*G11^2,"") | J11: =IF(ISNUMBER(G11),1000*Parameters!E12*G11^2,"") | K11: =IF(COUNT(Parameters!C18:D18,Parameters!F28:I28)<6,"待补坐标",IF(NOT(ISNUMBER(E11)),"待填轮行程",IF(E11<=0,"轮行程须大于0",IF(COUNT(L11:M11)<2,"无效半径","")))) -> 待补坐标 | L11: =IF(COUNT(Parameters!F28,Parameters!G28,Parameters!C18,Parameters!D18)<4,"",IF(N11=0,"",IF(Parameters!G28<Parameters!D18,-1,1)*DEGREES(ACOS(MAX(-1,MIN(1,(Parameters!C18-Parameters!F28)*1000/N11)))))) | M11: =IF(COUNT(Parameters!H28,Parameters!I28,Parameters!C18,Parameters!D18)<4,"",IF(O11=0,"",IF(Parameters!I28<Parameters!D18,-1,1)*DEGREES(ACOS(MAX(-1,MIN(1,(Parameters!C18-Parameters!H28)*1000/O11)))))) | N11: =IF(COUNT(Parameters!F28,Parameters!G28,Parameters!C18,Parameters!D18)<4,"",1000*SQRT((Parameters!F28-Parameters!C18)^2+(Parameters!G28-Parameters!D18)^2)) | O11: =IF(COUNT(Parameters!H28,Parameters!I28,Parameters!C18,Parameters!D18)<4,"",1000*SQRT((Parameters!H28-Parameters!C18)^2+(Parameters!I28-Parameters!D18)^2))
B12: Gravel | C12: Front | D12: L | E12: =IF(ISNUMBER(Parameters!E29),Parameters!E29,"") -> 259 | F12: =IF(COUNT(L12:M12)<2,"",MOD(M12-L12+180,360)-180) -> 35.033513 | G12: =IF(COUNT(E12:F12)<2,"",IF(E12<=0,"",RADIANS(F12)/E12)) -> 0.0023608114 | H12: =IF(ISNUMBER(G12),1000*Parameters!E7*G12^2,"") -> 5.246863 | I12: =IF(ISNUMBER(G12),1000*Parameters!E8*G12^2,"") -> 11.07998 | J12: =IF(ISNUMBER(G12),1000*Parameters!E9*G12^2,"") -> 20.394063 | K12: =IF(COUNT(Parameters!C17:D17,Parameters!F29:I29)<6,"待补坐标",IF(NOT(ISNUMBER(E12)),"待填轮行程",IF(E12<=0,"轮行程须大于0",IF(COUNT(L12:M12)<2,"无效半径","")))) | L12: =IF(COUNT(Parameters!F29,Parameters!G29,Parameters!C17,Parameters!D17)<4,"",IF(N12=0,"",IF(Parameters!G29<Parameters!D17,-1,1)*DEGREES(ACOS(MAX(-1,MIN(1,(Parameters!C17-Parameters!F29)*1000/N12)))))) -> 11.375115 | M12: =IF(COUNT(Parameters!H29,Parameters!I29,Parameters!C17,Parameters!D17)<4,"",IF(O12=0,"",IF(Parameters!I29<Parameters!D17,-1,1)*DEGREES(ACOS(MAX(-1,MIN(1,(Parameters!C17-Parameters!H29)*1000/O12)))))) -> 46.408629 | N12: =IF(COUNT(Parameters!F29,Parameters!G29,Parameters!C17,Parameters!D17)<4,"",1000*SQRT((Parameters!F29-Parameters!C17)^2+(Parameters!G29-Parameters!D17)^2)) -> 172.38619 | O12: =IF(COUNT(Parameters!H29,Parameters!I29,Parameters!C17,Parameters!D17)<4,"",1000*SQRT((Parameters!H29-Parameters!C17)^2+(Parameters!I29-Parameters!D17)^2)) -> 172.58621
B13: Gravel | C13: Front | D13: M | E13: =IF(ISNUMBER(Parameters!E30),Parameters!E30,"") -> 259 | F13: =IF(COUNT(L13:M13)<2,"",MOD(M13-L13+180,360)-180) -> 35.883582 | G13: =IF(COUNT(E13:F13)<2,"",IF(E13<=0,"",RADIANS(F13)/E13)) -> 0.0024180952 | H13: =IF(ISNUMBER(G13),1000*Parameters!E7*G13^2,"") -> 5.5045766 | I13: =IF(ISNUMBER(G13),1000*Parameters!E8*G13^2,"") -> 11.624203 | J13: =IF(ISNUMBER(G13),1000*Parameters!E9*G13^2,"") -> 21.395771 | K13: =IF(COUNT(Parameters!C17:D17,Parameters!F30:I30)<6,"待补坐标",IF(NOT(ISNUMBER(E13)),"待填轮行程",IF(E13<=0,"轮行程须大于0",IF(COUNT(L13:M13)<2,"无效半径","")))) | L13: =IF(COUNT(Parameters!F30,Parameters!G30,Parameters!C17,Parameters!D17)<4,"",IF(N13=0,"",IF(Parameters!G30<Parameters!D17,-1,1)*DEGREES(ACOS(MAX(-1,MIN(1,(Parameters!C17-Parameters!F30)*1000/N13)))))) -> 10.664576 | M13: =IF(COUNT(Parameters!H30,Parameters!I30,Parameters!C17,Parameters!D17)<4,"",IF(O13=0,"",IF(Parameters!I30<Parameters!D17,-1,1)*DEGREES(ACOS(MAX(-1,MIN(1,(Parameters!C17-Parameters!H30)*1000/O13)))))) -> 46.548158 | N13: =IF(COUNT(Parameters!F30,Parameters!G30,Parameters!C17,Parameters!D17)<4,"",1000*SQRT((Parameters!F30-Parameters!C17)^2+(Parameters!G30-Parameters!D17)^2)) -> 156.70673 | O13: =IF(COUNT(Parameters!H30,Parameters!I30,Parameters!C17,Parameters!D17)<4,"",1000*SQRT((Parameters!H30-Parameters!C17)^2+(Parameters!I30-Parameters!D17)^2)) -> 157.03503
B14: Gravel | C14: Front | D14: H | E14: =IF(ISNUMBER(Parameters!E31),Parameters!E31,"") -> 259 | F14: =IF(COUNT(L14:M14)<2,"",MOD(M14-L14+180,360)-180) -> 37.494384 | G14: =IF(COUNT(E14:F14)<2,"",IF(E14<=0,"",RADIANS(F14)/E14)) -> 0.0025266427 | H14: =IF(ISNUMBER(G14),1000*Parameters!E7*G14^2,"") -> 6.009866 | I14: =IF(ISNUMBER(G14),1000*Parameters!E8*G14^2,"") -> 12.691239 | J14: =IF(ISNUMBER(G14),1000*Parameters!E9*G14^2,"") -> 23.359783 | K14: =IF(COUNT(Parameters!C17:D17,Parameters!F31:I31)<6,"待补坐标",IF(NOT(ISNUMBER(E14)),"待填轮行程",IF(E14<=0,"轮行程须大于0",IF(COUNT(L14:M14)<2,"无效半径","")))) | L14: =IF(COUNT(Parameters!F31,Parameters!G31,Parameters!C17,Parameters!D17)<4,"",IF(N14=0,"",IF(Parameters!G31<Parameters!D17,-1,1)*DEGREES(ACOS(MAX(-1,MIN(1,(Parameters!C17-Parameters!F31)*1000/N14)))))) -> 8.9305901 | M14: =IF(COUNT(Parameters!H31,Parameters!I31,Parameters!C17,Parameters!D17)<4,"",IF(O14=0,"",IF(Parameters!I31<Parameters!D17,-1,1)*DEGREES(ACOS(MAX(-1,MIN(1,(Parameters!C17-Parameters!H31)*1000/O14)))))) -> 46.424974 | N14: =IF(COUNT(Parameters!F31,Parameters!G31,Parameters!C17,Parameters!D17)<4,"",1000*SQRT((Parameters!F31-Parameters!C17)^2+(Parameters!G31-Parameters!D17)^2)) -> 141.71803 | O14: =IF(COUNT(Parameters!H31,Parameters!I31,Parameters!C17,Parameters!D17)<4,"",1000*SQRT((Parameters!H31-Parameters!C17)^2+(Parameters!I31-Parameters!D17)^2)) -> 142.17243
B15: Gravel | C15: Rear | D15: L | E15: =IF(ISNUMBER(Parameters!E32),Parameters!E32,"") -> 252 | F15: =IF(COUNT(L15:M15)<2,"",MOD(M15-L15+180,360)-180) -> 40.242688 | G15: =IF(COUNT(E15:F15)<2,"",IF(E15<=0,"",RADIANS(F15)/E15)) -> 0.0027871722 | H15: =IF(ISNUMBER(G15),1000*Parameters!E10*G15^2,"") -> 11.085451 | I15: =IF(ISNUMBER(G15),1000*Parameters!E11*G15^2,"") -> 22.798183 | J15: =IF(ISNUMBER(G15),1000*Parameters!E12*G15^2,"") -> 38.393916 | K15: =IF(COUNT(Parameters!C18:D18,Parameters!F32:I32)<6,"待补坐标",IF(NOT(ISNUMBER(E15)),"待填轮行程",IF(E15<=0,"轮行程须大于0",IF(COUNT(L15:M15)<2,"无效半径","")))) | L15: =IF(COUNT(Parameters!F32,Parameters!G32,Parameters!C18,Parameters!D18)<4,"",IF(N15=0,"",IF(Parameters!G32<Parameters!D18,-1,1)*DEGREES(ACOS(MAX(-1,MIN(1,(Parameters!C18-Parameters!F32)*1000/N15)))))) -> -18.771319 | M15: =IF(COUNT(Parameters!H32,Parameters!I32,Parameters!C18,Parameters!D18)<4,"",IF(O15=0,"",IF(Parameters!I32<Parameters!D18,-1,1)*DEGREES(ACOS(MAX(-1,MIN(1,(Parameters!C18-Parameters!H32)*1000/O15)))))) -> 21.471368 | N15: =IF(COUNT(Parameters!F32,Parameters!G32,Parameters!C18,Parameters!D18)<4,"",1000*SQRT((Parameters!F32-Parameters!C18)^2+(Parameters!G32-Parameters!D18)^2)) -> 161.59517 | O15: =IF(COUNT(Parameters!H32,Parameters!I32,Parameters!C18,Parameters!D18)<4,"",1000*SQRT((Parameters!H32-Parameters!C18)^2+(Parameters!I32-Parameters!D18)^2)) -> 161.18623
B16: Gravel | C16: Rear | D16: M | E16: =IF(ISNUMBER(Parameters!E33),Parameters!E33,"") -> 252 | F16: =IF(COUNT(L16:M16)<2,"",MOD(M16-L16+180,360)-180) -> 44.707367 | G16: =IF(COUNT(E16:F16)<2,"",IF(E16<=0,"",RADIANS(F16)/E16)) -> 0.0030963919 | H16: =IF(ISNUMBER(G16),1000*Parameters!E10*G16^2,"") -> 13.681623 | I16: =IF(ISNUMBER(G16),1000*Parameters!E11*G16^2,"") -> 28.137433 | J16: =IF(ISNUMBER(G16),1000*Parameters!E12*G16^2,"") -> 47.385628 | K16: =IF(COUNT(Parameters!C18:D18,Parameters!F33:I33)<6,"待补坐标",IF(NOT(ISNUMBER(E16)),"待填轮行程",IF(E16<=0,"轮行程须大于0",IF(COUNT(L16:M16)<2,"无效半径","")))) | L16: =IF(COUNT(Parameters!F33,Parameters!G33,Parameters!C18,Parameters!D18)<4,"",IF(N16=0,"",IF(Parameters!G33<Parameters!D18,-1,1)*DEGREES(ACOS(MAX(-1,MIN(1,(Parameters!C18-Parameters!F33)*1000/N16)))))) -> -20.784861 | M16: =IF(COUNT(Parameters!H33,Parameters!I33,Parameters!C18,Parameters!D18)<4,"",IF(O16=0,"",IF(Parameters!I33<Parameters!D18,-1,1)*DEGREES(ACOS(MAX(-1,MIN(1,(Parameters!C18-Parameters!H33)*1000/O16)))))) -> 23.922506 | N16: =IF(COUNT(Parameters!F33,Parameters!G33,Parameters!C18,Parameters!D18)<4,"",1000*SQRT((Parameters!F33-Parameters!C18)^2+(Parameters!G33-Parameters!D18)^2)) -> 146.53668 | O16: =IF(COUNT(Parameters!H33,Parameters!I33,Parameters!C18,Parameters!D18)<4,"",1000*SQRT((Parameters!H33-Parameters!C18)^2+(Parameters!I33-Parameters!D18)^2)) -> 145.49914
B17: Gravel | C17: Rear | D17: H | E17: =IF(ISNUMBER(Parameters!E34),Parameters!E34,"") -> 252 | F17: =IF(COUNT(L17:M17)<2,"",MOD(M17-L17+180,360)-180) -> 50.596579 | G17: =IF(COUNT(E17:F17)<2,"",IF(E17<=0,"",RADIANS(F17)/E17)) -> 0.0035042734 | H17: =IF(ISNUMBER(G17),1000*Parameters!E10*G17^2,"") -> 17.523535 | I17: =IF(ISNUMBER(G17),1000*Parameters!E11*G17^2,"") -> 36.038656 | J17: =IF(ISNUMBER(G17),1000*Parameters!E12*G17^2,"") -> 60.691904 | K17: =IF(COUNT(Parameters!C18:D18,Parameters!F34:I34)<6,"待补坐标",IF(NOT(ISNUMBER(E17)),"待填轮行程",IF(E17<=0,"轮行程须大于0",IF(COUNT(L17:M17)<2,"无效半径","")))) | L17: =IF(COUNT(Parameters!F34,Parameters!G34,Parameters!C18,Parameters!D18)<4,"",IF(N17=0,"",IF(Parameters!G34<Parameters!D18,-1,1)*DEGREES(ACOS(MAX(-1,MIN(1,(Parameters!C18-Parameters!F34)*1000/N17)))))) -> -24.227745 | M17: =IF(COUNT(Parameters!H34,Parameters!I34,Parameters!C18,Parameters!D18)<4,"",IF(O17=0,"",IF(Parameters!I34<Parameters!D18,-1,1)*DEGREES(ACOS(MAX(-1,MIN(1,(Parameters!C18-Parameters!H34)*1000/O17)))))) -> 26.368834 | N17: =IF(COUNT(Parameters!F34,Parameters!G34,Parameters!C18,Parameters!D18)<4,"",1000*SQRT((Parameters!F34-Parameters!C18)^2+(Parameters!G34-Parameters!D18)^2)) -> 131.59027 | O17: =IF(COUNT(Parameters!H34,Parameters!I34,Parameters!C18,Parameters!D18)<4,"",1000*SQRT((Parameters!H34-Parameters!C18)^2+(Parameters!I34-Parameters!D18)^2)) -> 130.58714
B22: Setting | C22: Front | D22: Rear
B23: #1 L | C23: =IF(ISNUMBER(H12),H12,NA()) -> 5.246863 | D23: =IF(ISNUMBER(H15),H15,NA()) -> 11.085451
B24: #1 M | C24: =IF(ISNUMBER(H13),H13,NA()) -> 5.5045766 | D24: =IF(ISNUMBER(H16),H16,NA()) -> 13.681623
B25: #1 H | C25: =IF(ISNUMBER(H14),H14,NA()) -> 6.009866 | D25: =IF(ISNUMBER(H17),H17,NA()) -> 17.523535
B26: #2 L | C26: =IF(ISNUMBER(I12),I12,NA()) -> 11.07998 | D26: =IF(ISNUMBER(I15),I15,NA()) -> 22.798183
B27: #2 M | C27: =IF(ISNUMBER(I13),I13,NA()) -> 11.624203 | D27: =IF(ISNUMBER(I16),I16,NA()) -> 28.137433
B28: #2 H | C28: =IF(ISNUMBER(I14),I14,NA()) -> 12.691239 | D28: =IF(ISNUMBER(I17),I17,NA()) -> 36.038656
B29: #3 L | C29: =IF(ISNUMBER(J12),J12,NA()) -> 20.394063 | D29: =IF(ISNUMBER(J15),J15,NA()) -> 38.393916
B30: #3 M | C30: =IF(ISNUMBER(J13),J13,NA()) -> 21.395771 | D30: =IF(ISNUMBER(J16),J16,NA()) -> 47.385628
B31: #3 H | C31: =IF(ISNUMBER(J14),J14,NA()) -> 23.359783 | D31: =IF(ISNUMBER(J17),J17,NA()) -> 60.691904
B35: Setting | C35: Front | D35: Rear
B36: #1 L | C36: =IF(ISNUMBER(H6),H6,NA()) -> #N/A | D36: =IF(ISNUMBER(H9),H9,NA()) -> #N/A
B37: #1 M | C37: =IF(ISNUMBER(H7),H7,NA()) -> #N/A | D37: =IF(ISNUMBER(H10),H10,NA()) -> #N/A
B38: #1 H | C38: =IF(ISNUMBER(H8),H8,NA()) -> #N/A | D38: =IF(ISNUMBER(H11),H11,NA()) -> #N/A
B39: #2 L | C39: =IF(ISNUMBER(I6),I6,NA()) -> #N/A | D39: =IF(ISNUMBER(I9),I9,NA()) -> #N/A
B40: #2 M | C40: =IF(ISNUMBER(I7),I7,NA()) -> #N/A | D40: =IF(ISNUMBER(I10),I10,NA()) -> #N/A
B41: #2 H | C41: =IF(ISNUMBER(I8),I8,NA()) -> #N/A | D41: =IF(ISNUMBER(I11),I11,NA()) -> #N/A
B42: #3 L | C42: =IF(ISNUMBER(J6),J6,NA()) -> #N/A | D42: =IF(ISNUMBER(J9),J9,NA()) -> #N/A
B43: #3 M | C43: =IF(ISNUMBER(J7),J7,NA()) -> #N/A | D43: =IF(ISNUMBER(J10),J10,NA()) -> #N/A
B44: #3 H | C44: =IF(ISNUMBER(J8),J8,NA()) -> #N/A | D44: =IF(ISNUMBER(J11),J11,NA()) -> #N/A
B49: 旧表原值 | C49: 旧表原值 | D49: 旧表原值
B50: Tarmac!I19 | C50: 223
B51: Tarmac!J19 | C51: 267
B52: Tarmac!K19 | C52: 236
B53: Tarmac!I20 | C53: 238
...
