Workbook

Sheet Catalog
B1: Language / 语言 | C1: Language / 语言 | D1: Language / 语言 | E1: 简体中文 | F1: 简体中文 | G1: 简体中文
B2: =VLOOKUP("title.rax8DamperCatalog",Locale!$A$2:$D$78,4,FALSE) -> CTM Racing · RAx8 · 避震器目录
D4: =VLOOKUP("label.specification",Locale!$A$2:$D$78,4,FALSE) -> 规格 | E4: RA68 | F4: RA88
D5: =VLOOKUP("label.pistonTravel",Locale!$A$2:$D$78,4,FALSE) -> 活塞行程 | E5: =VLOOKUP("label.frontRearTravel",Locale!$A$2:$D$78,4,FALSE) -> 前轴 215 / 后轴 190 mm | F5: 280
B6: RA | D6: =VLOOKUP("label.dampingAdjustment",Locale!$A$2:$D$78,4,FALSE) -> 阻尼调节 | E6: =VLOOKUP("label.threeWay",Locale!$A$2:$D$78,4,FALSE) -> 3 向调节 | F6: =VLOOKUP("label.threePlusOneWay",Locale!$A$2:$D$78,4,FALSE) -> 3+1 向调节
D7: =VLOOKUP("label.lowSpeedCompressionC",Locale!$A$2:$D$78,4,FALSE) -> 低速压缩 · c | E7: =Parameters!D23 -> 24 | F7: =Parameters!D23 -> 24
B8: =VLOOKUP("label.rally",Locale!$A$2:$D$78,4,FALSE) -> 拉力 | D8: =VLOOKUP("label.highSpeedCompressionC",Locale!$A$2:$D$78,4,FALSE) -> 高速压缩 · C | E8: =Parameters!D27 -> 10 | F8: =Parameters!D24 -> 20
B9: =VLOOKUP("label.rallycross",Locale!$A$2:$D$78,4,FALSE) -> 跨界拉力 | D9: =VLOOKUP("label.reboundR",Locale!$A$2:$D$78,4,FALSE) -> 回弹 · R | E9: =Parameters!D25 -> 40 | F9: =Parameters!D26 -> 40
D10: HBS | E10: =VLOOKUP("label.fixed",Locale!$A$2:$D$78,4,FALSE) -> 固定 | F10: =VLOOKUP("label.adjustableSixteenClicks",Locale!$A$2:$D$78,4,FALSE) -> 可调 · 16 格
D11: HRS | F11: =VLOOKUP("label.available",Locale!$A$2:$D$78,4,FALSE) -> 有
D12: LRS | E12: =VLOOKUP("label.available",Locale!$A$2:$D$78,4,FALSE) -> 有 | F12: =VLOOKUP("label.available",Locale!$A$2:$D$78,4,FALSE) -> 有
D13: DSV

Sheet Calculator
B2: =VLOOKUP("title.rax8DampingCalculator",Locale!$A$2:$D$78,4,FALSE) -> CTM Racing · RAx8 · 阻尼计算器
B4: =VLOOKUP("label.valving",Locale!$A$2:$D$78,4,FALSE) -> 阀系 | C4: Type-A
B6: =VLOOKUP("label.damperModel",Locale!$A$2:$D$78,4,FALSE) -> 避震器型号 | C6: RA88 | F6: =VLOOKUP("title.currentDampingForce",Locale!$A$2:$D$78,4,FALSE) -> 当前输入 · 阻尼力大小
B7: LSC · c | C7: -8
B8: HSC · C | C8: -10 | F8: =VLOOKUP("label.compressionForceN",Locale!$A$2:$D$78,4,FALSE) -> 压缩力 (N) | I8: =IF(C18=VLOOKUP("status.ok",Locale!$A$2:$D$78,4,FALSE),Samples!F165*MIN(C10,Samples!G165)+Samples!I165*MAX(0,C10-Samples!G165)+Samples!J165*MAX(0,C10-Samples!K165),VLOOKUP("status.checkInput",Locale!$A$2:$D$78,4,FALSE)) -> 2151.6667
B9: LSR · R | C9: -24
B10: =VLOOKUP("label.shaftVelocityMps",Locale!$A$2:$D$78,4,FALSE) -> 轴速 (m/s) | C10: 0.6 | F10: =VLOOKUP("label.reboundForceN",Locale!$A$2:$D$78,4,FALSE) -> 回弹力 (N) | I10: =IF(C18=VLOOKUP("status.ok",Locale!$A$2:$D$78,4,FALSE),Samples!M165*MIN(C10,Samples!N165)+Samples!P165*MAX(0,C10-Samples!N165),VLOOKUP("status.checkInput",Locale!$A$2:$D$78,4,FALSE)) -> 1467.336
B13: =VLOOKUP("label.cTotalClicks",Locale!$A$2:$D$78,4,FALSE) -> c 总格数 | C13: =Parameters!D23 -> 24 | F13: =VLOOKUP("title.currentCurveParameters",Locale!$A$2:$D$78,4,FALSE) -> 当前曲线参数
B14: =VLOOKUP("label.hscTotalClicks",Locale!$A$2:$D$78,4,FALSE) -> C 总格数 | C14: =IF(C6="RA68",Parameters!D27,Parameters!D24) -> 20 | F14: bump1 | I14: =Samples!F165 -> 3400 | J14: N·s/m
B15: =VLOOKUP("label.lsrTotalClicks",Locale!$A$2:$D$78,4,FALSE) -> R 总格数 | C15: =IF(C6="RA88",Parameters!D26,Parameters!D25) -> 40 | F15: bump2 | I15: =Samples!I165 -> 3173.3333 | J15: N·s/m
F16: =VLOOKUP("label.highSpeedBumpIncrement",Locale!$A$2:$D$78,4,FALSE) -> HSbump · 高速增量 | I16: =Samples!J165 -> 1500 | J16: N·s/m
F17: =VLOOKUP("label.totalHighSpeedCoefficient",Locale!$A$2:$D$78,4,FALSE) -> 总高速系数 | I17: =Samples!L165 -> 4673.3333 | J17: N·s/m
B18: =VLOOKUP("label.inputCheck",Locale!$A$2:$D$78,4,FALSE) -> 输入检查 | C18: =IF(AND(OR(C4="Type-A",C4="Type-B"),OR(C6="RA68",C6="RA88"),COUNT(C7:C10)=4,C7>=-C13,C7<=0,C8>=-C14,C8<=0,C9>=-C15,C9<=0,C10>=0,INT(C7)=C7,INT(C8)=C8,INT(C9)=C9),VLOOKUP("status.ok",Locale!$A$2:$D$78,4,FALSE),VLOOKUP("status.checkInput",Locale!$A$2:$D$78,4,FALSE)) -> 正常
F19: =VLOOKUP("label.rebound",Locale!$A$2:$D$78,4,FALSE) -> 回弹 | I19: =Samples!M165 -> 2600 | J19: N·s/m
F20: HSrebound | I20: =Samples!P165 -> 2319.2 | J20: N·s/m
F22: =VLOOKUP("label.firstKnee",Locale!$A$2:$D$78,4,FALSE) -> 第一拐点 | I22: =Samples!G165 -> 0.1 | J22: m/s
F23: =VLOOKUP("label.secondKnee",Locale!$A$2:$D$78,4,FALSE) -> 第二拐点 | I23: =Samples!K165 -> 0.45 | J23: m/s
F24: =VLOOKUP("label.reboundKnee",Locale!$A$2:$D$78,4,FALSE) -> 回弹拐点 | I24: =Samples!N165 -> 0.27 | J24: m/s
B27: =VLOOKUP("note.yellowInputs",Locale!$A$2:$D$78,4,FALSE) -> 黄色单元格为手动输入。

Sheet LSC Sweep
B2: =VLOOKUP("title.rax8LSCSweep",Locale!$A$2:$D$78,4,FALSE) -> CTM Racing · RAx8 · LSC 扫描
B4: =VLOOKUP("label.valving",Locale!$A$2:$D$78,4,FALSE) -> 阀系 | C4: Type-A
B6: =VLOOKUP("label.fixedHsc",Locale!$A$2:$D$78,4,FALSE) -> 固定高速压缩 | C6: -10

Sheet HSC Sweep
B2: =VLOOKUP("title.rax8HSCSweep",Locale!$A$2:$D$78,4,FALSE) -> CTM Racing · RAx8 · HSC 扫描
B4: =VLOOKUP("label.valving",Locale!$A$2:$D$78,4,FALSE) -> 阀系 | C4: Type-A
B6: =VLOOKUP("label.fixedLsc",Locale!$A$2:$D$78,4,FALSE) -> 固定低速压缩 | C6: -8

Sheet LSR Sweep
B2: =VLOOKUP("title.rax8LSRSweep",Locale!$A$2:$D$78,4,FALSE) -> CTM Racing · RAx8 · LSR 扫描
B4: =VLOOKUP("label.valving",Locale!$A$2:$D$78,4,FALSE) -> 阀系 | C4: Type-A

Sheet Full Sweep
B2: =VLOOKUP("title.rax8FullSweep",Locale!$A$2:$D$78,4,FALSE) -> CTM Racing · RAx8 · 全范围扫描
B4: =VLOOKUP("label.valving",Locale!$A$2:$D$78,4,FALSE) -> 阀系 | C4: Type-A

Sheet Parameters
B2: =VLOOKUP("title.rax8ValvingParameters",Locale!$A$2:$D$78,4,FALSE) -> CTM Racing · RAx8 · 阀系参数
B3: =VLOOKUP("note.yellowInputs",Locale!$A$2:$D$78,4,FALSE) -> 黄色单元格为手动输入。
D5: Type-A | J5: Type-B
B6: =VLOOKUP("label.adjusterPosition",Locale!$A$2:$D$78,4,FALSE) -> 调节位置 | C6: =VLOOKUP("label.ratio",Locale!$A$2:$D$78,4,FALSE) -> 比例 | D6: 0 | E6: 0.25 | F6: 0.5 | G6: 0.75 | H6: 1 | J6: =D6 -> 0 | K6: =E6 -> 0.25 | L6: =F6 -> 0.5 | M6: =G6 -> 0.75 | N6: =H6 -> 1
B7: LSC · c | C7: =VLOOKUP("label.clicks",Locale!$A$2:$D$78,4,FALSE) -> 格 | D7: =(D$6-1)*$D$23 -> -24 | E7: =(E$6-1)*$D$23 -> -18 | F7: =(F$6-1)*$D$23 -> -12 | G7: =(G$6-1)*$D$23 -> -6 | H7: =(H$6-1)*$D$23 -> 0 | J7: =(J$6-1)*$D$23 -> -24 | K7: =(K$6-1)*$D$23 -> -18 | L7: =(L$6-1)*$D$23 -> -12 | M7: =(M$6-1)*$D$23 -> -6 | N7: =(N$6-1)*$D$23 -> 0
B8: HSC · C | C8: =VLOOKUP("label.clicks",Locale!$A$2:$D$78,4,FALSE) -> 格 | D8: =(D$6-1)*$D$24 -> -20 | E8: =(E$6-1)*$D$24 -> -15 | F8: =(F$6-1)*$D$24 -> -10 | G8: =(G$6-1)*$D$24 -> -5 | H8: =(H$6-1)*$D$24 -> 0 | J8: =(J$6-1)*$D$24 -> -20 | K8: =(K$6-1)*$D$24 -> -15 | L8: =(L$6-1)*$D$24 -> -10 | M8: =(M$6-1)*$D$24 -> -5 | N8: =(N$6-1)*$D$24 -> 0
B10: bump1 | C10: N·s/m | D10: 1800 | E10: =(D10+F10)/2 -> 2400 | F10: 3000 | G10: =(F10+H10)/2 -> 3600 | H10: 4200 | J10: 2600 | K10: =(J10+L10)/2 -> 3050 | L10: 3500 | M10: =(L10+N10)/2 -> 3950 | N10: 4400
B11: =VLOOKUP("label.firstKnee",Locale!$A$2:$D$78,4,FALSE) -> 第一拐点 | C11: m/s | D11: 0.1 | E11: =(D11+F11)/2 -> 0.1 | F11: 0.1 | G11: =(F11+H11)/2 -> 0.1 | H11: 0.1 | J11: 0.22 | K11: =(J11+L11)/2 -> 0.27 | L11: 0.32 | M11: =(L11+N11)/2 -> 0.37 | N11: 0.42
B12: bump2 / bump1 | C12: =VLOOKUP("label.multiplier",Locale!$A$2:$D$78,4,FALSE) -> 倍率 | D12: 1 | E12: =(D12+F12)/2 -> 0.975 | F12: 0.95 | G12: =(F12+H12)/2 -> 0.925 | H12: 0.9 | J12: 0.68 | K12: =(J12+L12)/2 -> 0.66 | L12: 0.64 | M12: =(L12+N12)/2 -> 0.62 | N12: 0.6
B13: =VLOOKUP("label.highSpeedBumpIncrement",Locale!$A$2:$D$78,4,FALSE) -> HSbump · 高速增量 | C13: N·s/m | D13: 100 | E13: =(D13+F13)/2 -> 800 | F13: 1500 | G13: =(F13+H13)/2 -> 2200 | H13: 2900 | J13: 250 | K13: =(J13+L13)/2 -> 250 | L13: 250 | M13: =(L13+N13)/2 -> 250 | N13: 250
B14: =VLOOKUP("label.secondKnee",Locale!$A$2:$D$78,4,FALSE) -> 第二拐点 | C14: m/s | D14: 0.44 | E14: =(D14+F14)/2 -> 0.445 | F14: 0.45 | G14: =(F14+H14)/2 -> 0.455 | H14: 0.46 | J14: =$L$14 -> 0.45 | K14: =$L$14 -> 0.45 | L14: 0.45 | M14: =$L$14 -> 0.45 | N14: =$L$14 -> 0.45
B16: LSR · R（RA88） | C16: =VLOOKUP("label.clicks",Locale!$A$2:$D$78,4,FALSE) -> 格 | D16: =(D$6-1)*$D$26 -> -40 | E16: =(E$6-1)*$D$26 -> -30 | F16: =(F$6-1)*$D$26 -> -20 | G16: =(G$6-1)*$D$26 -> -10 | H16: =(H$6-1)*$D$26 -> 0 | J16: =(J$6-1)*$D$26 -> -40 | K16: =(K$6-1)*$D$26 -> -30 | L16: =(L$6-1)*$D$26 -> -20 | M16: =(M$6-1)*$D$26 -> -10 | N16: =(N$6-1)*$D$26 -> 0
B17: =VLOOKUP("label.rebound",Locale!$A$2:$D$78,4,FALSE) -> 回弹 | C17: N·s/m | D17: 1800 | E17: =(D17+F17)/2 -> 2300 | F17: 2800 | G17: =(F17+H17)/2 -> 3300 | H17: 3800 | J17: 2500 | K17: =(J17+L17)/2 -> 3000 | L17: 3500 | M17: =(L17+N17)/2 -> 4000 | N17: 4500
B18: =VLOOKUP("label.reboundKnee",Locale!$A$2:$D$78,4,FALSE) -> 回弹拐点 | C18: m/s | D18: 0.23 | E18: =(D18+F18)/2 -> 0.255 | F18: 0.28 | G18: =(F18+H18)/2 -> 0.305 | H18: 0.33 | J18: 0.2 | K18: =(J18+L18)/2 -> 0.225 | L18: 0.25 | M18: =(L18+N18)/2 -> 0.275 | N18: 0.3
B19: HSrebound / rebound | C19: =VLOOKUP("label.multiplier",Locale!$A$2:$D$78,4,FALSE) -> 倍率 | D19: 0.94 | E19: =(D19+F19)/2 -> 0.91 | F19: 0.88 | G19: =(F19+H19)/2 -> 0.85 | H19: 0.82 | J19: 0.76 | K19: =(J19+L19)/2 -> 0.72 | L19: 0.68 | M19: =(L19+N19)/2 -> 0.64 | N19: 0.6
B22: =VLOOKUP("label.adjusterClicks",Locale!$A$2:$D$78,4,FALSE) -> 调节格数
B23: =VLOOKUP("label.lscAllSeries",Locale!$A$2:$D$78,4,FALSE) -> LSC · 全系列 | D23: 24 | F23: =VLOOKUP("note.sweepRa88Clicks",Locale!$A$2:$D$78,4,FALSE) -> 调节曲线使用 RA88 调节格数。
B24: HSC · RA88 | D24: 20
B25: LSR · RA68 | D25: 40
B26: LSR · RA88 | D26: 40 | F26: =VLOOKUP("note.adjusterClicks",Locale!$A$2:$D$78,4,FALSE) -> 0 为最硬，负数为退出格数。
B27: HSC · RA68 | D27: 10
B28: =VLOOKUP("note.baseDampingCurve",Locale!$A$2:$D$78,4,FALSE) -> 连续分段理论曲线，仅基础阻尼。

Sheet Locale
A1: key | B1: en-US | C1: zh-CN | D1: Active
A2: chart.rax8CompressionRebound | B2: RAx8 · Compression (+) / Rebound (−) | C2: RAx8 · 压缩 (+) / 回弹 (−) | D2: =IF(Catalog!$E$1="English",B2,C2) -> RAx8 · 压缩 (+) / 回弹 (−)
A3: chart.rax8HscSweep | B3: RAx8 · HSC Sweep | C3: RAx8 · 高速压缩调节曲线 | D3: =IF(Catalog!$E$1="English",B3,C3) -> RAx8 · 高速压缩调节曲线
A4: chart.rax8LscSweep | B4: RAx8 · LSC Sweep | C4: RAx8 · 低速压缩调节曲线 | D4: =IF(Catalog!$E$1="English",B4,C4) -> RAx8 · 低速压缩调节曲线
A5: chart.rax8LsrSweep | B5: RAx8 · LSR Sweep | C5: RAx8 · 低速回弹调节曲线 | D5: =IF(Catalog!$E$1="English",B5,C5) -> RAx8 · 低速回弹调节曲线
A6: label.adjustableSixteenClicks | B6: Adjustable · 16 clicks | C6: 可调 · 16 格 | D6: =IF(Catalog!$E$1="English",B6,C6) -> 可调 · 16 格
A7: label.adjusterClicks | B7: Adjusters · Clicks | C7: 调节格数 | D7: =IF(Catalog!$E$1="English",B7,C7) -> 调节格数
A8: label.adjusterPosition | B8: Adjuster position | C8: 调节位置 | D8: =IF(Catalog!$E$1="English",B8,C8) -> 调节位置
A9: label.available | B9: Yes | C9: 有 | D9: =IF(Catalog!$E$1="English",B9,C9) -> 有
A10: label.bump2Multiplier | B10: bump2 multiplier | C10: bump2 倍率 | D10: =IF(Catalog!$E$1="English",B10,C10) -> bump2 倍率
A11: label.bumpDampingForceN | B11: Bump damping force (N) | C11: 压缩阻尼力 (N) | D11: =IF(Catalog!$E$1="English",B11,C11) -> 压缩阻尼力 (N)
A12: label.cTotalClicks | B12: c total clicks | C12: c 总格数 | D12: =IF(Catalog!$E$1="English",B12,C12) -> c 总格数
A13: label.calculator | B13: Calculator | C13: 计算器 | D13: =IF(Catalog!$E$1="English",B13,C13) -> 计算器
... A78: title.rax8ValvingParameters | B78: CTM Racing · RAx8 · Valving Parameters | C78: CTM Racing · RAx8 · 阀系参数 | D78: =IF(Catalog!$E$1="English",B78,C78) -> CTM Racing · RAx8 · 阀系参数

Sheet Samples
B1: =VLOOKUP("label.lscSweep",Locale!$A$2:$D$78,4,FALSE) -> LSC 扫描
B4: =VLOOKUP("label.curve",Locale!$A$2:$D$78,4,FALSE) -> 曲线 | C4: c | D4: C | E4: R | F4: bump1 | G4: =VLOOKUP("label.firstKnee",Locale!$A$2:$D$78,4,FALSE) -> 第一拐点 | H4: =VLOOKUP("label.bump2Multiplier",Locale!$A$2:$D$78,4,FALSE) -> bump2 倍率 | I4: bump2 | J4: HSbump | K4: =VLOOKUP("label.secondKnee",Locale!$A$2:$D$78,4,FALSE) -> 第二拐点 | L4: =VLOOKUP("label.totalHsCoefficient",Locale!$A$2:$D$78,4,FALSE) -> 总 HS 系数 | M4: =VLOOKUP("label.rebound",Locale!$A$2:$D$78,4,FALSE) -> 回弹 | N4: =VLOOKUP("label.reboundKnee",Locale!$A$2:$D$78,4,FALSE) -> 回弹拐点 | O4: =VLOOKUP("label.hsrMultiplier",Locale!$A$2:$D$78,4,FALSE) -> HSR 倍率 | P4: HSrebound | Q4: =VLOOKUP("label.lscRange",Locale!$A$2:$D$78,4,FALSE) -> LSC 区间 | R4: =VLOOKUP("label.hscRange",Locale!$A$2:$D$78,4,FALSE) -> HSC 区间 | S4: =VLOOKUP("label.lsrRange",Locale!$A$2:$D$78,4,FALSE) -> LSR 区间 | T4: =VLOOKUP("label.lscRangePosition",Locale!$A$2:$D$78,4,FALSE) -> LSC 区间位置 | U4: =VLOOKUP("label.hscRangePosition",Locale!$A$2:$D$78,4,FALSE) -> HSC 区间位置 | V4: =VLOOKUP("label.lsrRangePosition",Locale!$A$2:$D$78,4,FALSE) -> LSR 区间位置
B5: ="c "&C5 -> c -24 | C5: =Parameters!D7 -> -24 | D5: ='LSC Sweep'!$C$6 -> -10 | E5: =Parameters!D16 -> -40 | F5: =IF('LSC Sweep'!$C$4="Type-B",INDEX(Parameters!$J$10:$N$10,1,Q5)+(INDEX(Parameters!$J$10:$N$10,1,Q5+1)-INDEX(Parameters!$J$10:$N$10,1,Q5))*T5,INDEX(Parameters!$D$10:$H$10,1,Q5)+(INDEX(Parameters!$D$10:$H$10,1,Q5+1)-INDEX(Parameters!$D$10:$H$10,1,Q5))*T5) -> 1800 | G5: =IF('LSC Sweep'!$C$4="Type-B",INDEX(Parameters!$J$11:$N$11,1,R5)+(INDEX(Parameters!$J$11:$N$11,1,R5+1)-INDEX(Parameters!$J$11:$N$11,1,R5))*U5,INDEX(Parameters!$D$11:$H$11,1,Q5)+(INDEX(Parameters!$D$11:$H$11,1,Q5+1)-INDEX(Parameters!$D$11:$H$11,1,Q5))*T5) -> 0.1 | H5: =IF('LSC Sweep'!$C$4="Type-B",INDEX(Parameters!$J$12:$N$12,1,Q5)+(INDEX(Parameters!$J$12:$N$12,1,Q5+1)-INDEX(Parameters!$J$12:$N$12,1,Q5))*T5,INDEX(Parameters!$D$12:$H$12,1,Q5)+(INDEX(Parameters!$D$12:$H$12,1,Q5+1)-INDEX(Parameters!$D$12:$H$12,1,Q5))*T5) -> 1 | I5: =F5*H5 -> 1800 | J5: =IF('LSC Sweep'!$C$4="Type-B",INDEX(Parameters!$J$13:$N$13,1,R5)+(INDEX(Parameters!$J$13:$N$13,1,R5+1)-INDEX(Parameters!$J$13:$N$13,1,R5))*U5,INDEX(Parameters!$D$13:$H$13,1,R5)+(INDEX(Parameters!$D$13:$H$13,1,R5+1)-INDEX(Parameters!$D$13:$H$13,1,R5))*U5) -> 1500 | K5: =IF('LSC Sweep'!$C$4="Type-B",Parameters!$L$14,INDEX(Parameters!$D$14:$H$14,1,R5)+(INDEX(Parameters!$D$14:$H$14,1,R5+1)-INDEX(Parameters!$D$14:$H$14,1,R5))*U5) -> 0.45 | L5: =I5+J5 -> 3300 | M5: =IF('LSC Sweep'!$C$4="Type-B",INDEX(Parameters!$J$17:$N$17,1,S5)+(INDEX(Parameters!$J$17:$N$17,1,S5+1)-INDEX(Parameters!$J$17:$N$17,1,S5))*V5,INDEX(Parameters!$D$17:$H$17,1,S5)+(INDEX(Parameters!$D$17:$H$17,1,S5+1)-INDEX(Parameters!$D$17:$H$17,1,S5))*V5) -> 1800 | N5: =IF('LSC Sweep'!$C$4="Type-B",INDEX(Parameters!$J$18:$N$18,1,S5)+(INDEX(Parameters!$J$18:$N$18,1,S5+1)-INDEX(Parameters!$J$18:$N$18,1,S5))*V5,INDEX(Parameters!$D$18:$H$18,1,S5)+(INDEX(Parameters!$D$18:$H$18,1,S5+1)-INDEX(Parameters!$D$18:$H$18,1,S5))*V5) -> 0.23 | O5: =IF('LSC Sweep'!$C$4="Type-B",INDEX(Parameters!$J$19:$N$19,1,S5)+(INDEX(Parameters!$J$19:$N$19,1,S5+1)-INDEX(Parameters!$J$19:$N$19,1,S5))*V5,INDEX(Parameters!$D$19:$H$19,1,S5)+(INDEX(Parameters!$D$19:$H$19,1,S5+1)-INDEX(Parameters!$D$19:$H$19,1,S5))*V5) -> 0.94 | P5: =M5*O5 -> 1692 | Q5: =MIN(4,MAX(1,INT((1+C5/Parameters!$D$23)*4)+1)) -> 1 | R5: =MIN(4,MAX(1,INT((1+D5/Parameters!$D$24)*4)+1)) -> 3 | S5: =MIN(4,MAX(1,INT((1+E5/Parameters!$D$26)*4)+1)) -> 1 | T5: =MAX(0,MIN(1,(1+C5/Parameters!$D$23)*4-(Q5-1))) -> 0 | U5: =MAX(0,MIN(1,(1+D5/Parameters!$D$24)*4-(R5-1))) -> 0 | V5: =MAX(0,MIN(1,(1+E5/Parameters!$D$26)*4-(S5-1))) -> 0
B6: ="c "&C6 -> c -18 | C6: =Parameters!E7 -> -18 | D6: ='LSC Sweep'!$C$6 -> -10 | E6: =Parameters!E16 -> -30 | F6: =IF('LSC Sweep'!$C$4="Type-B",INDEX(Parameters!$J$10:$N$10,1,Q6)+(INDEX(Parameters!$J$10:$N$10,1,Q6+1)-INDEX(Parameters!$J$10:$N$10,1,Q6))*T6,INDEX(Parameters!$D$10:$H$10,1,Q6)+(INDEX(Parameters!$D$10:$H$10,1,Q6+1)-INDEX(Parameters!$D$10:$H$10,1,Q6))*T6) -> 2400 | G6: =IF('LSC Sweep'!$C$4="Type-B",INDEX(Parameters!$J$11:$N$11,1,R6)+(INDEX(Parameters!$J$11:$N$11,1,R6+1)-INDEX(Parameters!$J$11:$N$11,1,R6))*U6,INDEX(Parameters!$D$11:$H$11,1,Q6)+(INDEX(Parameters!$D$11:$H$11,1,Q6+1)-INDEX(Parameters!$D$11:$H$11,1,Q6))*T6) -> 0.1 | H6: =IF('LSC Sweep'!$C$4="Type-B",INDEX(Parameters!$J$12:$N$12,1,Q6)+(INDEX(Parameters!$J$12:$N$12,1,Q6+1)-INDEX(Parameters!$J$12:$N$12,1,Q6))*T6,INDEX(Parameters!$D$12:$H$12,1,Q6)+(INDEX(Parameters!$D$12:$H$12,1,Q6+1)-INDEX(Parameters!$D$12:$H$12,1,Q6))*T6) -> 0.975 | I6: =F6*H6 -> 2340 | J6: =IF('LSC Sweep'!$C$4="Type-B",INDEX(Parameters!$J$13:$N$13,1,R6)+(INDEX(Parameters!$J$13:$N$13,1,R6+1)-INDEX(Parameters!$J$13:$N$13,1,R6))*U6,INDEX(Parameters!$D$13:$H$13,1,R6)+(INDEX(Parameters!$D$13:$H$13,1,R6+1)-INDEX(Parameters!$D$13:$H$13,1,R6))*U6) -> 1500 | K6: =IF('LSC Sweep'!$C$4="Type-B",Parameters!$L$14,INDEX(Parameters!$D$14:$H$14,1,R6)+(INDEX(Parameters!$D$14:$H$14,1,R6+1)-INDEX(Parameters!$D$14:$H$14,1,R6))*U6) -> 0.45 | L6: =I6+J6 -> 3840 | M6: =IF('LSC Sweep'!$C$4="Type-B",INDEX(Parameters!$J$17:$N$17,1,S6)+(INDEX(Parameters!$J$17:$N$17,1,S6+1)-INDEX(Parameters!$J$17:$N$17,1,S6))*V6,INDEX(Parameters!$D$17:$H$17,1,S6)+(INDEX(Parameters!$D$17:$H$17,1,S6+1)-INDEX(Parameters!$D$17:$H$17,1,S6))*V6) -> 2300 | N6: =IF('LSC Sweep'!$C$4="Type-B",INDEX(Parameters!$J$18:$N$18,1,S6)+(INDEX(Parameters!$J$18:$N$18,1,S6+1)-INDEX(Parameters!$J$18:$N$18,1,S6))*V6,INDEX(Parameters!$D$18:$H$18,1,S6)+(INDEX(Parameters!$D$18:$H$18,1,S6+1)-INDEX(Parameters!$D$18:$H$18,1,S6))*V6) -> 0.255 | O6: =IF('LSC Sweep'!$C$4="Type-B",INDEX(Parameters!$J$19:$N$19,1,S6)+(INDEX(Parameters!$J$19:$N$19,1,S6+1)-INDEX(Parameters!$J$19:$N$19,1,S6))*V6,INDEX(Parameters!$D$19:$H$19,1,S6)+(INDEX(Parameters!$D$19:$H$19,1,S6+1)-INDEX(Parameters!$D$19:$H$19,1,S6))*V6) -> 0.91 | P6: =M6*O6 -> 2093 | Q6: =MIN(4,MAX(1,INT((1+C6/Parameters!$D$23)*4)+1)) -> 2 | R6: =MIN(4,MAX(1,INT((1+D6/Parameters!$D$24)*4)+1)) -> 3 | S6: =MIN(4,MAX(1,INT((1+E6/Parameters!$D$26)*4)+1)) -> 2 | T6: =MAX(0,MIN(1,(1+C6/Parameters!$D$23)*4-(Q6-1))) -> 0 | U6: =MAX(0,MIN(1,(1+D6/Parameters!$D$24)*4-(R6-1))) -> 0 | V6: =MAX(0,MIN(1,(1+E6/Parameters!$D$26)*4-(S6-1))) -> 0
B7: ="c "&C7 -> c -12 | C7: =Parameters!F7 -> -12 | D7: ='LSC Sweep'!$C$6 -> -10 | E7: =Parameters!F16 -> -20 | F7: =IF('LSC Sweep'!$C$4="Type-B",INDEX(Parameters!$J$10:$N$10,1,Q7)+(INDEX(Parameters!$J$10:$N$10,1,Q7+1)-INDEX(Parameters!$J$10:$N$10,1,Q7))*T7,INDEX(Parameters!$D$10:$H$10,1,Q7)+(INDEX(Parameters!$D$10:$H$10,1,Q7+1)-INDEX(Parameters!$D$10:$H$10,1,Q7))*T7) -> 3000 | G7: =IF('LSC Sweep'!$C$4="Type-B",INDEX(Parameters!$J$11:$N$11,1,R7)+(INDEX(Parameters!$J$11:$N$11,1,R7+1)-INDEX(Parameters!$J$11:$N$11,1,R7))*U7,INDEX(Parameters!$D$11:$H$11,1,Q7)+(INDEX(Parameters!$D$11:$H$11,1,Q7+1)-INDEX(Parameters!$D$11:$H$11,1,Q7))*T7) -> 0.1 | H7: =IF('LSC Sweep'!$C$4="Type-B",INDEX(Parameters!$J$12:$N$12,1,Q7)+(INDEX(Parameters!$J$12:$N$12,1,Q7+1)-INDEX(Parameters!$J$12:$N$12,1,Q7))*T7,INDEX(Parameters!$D$12:$H$12,1,Q7)+(INDEX(Parameters!$D$12:$H$12,1,Q7+1)-INDEX(Parameters!$D$12:$H$12,1,Q7))*T7) -> 0.95 | I7: =F7*H7 -> 2850 | J7: =IF('LSC Sweep'!$C$4="Type-B",INDEX(Parameters!$J$13:$N$13,1,R7)+(INDEX(Parameters!$J$13:$N$13,1,R7+1)-INDEX(Parameters!$J$13:$N$13,1,R7))*U7,INDEX(Parameters!$D$13:$H$13,1,R7)+(INDEX(Parameters!$D$13:$H$13,1,R7+1)-INDEX(Parameters!$D$13:$H$13,1,R7))*U7) -> 1500 | K7: =IF('LSC Sweep'!$C$4="Type-B",Parameters!$L$14,INDEX(Parameters!$D$14:$H$14,1,R7)+(INDEX(Parameters!$D$14:$H$14,1,R7+1)-INDEX(Parameters!$D$14:$H$14,1,R7))*U7) -> 0.45 | L7: =I7+J7 -> 4350 | M7: =IF('LSC Sweep'!$C$4="Type-B",INDEX(Parameters!$J$17:$N$17,1,S7)+(INDEX(Parameters!$J$17:$N$17,1,S7+1)-INDEX(Parameters!$J$17:$N$17,1,S7))*V7,INDEX(Parameters!$D$17:$H$17,1,S7)+(INDEX(Parameters!$D$17:$H$17,1,S7+1)-INDEX(Parameters!$D$17:$H$17,1,S7))*V7) -> 2800 | N7: =IF('LSC Sweep'!$C$4="Type-B",INDEX(Parameters!$J$18:$N$18,1,S7)+(INDEX(Parameters!$J$18:$N$18,1,S7+1)-INDEX(Parameters!$J$18:$N$18,1,S7))*V7,INDEX(Parameters!$D$18:$H$18,1,S7)+(INDEX(Parameters!$D$18:$H$18,1,S7+1)-INDEX(Parameters!$D$18:$H$18,1,S7))*V7) -> 0.28 | O7: =IF('LSC Sweep'!$C$4="Type-B",INDEX(Parameters!$J$19:$N$19,1,S7)+(INDEX(Parameters!$J$19:$N$19,1,S7+1)-INDEX(Parameters!$J$19:$N$19,1,S7))*V7,INDEX(Parameters!$D$19:$H$19,1,S7)+(INDEX(Parameters!$D$19:$H$19,1,S7+1)-INDEX(Parameters!$D$19:$H$19,1,S7))*V7) -> 0.88 | P7: =M7*O7 -> 2464 | Q7: =MIN(4,MAX(1,INT((1+C7/Parameters!$D$23)*4)+1)) -> 3 | R7: =MIN(4,MAX(1,INT((1+D7/Parameters!$D$24)*4)+1)) -> 3 | S7: =MIN(4,MAX(1,INT((1+E7/Parameters!$D$26)*4)+1)) -> 3 | T7: =MAX(0,MIN(1,(1+C7/Parameters!$D$23)*4-(Q7-1))) -> 0 | U7: =MAX(0,MIN(1,(1+D7/Parameters!$D$24)*4-(R7-1))) -> 0 | V7: =MAX(0,MIN(1,(1+E7/Parameters!$D$26)*4-(S7-1))) -> 0
B8: ="c "&C8 -> c -6 | C8: =Parameters!G7 -> -6 | D8: ='LSC Sweep'!$C$6 -> -10 | E8: =Parameters!G16 -> -10 | F8: =IF('LSC Sweep'!$C$4="Type-B",INDEX(Parameters!$J$10:$N$10,1,Q8)+(INDEX(Parameters!$J$10:$N$10,1,Q8+1)-INDEX(Parameters!$J$10:$N$10,1,Q8))*T8,INDEX(Parameters!$D$10:$H$10,1,Q8)+(INDEX(Parameters!$D$10:$H$10,1,Q8+1)-INDEX(Parameters!$D$10:$H$10,1,Q8))*T8) -> 3600 | G8: =IF('LSC Sweep'!$C$4="Type-B",INDEX(Parameters!$J$11:$N$11,1,R8)+(INDEX(Parameters!$J$11:$N$11,1,R8+1)-INDEX(Parameters!$J$11:$N$11,1,R8))*U8,INDEX(Parameters!$D$11:$H$11,1,Q8)+(INDEX(Parameters!$D$11:$H$11,1,Q8+1)-INDEX(Parameters!$D$11:$H$11,1,Q8))*T8) -> 0.1 | H8: =IF('LSC Sweep'!$C$4="Type-B",INDEX(Parameters!$J$12:$N$12,1,Q8)+(INDEX(Parameters!$J$12:$N$12,1,Q8+1)-INDEX(Parameters!$J$12:$N$12,1,Q8))*T8,INDEX(Parameters!$D$12:$H$12,1,Q8)+(INDEX(Parameters!$D$12:$H$12,1,Q8+1)-INDEX(Parameters!$D$12:$H$12,1,Q8))*T8) -> 0.925 | I8: =F8*H8 -> 3330 | J8: =IF('LSC Sweep'!$C$4="Type-B",INDEX(Parameters!$J$13:$N$13,1,R8)+(INDEX(Parameters!$J$13:$N$13,1,R8+1)-INDEX(Parameters!$J$13:$N$13,1,R8))*U8,INDEX(Parameters!$D$13:$H$13,1,R8)+(INDEX(Parameters!$D$13:$H$13,1,R8+1)-INDEX(Parameters!$D$13:$H$13,1,R8))*U8) -> 1500 | K8: =IF('LSC Sweep'!$C$4="Type-B",Parameters!$L$14,INDEX(Parameters!$D$14:$H$14,1,R8)+(INDEX(Parameters!$D$14:$H$14,1,R8+1)-INDEX(Parameters!$D$14:$H$14,1,R8))*U8) -> 0.45 | L8: =I8+J8 -> 4830 | M8: =IF('LSC Sweep'!$C$4="Type-B",INDEX(Parameters!$J$17:$N$17,1,S8)+(INDEX(Parameters!$J$17:$N$17,1,S8+1)-INDEX(Parameters!$J$17:$N$17,1,S8))*V8,INDEX(Parameters!$D$17:$H$17,1,S8)+(INDEX(Parameters!$D$17:$H$17,1,S8+1)-INDEX(Parameters!$D$17:$H$17,1,S8))*V8) -> 3300 | N8: =IF('LSC Sweep'!$C$4="Type-B",INDEX(Parameters!$J$18:$N$18,1,S8)+(INDEX(Parameters!$J$18:$N$18,1,S8+1)-INDEX(Parameters!$J$18:$N$18,1,S8))*V8,INDEX(Parameters!$D$18:$H$18,1,S8)+(INDEX(Parameters!$D$18:$H$18,1,S8+1)-INDEX(Parameters!$D$18:$H$18,1,S8))*V8) -> 0.305 | O8: =IF('LSC Sweep'!$C$4="Type-B",INDEX(Parameters!$J$19:$N$19,1,S8)+(INDEX(Parameters!$J$19:$N$19,1,S8+1)-INDEX(Parameters!$J$19:$N$19,1,S8))*V8,INDEX(Parameters!$D$19:$H$19,1,S8)+(INDEX(Parameters!$D$19:$H$19,1,S8+1)-INDEX(Parameters!$D$19:$H$19,1,S8))*V8) -> 0.85 | P8: =M8*O8 -> 2805 | Q8: =MIN(4,MAX(1,INT((1+C8/Parameters!$D$23)*4)+1)) -> 4 | R8: =MIN(4,MAX(1,INT((1+D8/Parameters!$D$24)*4)+1)) -> 3 | S8: =MIN(4,MAX(1,INT((1+E8/Parameters!$D$26)*4)+1)) -> 4 | T8: =MAX(0,MIN(1,(1+C8/Parameters!$D$23)*4-(Q8-1))) -> 0 | U8: =MAX(0,MIN(1,(1+D8/Parameters!$D$24)*4-(R8-1))) -> 0 | V8: =MAX(0,MIN(1,(1+E8/Parameters!$D$26)*4-(S8-1))) -> 0
B9: ="c "&C9 -> c 0 | C9: =Parameters!H7 -> 0 | D9: ='LSC Sweep'!$C$6 -> -10 | E9: =Parameters!H16 -> 0 | F9: =IF('LSC Sweep'!$C$4="Type-B",INDEX(Parameters!$J$10:$N$10,1,Q9)+(INDEX(Parameters!$J$10:$N$10,1,Q9+1)-INDEX(Parameters!$J$10:$N$10,1,Q9))*T9,INDEX(Parameters!$D$10:$H$10,1,Q9)+(INDEX(Parameters!$D$10:$H$10,1,Q9+1)-INDEX(Parameters!$D$10:$H$10,1,Q9))*T9) -> 4200 | G9: =IF('LSC Sweep'!$C$4="Type-B",INDEX(Parameters!$J$11:$N$11,1,R9)+(INDEX(Parameters!$J$11:$N$11,1,R9+1)-INDEX(Parameters!$J$11:$N$11,1,R9))*U9,INDEX(Parameters!$D$11:$H$11,1,Q9)+(INDEX(Parameters!$D$11:$H$11,1,Q9+1)-INDEX(Parameters!$D$11:$H$11,1,Q9))*T9) -> 0.1 | H9: =IF('LSC Sweep'!$C$4="Type-B",INDEX(Parameters!$J$12:$N$12,1,Q9)+(INDEX(Parameters!$J$12:$N$12,1,Q9+1)-INDEX(Parameters!$J$12:$N$12,1,Q9))*T9,INDEX(Parameters!$D$12:$H$12,1,Q9)+(INDEX(Parameters!$D$12:$H$12,1,Q9+1)-INDEX(Parameters!$D$12:$H$12,1,Q9))*T9) -> 0.9 | I9: =F9*H9 -> 3780 | J9: =IF('LSC Sweep'!$C$4="Type-B",INDEX(Parameters!$J$13:$N$13,1,R9)+(INDEX(Parameters!$J$13:$N$13,1,R9+1)-INDEX(Parameters!$J$13:$N$13,1,R9))*U9,INDEX(Parameters!$D$13:$H$13,1,R9)+(INDEX(Parameters!$D$13:$H$13,1,R9+1)-INDEX(Parameters!$D$13:$H$13,1,R9))*U9) -> 1500 | K9: =IF('LSC Sweep'!$C$4="Type-B",Parameters!$L$14,INDEX(Parameters!$D$14:$H$14,1,R9)+(INDEX(Parameters!$D$14:$H$14,1,R9+1)-INDEX(Parameters!$D$14:$H$14,1,R9))*U9) -> 0.45 | L9: =I9+J9 -> 5280 | M9: =IF('LSC Sweep'!$C$4="Type-B",INDEX(Parameters!$J$17:$N$17,1,S9)+(INDEX(Parameters!$J$17:$N$17,1,S9+1)-INDEX(Parameters!$J$17:$N$17,1,S9))*V9,INDEX(Parameters!$D$17:$H$17,1,S9)+(INDEX(Parameters!$D$17:$H$17,1,S9+1)-INDEX(Parameters!$D$17:$H$17,1,S9))*V9) -> 3800 | N9: =IF('LSC Sweep'!$C$4="Type-B",INDEX(Parameters!$J$18:$N$18,1,S9)+(INDEX(Parameters!$J$18:$N$18,1,S9+1)-INDEX(Parameters!$J$18:$N$18,1,S9))*V9,INDEX(Parameters!$D$18:$H$18,1,S9)+(INDEX(Parameters!$D$18:$H$18,1,S9+1)-INDEX(Parameters!$D$18:$H$18,1,S9))*V9) -> 0.33 | O9: =IF('LSC Sweep'!$C$4="Type-B",INDEX(Parameters!$J$19:$N$19,1,S9)+(INDEX(Parameters!$J$19:$N$19,1,S9+1)-INDEX(Parameters!$J$19:$N$19,1,S9))*V9,INDEX(Parameters!$D$19:$H$19,1,S9)+(INDEX(Parameters!$D$19:$H$19,1,S9+1)-INDEX(Parameters!$D$19:$H$19,1,S9))*V9) -> 0.82 | P9: =M9*O9 -> 3116 | Q9: =MIN(4,MAX(1,INT((1+C9/Parameters!$D$23)*4)+1)) -> 4 | R9: =MIN(4,MAX(1,INT((1+D9/Parameters!$D$24)*4)+1)) -> 3 | S9: =MIN(4,MAX(1,INT((1+E9/Parameters!$D$26)*4)+1)) -> 4 | T9: =MAX(0,MIN(1,(1+C9/Parameters!$D$23)*4-(Q9-1))) -> 1 | U9: =MAX(0,MIN(1,(1+D9/Parameters!$D$24)*4-(R9-1))) -> 0 | V9: =MAX(0,MIN(1,(1+E9/Parameters!$D$26)*4-(S9-1))) -> 1
B13: =VLOOKUP("label.shaftVelocityMps",Locale!$A$2:$D$78,4,FALSE) -> 轴速 (m/s) | C13: =B5 -> c -24 | D13: =B6 -> c -18 | E13: =B7 -> c -12 | F13: =B8 -> c -6 | G13: =B9 -> c 0
B14: 0 | C14: =$F$5*MIN($B14,$G$5)+$I$5*MAX(0,$B14-$G$5)+$J$5*MAX(0,$B14-$K$5) -> 0 | D14: =$F$6*MIN($B14,$G$6)+$I$6*MAX(0,$B14-$G$6)+$J$6*MAX(0,$B14-$K$6) -> 0 | E14: =$F$7*MIN($B14,$G$7)+$I$7*MAX(0,$B14-$G$7)+$J$7*MAX(0,$B14-$K$7) -> 0 | F14: =$F$8*MIN($B14,$G$8)+$I$8*MAX(0,$B14-$G$8)+$J$8*MAX(0,$B14-$K$8) -> 0 | G14: =$F$9*MIN($B14,$G$9)+$I$9*MAX(0,$B14-$G$9)+$J$9*MAX(0,$B14-$K$9) -> 0
B15: 0.05 | C15: =$F$5*MIN($B15,$G$5)+$I$5*MAX(0,$B15-$G$5)+$J$5*MAX(0,$B15-$K$5) -> 90 | D15: =$F$6*MIN($B15,$G$6)+$I$6*MAX(0,$B15-$G$6)+$J$6*MAX(0,$B15-$K$6) -> 120 | E15: =$F$7*MIN($B15,$G$7)+$I$7*MAX(0,$B15-$G$7)+$J$7*MAX(0,$B15-$K$7) -> 150 | F15: =$F$8*MIN($B15,$G$8)+$I$8*MAX(0,$B15-$G$8)+$J$8*MAX(0,$B15-$K$8) -> 180 | G15: =$F$9*MIN($B15,$G$9)+$I$9*MAX(0,$B15-$G$9)+$J$9*MAX(0,$B15-$K$9) -> 210
B16: 0.1 | C16: =$F$5*MIN($B16,$G$5)+$I$5*MAX(0,$B16-$G$5)+$J$5*MAX(0,$B16-$K$5) -> 180 | D16: =$F$6*MIN($B16,$G$6)+$I$6*MAX(0,$B16-$G$6)+$J$6*MAX(0,$B16-$K$6) -> 240 | E16: =$F$7*MIN($B16,$G$7)+$I$7*MAX(0,$B16-$G$7)+$J$7*MAX(0,$B16-$K$7) -> 300 | F16: =$F$8*MIN($B16,$G$8)+$I$8*MAX(0,$B16-$G$8)+$J$8*MAX(0,$B16-$K$8) -> 360 | G16: =$F$9*MIN($B16,$G$9)+$I$9*MAX(0,$B16-$G$9)+$J$9*MAX(0,$B16-$K$9) -> 420
B17: 0.15 | C17: =$F$5*MIN($B17,$G$5)+$I$5*MAX(0,$B17-$G$5)+$J$5*MAX(0,$B17-$K$5) -> 270 | D17: =$F$6*MIN($B17,$G$6)+$I$6*MAX(0,$B17-$G$6)+$J$6*MAX(0,$B17-$K$6) -> 357 | E17: =$F$7*MIN($B17,$G$7)+$I$7*MAX(0,$B17-$G$7)+$J$7*MAX(0,$B17-$K$7) -> 442.5 | F17: =$F$8*MIN($B17,$G$8)+$I$8*MAX(0,$B17-$G$8)+$J$8*MAX(0,$B17-$K$8) -> 526.5 | G17: =$F$9*MIN($B17,$G$9)+$I$9*MAX(0,$B17-$G$9)+$J$9*MAX(0,$B17-$K$9) -> 609
B18: 0.2 | C18: =$F$5*MIN($B18,$G$5)+$I$5*MAX(0,$B18-$G$5)+$J$5*MAX(0,$B18-$K$5) -> 360 | D18: =$F$6*MIN($B18,$G$6)+$I$6*MAX(0,$B18-$G$6)+$J$6*MAX(0,$B18-$K$6) -> 474 | E18: =$F$7*MIN($B18,$G$7)+$I$7*MAX(0,$B18-$G$7)+$J$7*MAX(0,$B18-$K$7) -> 585 | F18: =$F$8*MIN($B18,$G$8)+$I$8*MAX(0,$B18-$G$8)+$J$8*MAX(0,$B18-$K$8) -> 693 | G18: =$F$9*MIN($B18,$G$9)+$I$9*MAX(0,$B18-$G$9)+$J$9*MAX(0,$B18-$K$9) -> 798
B19: 0.25 | C19: =$F$5*MIN($B19,$G$5)+$I$5*MAX(0,$B19-$G$5)+$J$5*MAX(0,$B19-$K$5) -> 450 | D19: =$F$6*MIN($B19,$G$6)+$I$6*MAX(0,$B19-$G$6)+$J$6*MAX(0,$B19-$K$6) -> 591 | E19: =$F$7*MIN($B19,$G$7)+$I$7*MAX(0,$B19-$G$7)+$J$7*MAX(0,$B19-$K$7) -> 727.5 | F19: =$F$8*MIN($B19,$G$8)+$I$8*MAX(0,$B19-$G$8)+$J$8*MAX(0,$B19-$K$8) -> 859.5 | G19: =$F$9*MIN($B19,$G$9)+$I$9*MAX(0,$B19-$G$9)+$J$9*MAX(0,$B19-$K$9) -> 987
B20: 0.3 | C20: =$F$5*MIN($B20,$G$5)+$I$5*MAX(0,$B20-$G$5)+$J$5*MAX(0,$B20-$K$5) -> 540 | D20: =$F$6*MIN($B20,$G$6)+$I$6*MAX(0,$B20-$G$6)+$J$6*MAX(0,$B20-$K$6) -> 708 | E20: =$F$7*MIN($B20,$G$7)+$I$7*MAX(0,$B20-$G$7)+$J$7*MAX(0,$B20-$K$7) -> 870 | F20: =$F$8*MIN($B20,$G$8)+$I$8*MAX(0,$B20-$G$8)+$J$8*MAX(0,$B20-$K$8) -> 1026 | G20: =$F$9*MIN($B20,$G$9)+$I$9*MAX(0,$B20-$G$9)+$J$9*MAX(0,$B20-$K$9) -> 1176
B21: 0.35 | C21: =$F$5*MIN($B21,$G$5)+$I$5*MAX(0,$B21-$G$5)+$J$5*MAX(0,$B21-$K$5) -> 630 | D21: =$F$6*MIN($B21,$G$6)+$I$6*MAX(0,$B21-$G$6)+$J$6*MAX(0,$B21-$K$6) -> 825 | E21: =$F$7*MIN($B21,$G$7)+$I$7*MAX(0,$B21-$G$7)+$J$7*MAX(0,$B21-$K$7) -> 1012.5 | F21: =$F$8*MIN($B21,$G$8)+$I$8*MAX(0,$B21-$G$8)+$J$8*MAX(0,$B21-$K$8) -> 1192.5 | G21: =$F$9*MIN($B21,$G$9)+$I$9*MAX(0,$B21-$G$9)+$J$9*MAX(0,$B21-$K$9) -> 1365
B22: 0.4 | C22: =$F$5*MIN($B22,$G$5)+$I$5*MAX(0,$B22-$G$5)+$J$5*MAX(0,$B22-$K$5) -> 720 | D22: =$F$6*MIN($B22,$G$6)+$I$6*MAX(0,$B22-$G$6)+$J$6*MAX(0,$B22-$K$6) -> 942 | E22: =$F$7*MIN($B22,$G$7)+$I$7*MAX(0,$B22-$G$7)+$J$7*MAX(0,$B22-$K$7) -> 1155 | F22: =$F$8*MIN($B22,$G$8)+$I$8*MAX(0,$B22-$G$8)+$J$8*MAX(0,$B22-$K$8) -> 1359 | G22: =$F$9*MIN($B22,$G$9)+$I$9*MAX(0,$B22-$G$9)+$J$9*MAX(0,$B22-$K$9) -> 1554
B23: 0.45 | C23: =$F$5*MIN($B23,$G$5)+$I$5*MAX(0,$B23-$G$5)+$J$5*MAX(0,$B23-$K$5) -> 810 | D23: =$F$6*MIN($B23,$G$6)+$I$6*MAX(0,$B23-$G$6)+$J$6*MAX(0,$B23-$K$6) -> 1059 | E23: =$F$7*MIN($B23,$G$7)+$I$7*MAX(0,$B23-$G$7)+$J$7*MAX(0,$B23-$K$7) -> 1297.5 | F23: =$F$8*MIN($B23,$G$8)+$I$8*MAX(0,$B23-$G$8)+$J$8*MAX(0,$B23-$K$8) -> 1525.5 | G23: =$F$9*MIN($B23,$G$9)+$I$9*MAX(0,$B23-$G$9)+$J$9*MAX(0,$B23-$K$9) -> 1743
B24: 0.5 | C24: =$F$5*MIN($B24,$G$5)+$I$5*MAX(0,$B24-$G$5)+$J$5*MAX(0,$B24-$K$5) -> 975 | D24: =$F$6*MIN($B24,$G$6)+$I$6*MAX(0,$B24-$G$6)+$J$6*MAX(0,$B24-$K$6) -> 1251 | E24: =$F$7*MIN($B24,$G$7)+$I$7*MAX(0,$B24-$G$7)+$J$7*MAX(0,$B24-$K$7) -> 1515 | F24: =$F$8*MIN($B24,$G$8)+$I$8*MAX(0,$B24-$G$8)+$J$8*MAX(0,$B24-$K$8) -> 1767 | G24: =$F$9*MIN($B24,$G$9)+$I$9*MAX(0,$B24-$G$9)+$J$9*MAX(0,$B24-$K$9) -> 2007
B25: 0.55 | C25: =$F$5*MIN($B25,$G$5)+$I$5*MAX(0,$B25-$G$5)+$J$5*MAX(0,$B25-$K$5) -> 1140 | D25: =$F$6*MIN($B25,$G$6)+$I$6*MAX(0,$B25-$G$6)+$J$6*MAX(0,$B25-$K$6) -> 1443 | E25: =$F$7*MIN($B25,$G$7)+$I$7*MAX(0,$B25-$G$7)+$J$7*MAX(0,$B25-$K$7) -> 1732.5 | F25: =$F$8*MIN($B25,$G$8)+$I$8*MAX(0,$B25-$G$8)+$J$8*MAX(0,$B25-$K$8) -> 2008.5 | G25: =$F$9*MIN($B25,$G$9)+$I$9*MAX(0,$B25-$G$9)+$J$9*MAX(0,$B25-$K$9) -> 2271
... B34: 1 | C34: =$F$5*MIN($B34,$G$5)+$I$5*MAX(0,$B34-$G$5)+$J$5*MAX(0,$B34-$K$5) -> 2625 | D34: =$F$6*MIN($B34,$G$6)+$I$6*MAX(0,$B34-$G$6)+$J$6*MAX(0,$B34-$K$6) -> 3171 | E34: =$F$7*MIN($B34,$G$7)+$I$7*MAX(0,$B34-$G$7)+$J$7*MAX(0,$B34-$K$7) -> 3690 | F34: =$F$8*MIN($B34,$G$8)+$I$8*MAX(0,$B34-$G$8)+$J$8*MAX(0,$B34-$K$8) -> 4182 | G34: =$F$9*MIN($B34,$G$9)+$I$9*MAX(0,$B34-$G$9)+$J$9*MAX(0,$B34-$K$9) -> 4647
B41: =VLOOKUP("label.hscSweep",Locale!$A$2:$D$78,4,FALSE) -> HSC 扫描
B44: =VLOOKUP("label.curve",Locale!$A$2:$D$78,4,FALSE) -> 曲线 | C44: c | D44: C | E44: R | F44: bump1 | G44: =VLOOKUP("label.firstKnee",Locale!$A$2:$D$78,4,FALSE) -> 第一拐点 | H44: =VLOOKUP("label.bump2Multiplier",Locale!$A$2:$D$78,4,FALSE) -> bump2 倍率 | I44: bump2 | J44: HSbump | K44: =VLOOKUP("label.secondKnee",Locale!$A$2:$D$78,4,FALSE) -> 第二拐点 | L44: =VLOOKUP("label.totalHsCoefficient",Locale!$A$2:$D$78,4,FALSE) -> 总 HS 系数 | M44: =VLOOKUP("label.rebound",Locale!$A$2:$D$78,4,FALSE) -> 回弹 | N44: =VLOOKUP("label.reboundKnee",Locale!$A$2:$D$78,4,FALSE) -> 回弹拐点 | O44: =VLOOKUP("label.hsrMultiplier",Locale!$A$2:$D$78,4,FALSE) -> HSR 倍率 | P44: HSrebound | Q44: =VLOOKUP("label.lscRange",Locale!$A$2:$D$78,4,FALSE) -> LSC 区间 | R44: =VLOOKUP("label.hscRange",Locale!$A$2:$D$78,4,FALSE) -> HSC 区间 | S44: =VLOOKUP("label.lsrRange",Locale!$A$2:$D$78,4,FALSE) -> LSR 区间 | T44: =VLOOKUP("label.lscRangePosition",Locale!$A$2:$D$78,4,FALSE) -> LSC 区间位置 | U44: =VLOOKUP("label.hscRangePosition",Locale!$A$2:$D$78,4,FALSE) -> HSC 区间位置 | V44: =VLOOKUP("label.lsrRangePosition",Locale!$A$2:$D$78,4,FALSE) -> LSR 区间位置
B45: ="C "&D45 -> C -20 | C45: ='HSC Sweep'!$C$6 -> -8 | D45: =Parameters!D8 -> -20 | E45: =Parameters!D16 -> -40 | F45: =IF('HSC Sweep'!$C$4="Type-B",INDEX(Parameters!$J$10:$N$10,1,Q45)+(INDEX(Parameters!$J$10:$N$10,1,Q45+1)-INDEX(Parameters!$J$10:$N$10,1,Q45))*T45,INDEX(Parameters!$D$10:$H$10,1,Q45)+(INDEX(Parameters!$D$10:$H$10,1,Q45+1)-INDEX(Parameters!$D$10:$H$10,1,Q45))*T45) -> 3400 | G45: =IF('HSC Sweep'!$C$4="Type-B",INDEX(Parameters!$J$11:$N$11,1,R45)+(INDEX(Parameters!$J$11:$N$11,1,R45+1)-INDEX(Parameters!$J$11:$N$11,1,R45))*U45,INDEX(Parameters!$D$11:$H$11,1,Q45)+(INDEX(Parameters!$D$11:$H$11,1,Q45+1)-INDEX(Parameters!$D$11:$H$11,1,Q45))*T45) -> 0.1 | H45: =IF('HSC Sweep'!$C$4="Type-B",INDEX(Parameters!$J$12:$N$12,1,Q45)+(INDEX(Parameters!$J$12:$N$12,1,Q45+1)-INDEX(Parameters!$J$12:$N$12,1,Q45))*T45,INDEX(Parameters!$D$12:$H$12,1,Q45)+(INDEX(Parameters!$D$12:$H$12,1,Q45+1)-INDEX(Parameters!$D$12:$H$12,1,Q45))*T45) -> 0.93333333 | I45: =F45*H45 -> 3173.3333 | J45: =IF('HSC Sweep'!$C$4="Type-B",INDEX(Parameters!$J$13:$N$13,1,R45)+(INDEX(Parameters!$J$13:$N$13,1,R45+1)-INDEX(Parameters!$J$13:$N$13,1,R45))*U45,INDEX(Parameters!$D$13:$H$13,1,R45)+(INDEX(Parameters!$D$13:$H$13,1,R45+1)-INDEX(Parameters!$D$13:$H$13,1,R45))*U45) -> 100 | K45: =IF('HSC Sweep'!$C$4="Type-B",Parameters!$L$14,INDEX(Parameters!$D$14:$H$14,1,R45)+(INDEX(Parameters!$D$14:$H$14,1,R45+1)-INDEX(Parameters!$D$14:$H$14,1,R45))*U45) -> 0.44 | L45: =I45+J45 -> 3273.3333 | M45: =IF('HSC Sweep'!$C$4="Type-B",INDEX(Parameters!$J$17:$N$17,1,S45)+(INDEX(Parameters!$J$17:$N$17,1,S45+1)-INDEX(Parameters!$J$17:$N$17,1,S45))*V45,INDEX(Parameters!$D$17:$H$17,1,S45)+(INDEX(Parameters!$D$17:$H$17,1,S45+1)-INDEX(Parameters!$D$17:$H$17,1,S45))*V45) -> 1800 | N45: =IF('HSC Sweep'!$C$4="Type-B",INDEX(Parameters!$J$18:$N$18,1,S45)+(INDEX(Parameters!$J$18:$N$18,1,S45+1)-INDEX(Parameters!$J$18:$N$18,1,S45))*V45,INDEX(Parameters!$D$18:$H$18,1,S45)+(INDEX(Parameters!$D$18:$H$18,1,S45+1)-INDEX(Parameters!$D$18:$H$18,1,S45))*V45) -> 0.23 | O45: =IF('HSC Sweep'!$C$4="Type-B",INDEX(Parameters!$J$19:$N$19,1,S45)+(INDEX(Parameters!$J$19:$N$19,1,S45+1)-INDEX(Parameters!$J$19:$N$19,1,S45))*V45,INDEX(Parameters!$D$19:$H$19,1,S45)+(INDEX(Parameters!$D$19:$H$19,1,S45+1)-INDEX(Parameters!$D$19:$H$19,1,S45))*V45) -> 0.94 | P45: =M45*O45 -> 1692 | Q45: =MIN(4,MAX(1,INT((1+C45/Parameters!$D$23)*4)+1)) -> 3 | R45: =MIN(4,MAX(1,INT((1+D45/Parameters!$D$24)*4)+1)) -> 1 | S45: =MIN(4,MAX(1,INT((1+E45/Parameters!$D$26)*4)+1)) -> 1 | T45: =MAX(0,MIN(1,(1+C45/Parameters!$D$23)*4-(Q45-1))) -> 0.66666667 | U45: =MAX(0,MIN(1,(1+D45/Parameters!$D$24)*4-(R45-1))) -> 0 | V45: =MAX(0,MIN(1,(1+E45/Parameters!$D$26)*4-(S45-1))) -> 0
B46: ="C "&D46 -> C -15 | C46: ='HSC Sweep'!$C$6 -> -8 | D46: =Parameters!E8 -> -15 | E46: =Parameters!E16 -> -30 | F46: =IF('HSC Sweep'!$C$4="Type-B",INDEX(Parameters!$J$10:$N$10,1,Q46)+(INDEX(Parameters!$J$10:$N$10,1,Q46+1)-INDEX(Parameters!$J$10:$N$10,1,Q46))*T46,INDEX(Parameters!$D$10:$H$10,1,Q46)+(INDEX(Parameters!$D$10:$H$10,1,Q46+1)-INDEX(Parameters!$D$10:$H$10,1,Q46))*T46) -> 3400 | G46: =IF('HSC Sweep'!$C$4="Type-B",INDEX(Parameters!$J$11:$N$11,1,R46)+(INDEX(Parameters!$J$11:$N$11,1,R46+1)-INDEX(Parameters!$J$11:$N$11,1,R46))*U46,INDEX(Parameters!$D$11:$H$11,1,Q46)+(INDEX(Parameters!$D$11:$H$11,1,Q46+1)-INDEX(Parameters!$D$11:$H$11,1,Q46))*T46) -> 0.1 | H46: =IF('HSC Sweep'!$C$4="Type-B",INDEX(Parameters!$J$12:$N$12,1,Q46)+(INDEX(Parameters!$J$12:$N$12,1,Q46+1)-INDEX(Parameters!$J$12:$N$12,1,Q46))*T46,INDEX(Parameters!$D$12:$H$12,1,Q46)+(INDEX(Parameters!$D$12:$H$12,1,Q46+1)-INDEX(Parameters!$D$12:$H$12,1,Q46))*T46) -> 0.93333333 | I46: =F46*H46 -> 3173.3333 | J46: =IF('HSC Sweep'!$C$4="Type-B",INDEX(Parameters!$J$13:$N$13,1,R46)+(INDEX(Parameters!$J$13:$N$13,1,R46+1)-INDEX(Parameters!$J$13:$N$13,1,R46))*U46,INDEX(Parameters!$D$13:$H$13,1,R46)+(INDEX(Parameters!$D$13:$H$13,1,R46+1)-INDEX(Parameters!$D$13:$H$13,1,R46))*U46) -> 800 | K46: =IF('HSC Sweep'!$C$4="Type-B",Parameters!$L$14,INDEX(Parameters!$D$14:$H$14,1,R46)+(INDEX(Parameters!$D$14:$H$14,1,R46+1)-INDEX(Parameters!$D$14:$H$14,1,R46))*U46) -> 0.445 | L46: =I46+J46 -> 3973.3333 | M46: =IF('HSC Sweep'!$C$4="Type-B",INDEX(Parameters!$J$17:$N$17,1,S46)+(INDEX(Parameters!$J$17:$N$17,1,S46+1)-INDEX(Parameters!$J$17:$N$17,1,S46))*V46,INDEX(Parameters!$D$17:$H$17,1,S46)+(INDEX(Parameters!$D$17:$H$17,1,S46+1)-INDEX(Parameters!$D$17:$H$17,1,S46))*V46) -> 2300 | N46: =IF('HSC Sweep'!$C$4="Type-B",INDEX(Parameters!$J$18:$N$18,1,S46)+(INDEX(Parameters!$J$18:$N$18,1,S46+1)-INDEX(Parameters!$J$18:$N$18,1,S46))*V46,INDEX(Parameters!$D$18:$H$18,1,S46)+(INDEX(Parameters!$D$18:$H$18,1,S46+1)-INDEX(Parameters!$D$18:$H$18,1,S46))*V46) -> 0.255 | O46: =IF('HSC Sweep'!$C$4="Type-B",INDEX(Parameters!$J$19:$N$19,1,S46)+(INDEX(Parameters!$J$19:$N$19,1,S46+1)-INDEX(Parameters!$J$19:$N$19,1,S46))*V46,INDEX(Parameters!$D$19:$H$19,1,S46)+(INDEX(Parameters!$D$19:$H$19,1,S46+1)-INDEX(Parameters!$D$19:$H$19,1,S46))*V46) -> 0.91 | P46: =M46*O46 -> 2093 | Q46: =MIN(4,MAX(1,INT((1+C46/Parameters!$D$23)*4)+1)) -> 3 | R46: =MIN(4,MAX(1,INT((1+D46/Parameters!$D$24)*4)+1)) -> 2 | S46: =MIN(4,MAX(1,INT((1+E46/Parameters!$D$26)*4)+1)) -> 2 | T46: =MAX(0,MIN(1,(1+C46/Parameters!$D$23)*4-(Q46-1))) -> 0.66666667 | U46: =MAX(0,MIN(1,(1+D46/Parameters!$D$24)*4-(R46-1))) -> 0 | V46: =MAX(0,MIN(1,(1+E46/Parameters!$D$26)*4-(S46-1))) -> 0
B47: ="C "&D47 -> C -10 | C47: ='HSC Sweep'!$C$6 -> -8 | D47: =Parameters!F8 -> -10 | E47: =Parameters!F16 -> -20 | F47: =IF('HSC Sweep'!$C$4="Type-B",INDEX(Parameters!$J$10:$N$10,1,Q47)+(INDEX(Parameters!$J$10:$N$10,1,Q47+1)-INDEX(Parameters!$J$10:$N$10,1,Q47))*T47,INDEX(Parameters!$D$10:$H$10,1,Q47)+(INDEX(Parameters!$D$10:$H$10,1,Q47+1)-INDEX(Parameters!$D$10:$H$10,1,Q47))*T47) -> 3400 | G47: =IF('HSC Sweep'!$C$4="Type-B",INDEX(Parameters!$J$11:$N$11,1,R47)+(INDEX(Parameters!$J$11:$N$11,1,R47+1)-INDEX(Parameters!$J$11:$N$11,1,R47))*U47,INDEX(Parameters!$D$11:$H$11,1,Q47)+(INDEX(Parameters!$D$11:$H$11,1,Q47+1)-INDEX(Parameters!$D$11:$H$11,1,Q47))*T47) -> 0.1 | H47: =IF('HSC Sweep'!$C$4="Type-B",INDEX(Parameters!$J$12:$N$12,1,Q47)+(INDEX(Parameters!$J$12:$N$12,1,Q47+1)-INDEX(Parameters!$J$12:$N$12,1,Q47))*T47,INDEX(Parameters!$D$12:$H$12,1,Q47)+(INDEX(Parameters!$D$12:$H$12,1,Q47+1)-INDEX(Parameters!$D$12:$H$12,1,Q47))*T47) -> 0.93333333 | I47: =F47*H47 -> 3173.3333 | J47: =IF('HSC Sweep'!$C$4="Type-B",INDEX(Parameters!$J$13:$N$13,1,R47)+(INDEX(Parameters!$J$13:$N$13,1,R47+1)-INDEX(Parameters!$J$13:$N$13,1,R47))*U47,INDEX(Parameters!$D$13:$H$13,1,R47)+(INDEX(Parameters!$D$13:$H$13,1,R47+1)-INDEX(Parameters!$D$13:$H$13,1,R47))*U47) -> 1500 | K47: =IF('HSC Sweep'!$C$4="Type-B",Parameters!$L$14,INDEX(Parameters!$D$14:$H$14,1,R47)+(INDEX(Parameters!$D$14:$H$14,1,R47+1)-INDEX(Parameters!$D$14:$H$14,1,R47))*U47) -> 0.45 | L47: =I47+J47 -> 4673.3333 | M47: =IF('HSC Sweep'!$C$4="Type-B",INDEX(Parameters!$J$17:$N$17,1,S47)+(INDEX(Parameters!$J$17:$N$17,1,S47+1)-INDEX(Parameters!$J$17:$N$17,1,S47))*V47,INDEX(Parameters!$D$17:$H$17,1,S47)+(INDEX(Parameters!$D$17:$H$17,1,S47+1)-INDEX(Parameters!$D$17:$H$17,1,S47))*V47) -> 2800 | N47: =IF('HSC Sweep'!$C$4="Type-B",INDEX(Parameters!$J$18:$N$18,1,S47)+(INDEX(Parameters!$J$18:$N$18,1,S47+1)-INDEX(Parameters!$J$18:$N$18,1,S47))*V47,INDEX(Parameters!$D$18:$H$18,1,S47)+(INDEX(Parameters!$D$18:$H$18,1,S47+1)-INDEX(Parameters!$D$18:$H$18,1,S47))*V47) -> 0.28 | O47: =IF('HSC Sweep'!$C$4="Type-B",INDEX(Parameters!$J$19:$N$19,1,S47)+(INDEX(Parameters!$J$19:$N$19,1,S47+1)-INDEX(Parameters!$J$19:$N$19,1,S47))*V47,INDEX(Parameters!$D$19:$H$19,1,S47)+(INDEX(Parameters!$D$19:$H$19,1,S47+1)-INDEX(Parameters!$D$19:$H$19,1,S47))*V47) -> 0.88 | P47: =M47*O47 -> 2464 | Q47: =MIN(4,MAX(1,INT((1+C47/Parameters!$D$23)*4)+1)) -> 3 | R47: =MIN(4,MAX(1,INT((1+D47/Parameters!$D$24)*4)+1)) -> 3 | S47: =MIN(4,MAX(1,INT((1+E47/Parameters!$D$26)*4)+1)) -> 3 | T47: =MAX(0,MIN(1,(1+C47/Parameters!$D$23)*4-(Q47-1))) -> 0.66666667 | U47: =MAX(0,MIN(1,(1+D47/Parameters!$D$24)*4-(R47-1))) -> 0 | V47: =MAX(0,MIN(1,(1+E47/Parameters!$D$26)*4-(S47-1))) -> 0
B48: ="C "&D48 -> C -5 | C48: ='HSC Sweep'!$C$6 -> -8 | D48: =Parameters!G8 -> -5 | E48: =Parameters!G16 -> -10 | F48: =IF('HSC Sweep'!$C$4="Type-B",INDEX(Parameters!$J$10:$N$10,1,Q48)+(INDEX(Parameters!$J$10:$N$10,1,Q48+1)-INDEX(Parameters!$J$10:$N$10,1,Q48))*T48,INDEX(Parameters!$D$10:$H$10,1,Q48)+(INDEX(Parameters!$D$10:$H$10,1,Q48+1)-INDEX(Parameters!$D$10:$H$10,1,Q48))*T48) -> 3400 | G48: =IF('HSC Sweep'!$C$4="Type-B",INDEX(Parameters!$J$11:$N$11,1,R48)+(INDEX(Parameters!$J$11:$N$11,1,R48+1)-INDEX(Parameters!$J$11:$N$11,1,R48))*U48,INDEX(Parameters!$D$11:$H$11,1,Q48)+(INDEX(Parameters!$D$11:$H$11,1,Q48+1)-INDEX(Parameters!$D$11:$H$11,1,Q48))*T48) -> 0.1 | H48: =IF('HSC Sweep'!$C$4="Type-B",INDEX(Parameters!$J$12:$N$12,1,Q48)+(INDEX(Parameters!$J$12:$N$12,1,Q48+1)-INDEX(Parameters!$J$12:$N$12,1,Q48))*T48,INDEX(Parameters!$D$12:$H$12,1,Q48)+(INDEX(Parameters!$D$12:$H$12,1,Q48+1)-INDEX(Parameters!$D$12:$H$12,1,Q48))*T48) -> 0.93333333 | I48: =F48*H48 -> 3173.3333 | J48: =IF('HSC Sweep'!$C$4="Type-B",INDEX(Parameters!$J$13:$N$13,1,R48)+(INDEX(Parameters!$J$13:$N$13,1,R48+1)-INDEX(Parameters!$J$13:$N$13,1,R48))*U48,INDEX(Parameters!$D$13:$H$13,1,R48)+(INDEX(Parameters!$D$13:$H$13,1,R48+1)-INDEX(Parameters!$D$13:$H$13,1,R48))*U48) -> 2200 | K48: =IF('HSC Sweep'!$C$4="Type-B",Parameters!$L$14,INDEX(Parameters!$D$14:$H$14,1,R48)+(INDEX(Parameters!$D$14:$H$14,1,R48+1)-INDEX(Parameters!$D$14:$H$14,1,R48))*U48) -> 0.455 | L48: =I48+J48 -> 5373.3333 | M48: =IF('HSC Sweep'!$C$4="Type-B",INDEX(Parameters!$J$17:$N$17,1,S48)+(INDEX(Parameters!$J$17:$N$17,1,S48+1)-INDEX(Parameters!$J$17:$N$17,1,S48))*V48,INDEX(Parameters!$D$17:$H$17,1,S48)+(INDEX(Parameters!$D$17:$H$17,1,S48+1)-INDEX(Parameters!$D$17:$H$17,1,S48))*V48) -> 3300 | N48: =IF('HSC Sweep'!$C$4="Type-B",INDEX(Parameters!$J$18:$N$18,1,S48)+(INDEX(Parameters!$J$18:$N$18,1,S48+1)-INDEX(Parameters!$J$18:$N$18,1,S48))*V48,INDEX(Parameters!$D$18:$H$18,1,S48)+(INDEX(Parameters!$D$18:$H$18,1,S48+1)-INDEX(Parameters!$D$18:$H$18,1,S48))*V48) -> 0.305 | O48: =IF('HSC Sweep'!$C$4="Type-B",INDEX(Parameters!$J$19:$N$19,1,S48)+(INDEX(Parameters!$J$19:$N$19,1,S48+1)-INDEX(Parameters!$J$19:$N$19,1,S48))*V48,INDEX(Parameters!$D$19:$H$19,1,S48)+(INDEX(Parameters!$D$19:$H$19,1,S48+1)-INDEX(Parameters!$D$19:$H$19,1,S48))*V48) -> 0.85 | P48: =M48*O48 -> 2805 | Q48: =MIN(4,MAX(1,INT((1+C48/Parameters!$D$23)*4)+1)) -> 3 | R48: =MIN(4,MAX(1,INT((1+D48/Parameters!$D$24)*4)+1)) -> 4 | S48: =MIN(4,MAX(1,INT((1+E48/Parameters!$D$26)*4)+1)) -> 4 | T48: =MAX(0,MIN(1,(1+C48/Parameters!$D$23)*4-(Q48-1))) -> 0.66666667 | U48: =MAX(0,MIN(1,(1+D48/Parameters!$D$24)*4-(R48-1))) -> 0 | V48: =MAX(0,MIN(1,(1+E48/Parameters!$D$26)*4-(S48-1))) -> 0
B49: ="C "&D49 -> C 0 | C49: ='HSC Sweep'!$C$6 -> -8 | D49: =Parameters!H8 -> 0 | E49: =Parameters!H16 -> 0 | F49: =IF('HSC Sweep'!$C$4="Type-B",INDEX(Parameters!$J$10:$N$10,1,Q49)+(INDEX(Parameters!$J$10:$N$10,1,Q49+1)-INDEX(Parameters!$J$10:$N$10,1,Q49))*T49,INDEX(Parameters!$D$10:$H$10,1,Q49)+(INDEX(Parameters!$D$10:$H$10,1,Q49+1)-INDEX(Parameters!$D$10:$H$10,1,Q49))*T49) -> 3400 | G49: =IF('HSC Sweep'!$C$4="Type-B",INDEX(Parameters!$J$11:$N$11,1,R49)+(INDEX(Parameters!$J$11:$N$11,1,R49+1)-INDEX(Parameters!$J$11:$N$11,1,R49))*U49,INDEX(Parameters!$D$11:$H$11,1,Q49)+(INDEX(Parameters!$D$11:$H$11,1,Q49+1)-INDEX(Parameters!$D$11:$H$11,1,Q49))*T49) -> 0.1 | H49: =IF('HSC Sweep'!$C$4="Type-B",INDEX(Parameters!$J$12:$N$12,1,Q49)+(INDEX(Parameters!$J$12:$N$12,1,Q49+1)-INDEX(Parameters!$J$12:$N$12,1,Q49))*T49,INDEX(Parameters!$D$12:$H$12,1,Q49)+(INDEX(Parameters!$D$12:$H$12,1,Q49+1)-INDEX(Parameters!$D$12:$H$12,1,Q49))*T49) -> 0.93333333 | I49: =F49*H49 -> 3173.3333 | J49: =IF('HSC Sweep'!$C$4="Type-B",INDEX(Parameters!$J$13:$N$13,1,R49)+(INDEX(Parameters!$J$13:$N$13,1,R49+1)-INDEX(Parameters!$J$13:$N$13,1,R49))*U49,INDEX(Parameters!$D$13:$H$13,1,R49)+(INDEX(Parameters!$D$13:$H$13,1,R49+1)-INDEX(Parameters!$D$13:$H$13,1,R49))*U49) -> 2900 | K49: =IF('HSC Sweep'!$C$4="Type-B",Parameters!$L$14,INDEX(Parameters!$D$14:$H$14,1,R49)+(INDEX(Parameters!$D$14:$H$14,1,R49+1)-INDEX(Parameters!$D$14:$H$14,1,R49))*U49) -> 0.46 | L49: =I49+J49 -> 6073.3333 | M49: =IF('HSC Sweep'!$C$4="Type-B",INDEX(Parameters!$J$17:$N$17,1,S49)+(INDEX(Parameters!$J$17:$N$17,1,S49+1)-INDEX(Parameters!$J$17:$N$17,1,S49))*V49,INDEX(Parameters!$D$17:$H$17,1,S49)+(INDEX(Parameters!$D$17:$H$17,1,S49+1)-INDEX(Parameters!$D$17:$H$17,1,S49))*V49) -> 3800 | N49: =IF('HSC Sweep'!$C$4="Type-B",INDEX(Parameters!$J$18:$N$18,1,S49)+(INDEX(Parameters!$J$18:$N$18,1,S49+1)-INDEX(Parameters!$J$18:$N$18,1,S49))*V49,INDEX(Parameters!$D$18:$H$18,1,S49)+(INDEX(Parameters!$D$18:$H$18,1,S49+1)-INDEX(Parameters!$D$18:$H$18,1,S49))*V49) -> 0.33 | O49: =IF('HSC Sweep'!$C$4="Type-B",INDEX(Parameters!$J$19:$N$19,1,S49)+(INDEX(Parameters!$J$19:$N$19,1,S49+1)-INDEX(Parameters!$J$19:$N$19,1,S49))*V49,INDEX(Parameters!$D$19:$H$19,1,S49)+(INDEX(Parameters!$D$19:$H$19,1,S49+1)-INDEX(Parameters!$D$19:$H$19,1,S49))*V49) -> 0.82 | P49: =M49*O49 -> 3116 | Q49: =MIN(4,MAX(1,INT((1+C49/Parameters!$D$23)*4)+1)) -> 3 | R49: =MIN(4,MAX(1,INT((1+D49/Parameters!$D$24)*4)+1)) -> 4 | S49: =MIN(4,MAX(1,INT((1+E49/Parameters!$D$26)*4)+1)) -> 4 | T49: =MAX(0,MIN(1,(1+C49/Parameters!$D$23)*4-(Q49-1))) -> 0.66666667 | U49: =MAX(0,MIN(1,(1+D49/Parameters!$D$24)*4-(R49-1))) -> 1 | V49: =MAX(0,MIN(1,(1+E49/Parameters!$D$26)*4-(S49-1))) -> 1
B53: =VLOOKUP("label.shaftVelocityMps",Locale!$A$2:$D$78,4,FALSE) -> 轴速 (m/s) | C53: =B45 -> C -20 | D53: =B46 -> C -15 | E53: =B47 -> C -10 | F53: =B48 -> C -5 | G53: =B49 -> C 0
B54: 0 | C54: =$F$45*MIN($B54,$G$45)+$I$45*MAX(0,$B54-$G$45)+$J$45*MAX(0,$B54-$K$45) -> 0 | D54: =$F$46*MIN($B54,$G$46)+$I$46*MAX(0,$B54-$G$46)+$J$46*MAX(0,$B54-$K$46) -> 0 | E54: =$F$47*MIN($B54,$G$47)+$I$47*MAX(0,$B54-$G$47)+$J$47*MAX(0,$B54-$K$47) -> 0 | F54: =$F$48*MIN($B54,$G$48)+$I$48*MAX(0,$B54-$G$48)+$J$48*MAX(0,$B54-$K$48) -> 0 | G54: =$F$49*MIN($B54,$G$49)+$I$49*MAX(0,$B54-$G$49)+$J$49*MAX(0,$B54-$K$49) -> 0
B55: 0.05 | C55: =$F$45*MIN($B55,$G$45)+$I$45*MAX(0,$B55-$G$45)+$J$45*MAX(0,$B55-$K$45) -> 170 | D55: =$F$46*MIN($B55,$G$46)+$I$46*MAX(0,$B55-$G$46)+$J$46*MAX(0,$B55-$K$46) -> 170 | E55: =$F$47*MIN($B55,$G$47)+$I$47*MAX(0,$B55-$G$47)+$J$47*MAX(0,$B55-$K$47) -> 170 | F55: =$F$48*MIN($B55,$G$48)+$I$48*MAX(0,$B55-$G$48)+$J$48*MAX(0,$B55-$K$48) -> 170 | G55: =$F$49*MIN($B55,$G$49)+$I$49*MAX(0,$B55-$G$49)+$J$49*MAX(0,$B55-$K$49) -> 170
B56: 0.1 | C56: =$F$45*MIN($B56,$G$45)+$I$45*MAX(0,$B56-$G$45)+$J$45*MAX(0,$B56-$K$45) -> 340 | D56: =$F$46*MIN($B56,$G$46)+$I$46*MAX(0,$B56-$G$46)+$J$46*MAX(0,$B56-$K$46) -> 340 | E56: =$F$47*MIN($B56,$G$47)+$I$47*MAX(0,$B56-$G$47)+$J$47*MAX(0,$B56-$K$47) -> 340 | F56: =$F$48*MIN($B56,$G$48)+$I$48*MAX(0,$B56-$G$48)+$J$48*MAX(0,$B56-$K$48) -> 340 | G56: =$F$49*MIN($B56,$G$49)+$I$49*MAX(0,$B56-$G$49)+$J$49*MAX(0,$B56-$K$49) -> 340
B57: 0.15 | C57: =$F$45*MIN($B57,$G$45)+$I$45*MAX(0,$B57-$G$45)+$J$45*MAX(0,$B57-$K$45) -> 498.66667 | D57: =$F$46*MIN($B57,$G$46)+$I$46*MAX(0,$B57-$G$46)+$J$46*MAX(0,$B57-$K$46) -> 498.66667 | E57: =$F$47*MIN($B57,$G$47)+$I$47*MAX(0,$B57-$G$47)+$J$47*MAX(0,$B57-$K$47) -> 498.66667 | F57: =$F$48*MIN($B57,$G$48)+$I$48*MAX(0,$B57-$G$48)+$J$48*MAX(0,$B57-$K$48) -> 498.66667 | G57: =$F$49*MIN($B57,$G$49)+$I$49*MAX(0,$B57-$G$49)+$J$49*MAX(0,$B57-$K$49) -> 498.66667
B58: 0.2 | C58: =$F$45*MIN($B58,$G$45)+$I$45*MAX(0,$B58-$G$45)+$J$45*MAX(0,$B58-$K$45) -> 657.33333 | D58: =$F$46*MIN($B58,$G$46)+$I$46*MAX(0,$B58-$G$46)+$J$46*MAX(0,$B58-$K$46) -> 657.33333 | E58: =$F$47*MIN($B58,$G$47)+$I$47*MAX(0,$B58-$G$47)+$J$47*MAX(0,$B58-$K$47) -> 657.33333 | F58: =$F$48*MIN($B58,$G$48)+$I$48*MAX(0,$B58-$G$48)+$J$48*MAX(0,$B58-$K$48) -> 657.33333 | G58: =$F$49*MIN($B58,$G$49)+$I$49*MAX(0,$B58-$G$49)+$J$49*MAX(0,$B58-$K$49) -> 657.33333
B59: 0.25 | C59: =$F$45*MIN($B59,$G$45)+$I$45*MAX(0,$B59-$G$45)+$J$45*MAX(0,$B59-$K$45) -> 816 | D59: =$F$46*MIN($B59,$G$46)+$I$46*MAX(0,$B59-$G$46)+$J$46*MAX(0,$B59-$K$46) -> 816 | E59: =$F$47*MIN($B59,$G$47)+$I$47*MAX(0,$B59-$G$47)+$J$47*MAX(0,$B59-$K$47) -> 816 | F59: =$F$48*MIN($B59,$G$48)+$I$48*MAX(0,$B59-$G$48)+$J$48*MAX(0,$B59-$K$48) -> 816 | G59: =$F$49*MIN($B59,$G$49)+$I$49*MAX(0,$B59-$G$49)+$J$49*MAX(0,$B59-$K$49) -> 816
B60: 0.3 | C60: =$F$45*MIN($B60,$G$45)+$I$45*MAX(0,$B60-$G$45)+$J$45*MAX(0,$B60-$K$45) -> 974.66667 | D60: =$F$46*MIN($B60,$G$46)+$I$46*MAX(0,$B60-$G$46)+$J$46*MAX(0,$B60-$K$46) -> 974.66667 | E60: =$F$47*MIN($B60,$G$47)+$I$47*MAX(0,$B60-$G$47)+$J$47*MAX(0,$B60-$K$47) -> 974.66667 | F60: =$F$48*MIN($B60,$G$48)+$I$48*MAX(0,$B60-$G$48)+$J$48*MAX(0,$B60-$K$48) -> 974.66667 | G60: =$F$49*MIN($B60,$G$49)+$I$49*MAX(0,$B60-$G$49)+$J$49*MAX(0,$B60-$K$49) -> 974.66667
B61: 0.35 | C61: =$F$45*MIN($B61,$G$45)+$I$45*MAX(0,$B61-$G$45)+$J$45*MAX(0,$B61-$K$45) -> 1133.3333 | D61: =$F$46*MIN($B61,$G$46)+$I$46*MAX(0,$B61-$G$46)+$J$46*MAX(0,$B61-$K$46) -> 1133.3333 | E61: =$F$47*MIN($B61,$G$47)+$I$47*MAX(0,$B61-$G$47)+$J$47*MAX(0,$B61-$K$47) -> 1133.3333 | F61: =$F$48*MIN($B61,$G$48)+$I$48*MAX(0,$B61-$G$48)+$J$48*MAX(0,$B61-$K$48) -> 1133.3333 | G61: =$F$49*MIN($B61,$G$49)+$I$49*MAX(0,$B61-$G$49)+$J$49*MAX(0,$B61-$K$49) -> 1133.3333
B62: 0.4 | C62: =$F$45*MIN($B62,$G$45)+$I$45*MAX(0,$B62-$G$45)+$J$45*MAX(0,$B62-$K$45) -> 1292 | D62: =$F$46*MIN($B62,$G$46)+$I$46*MAX(0,$B62-$G$46)+$J$46*MAX(0,$B62-$K$46) -> 1292 | E62: =$F$47*MIN($B62,$G$47)+$I$47*MAX(0,$B62-$G$47)+$J$47*MAX(0,$B62-$K$47) -> 1292 | F62: =$F$48*MIN($B62,$G$48)+$I$48*MAX(0,$B62-$G$48)+$J$48*MAX(0,$B62-$K$48) -> 1292 | G62: =$F$49*MIN($B62,$G$49)+$I$49*MAX(0,$B62-$G$49)+$J$49*MAX(0,$B62-$K$49) -> 1292
B63: 0.45 | C63: =$F$45*MIN($B63,$G$45)+$I$45*MAX(0,$B63-$G$45)+$J$45*MAX(0,$B63-$K$45) -> 1451.6667 | D63: =$F$46*MIN($B63,$G$46)+$I$46*MAX(0,$B63-$G$46)+$J$46*MAX(0,$B63-$K$46) -> 1454.6667 | E63: =$F$47*MIN($B63,$G$47)+$I$47*MAX(0,$B63-$G$47)+$J$47*MAX(0,$B63-$K$47) -> 1450.6667 | F63: =$F$48*MIN($B63,$G$48)+$I$48*MAX(0,$B63-$G$48)+$J$48*MAX(0,$B63-$K$48) -> 1450.6667 | G63: =$F$49*MIN($B63,$G$49)+$I$49*MAX(0,$B63-$G$49)+$J$49*MAX(0,$B63-$K$49) -> 1450.6667
B64: 0.5 | C64: =$F$45*MIN($B64,$G$45)+$I$45*MAX(0,$B64-$G$45)+$J$45*MAX(0,$B64-$K$45) -> 1615.3333 | D64: =$F$46*MIN($B64,$G$46)+$I$46*MAX(0,$B64-$G$46)+$J$46*MAX(0,$B64-$K$46) -> 1653.3333 | E64: =$F$47*MIN($B64,$G$47)+$I$47*MAX(0,$B64-$G$47)+$J$47*MAX(0,$B64-$K$47) -> 1684.3333 | F64: =$F$48*MIN($B64,$G$48)+$I$48*MAX(0,$B64-$G$48)+$J$48*MAX(0,$B64-$K$48) -> 1708.3333 | G64: =$F$49*MIN($B64,$G$49)+$I$49*MAX(0,$B64-$G$49)+$J$49*MAX(0,$B64-$K$49) -> 1725.3333
...
