Workbook

Sheet Calculator
B2: CTM Racing · MRAx0 · Damping Calculator
B4: Valving | C4: Type-A | E4: MRA60 / MRA80 · 柏油拉力 · c / C / R 调节与阻尼力计算
B6: 避震器型号 | C6: MRA60 | F6: 当前输入 · 阻尼力大小
B7: LSC · c | C7: -12
B8: HSC · C | C8: -10 | F8: 压缩力 (N) | I8: =IF(C18="OK",Samples!F165*MIN(C10,Samples!G165)+Samples!I165*MAX(0,C10-Samples!G165)+Samples!J165*MAX(0,C10-Samples!K165),"检查输入") -> 1736.47
B9: LSR · R | C9: -20
B10: 轴速 (m/s) | C10: 0.45 | F10: 回弹力 (N) | I10: =IF(C18="OK",Samples!M165*MIN(C10,Samples!N165)+Samples!P165*MAX(0,C10-Samples!N165),"检查输入") -> 1519.2
B13: c 总格数 | C13: =Parameters!D23 -> 24 | F13: 当前曲线参数
B14: C 总格数 | C14: =Parameters!D24 -> 20 | F14: bump1 | I14: =Samples!F165 -> 3650 | J14: N·s/m
B15: R 总格数 | C15: =IF(C6="MRA80",Parameters!D26,Parameters!D25) -> 40 | F15: bump2 | I15: =Samples!I165 -> 3431 | J15: N·s/m
F16: HSbump · 高速增量 | I16: =Samples!J165 -> 1750 | J16: N·s/m
F17: 总高速系数 | I17: =Samples!L165 -> 5181 | J17: N·s/m
B18: 输入检查 | C18: =IF(AND(OR(C4="Type-A",C4="Type-B"),OR(C6="MRA60",C6="MRA80",C6="MRA80 (Mod)"),COUNT(C7:C10)=4,C7>=-C13,C7<=0,C8>=-C14,C8<=0,C9>=-C15,C9<=0,C10>=0,INT(C7)=C7,INT(C8)=C8,INT(C9)=C9),"OK","检查输入") -> OK
F19: rebound | I19: =Samples!M165 -> 3600 | J19: N·s/m
F20: HSrebound | I20: =Samples!P165 -> 3096 | J20: N·s/m
F22: 第一 knee | I22: =Samples!G165 -> 0.08 | J22: m/s
F23: 第二 knee | I23: =Samples!K165 -> 0.35 | J23: m/s
F24: Rebound knee | I24: =Samples!N165 -> 0.25 | J24: m/s
B27: 计算器支持任意非负轴速；Sweep 图显示 0–0.6 m/s。斜率和膝点由所选阀系插值得到。

Sheet LSC Sweep
B2: CTM Racing · MRAx0 · LSC Sweep
B4: Valving | C4: Type-A | E4: 柏油拉力 · Type-A / Type-B 阀系；各页独立选择。
B6: 固定 HSC | C6: -10 | E6: LSC：最软 / 25% / 默认 / 75% / 最硬
B41: 轴速 0～1 m/s · 每 0.05 m/s 一点 · 直线连接 · 详细计算与采样位于 Samples

Sheet HSC Sweep
B2: CTM Racing · MRAx0 · HSC Sweep
B4: Valving | C4: Type-B | E4: 柏油拉力 · Type-A / Type-B 阀系；各页独立选择。
B6: 固定 LSC | C6: -12 | E6: HSC：最软 / 25% / 默认 / 75% / 最硬
B41: 轴速 0～1 m/s · 每 0.05 m/s 一点 · 直线连接 · 详细计算与采样位于 Samples

Sheet LSR Sweep
B2: CTM Racing · MRAx0 · LSR Sweep
B4: Valving | C4: Type-A | E4: 柏油拉力 · Type-A / Type-B 阀系；各页独立选择。
B6: LSR：−40 / −30 / −20 / −10 / 0 R；图中显示回弹力大小。
B41: 轴速 0～1 m/s · 每 0.05 m/s 一点 · 直线连接 · 详细计算与采样位于 Samples

Sheet Full Sweep
B2: CTM Racing · MRAx0 · Full Sweep
B4: Valving | C4: Type-A | E4: 柏油拉力 · Type-A / Type-B 阀系；各页独立选择。
B6: 压缩与回弹各五条：最软 / 25% / 默认 / 75% / 最硬。
B41: 轴速 0～1 m/s · 每 0.05 m/s 一点 · 直线连接 · 详细计算与采样位于 Samples

Sheet Parameters
B2: CTM Racing · MRAx0 · Valving Parameters
B3: MRA60 / MRA80 / MRA80 (Mod) · 柏油拉力系列；黄色单元格为可编辑标定。
D5: Type-A | J5: Type-B
B6: 调节位置 | C6: 比例 | D6: 0 | E6: 0.25 | F6: 0.5 | G6: 0.75 | H6: 1 | J6: =D6 -> 0 | K6: =E6 -> 0.25 | L6: =F6 -> 0.5 | M6: =G6 -> 0.75 | N6: =H6 -> 1
B7: LSC · c | C7: 格 | D7: =(D$6-1)*$D$23 -> -24 | E7: =(E$6-1)*$D$23 -> -18 | F7: =(F$6-1)*$D$23 -> -12 | G7: =(G$6-1)*$D$23 -> -6 | H7: =(H$6-1)*$D$23 -> 0 | J7: =(J$6-1)*$D$23 -> -24 | K7: =(K$6-1)*$D$23 -> -18 | L7: =(L$6-1)*$D$23 -> -12 | M7: =(M$6-1)*$D$23 -> -6 | N7: =(N$6-1)*$D$23 -> 0
B8: HSC · C | C8: 格 | D8: =(D$6-1)*$D$24 -> -20 | E8: =(E$6-1)*$D$24 -> -15 | F8: =(F$6-1)*$D$24 -> -10 | G8: =(G$6-1)*$D$24 -> -5 | H8: =(H$6-1)*$D$24 -> 0 | J8: =(J$6-1)*$D$24 -> -20 | K8: =(K$6-1)*$D$24 -> -15 | L8: =(L$6-1)*$D$24 -> -10 | M8: =(M$6-1)*$D$24 -> -5 | N8: =(N$6-1)*$D$24 -> 0
B10: bump1 | C10: N·s/m | D10: 1850 | E10: =(D10+F10)/2 -> 2750 | F10: 3650 | G10: =(F10+H10)/2 -> 4550 | H10: 5450 | J10: 2400 | K10: =(J10+L10)/2 -> 3300 | L10: 4200 | M10: =(L10+N10)/2 -> 5100 | N10: 6000
B11: 第一 knee | C11: m/s | D11: 0.08 | E11: =(D11+F11)/2 -> 0.08 | F11: 0.08 | G11: =(F11+H11)/2 -> 0.08 | H11: 0.08 | J11: 0.2 | K11: =(J11+L11)/2 -> 0.25 | L11: 0.3 | M11: =(L11+N11)/2 -> 0.35 | N11: 0.4
B12: bump2 / bump1 | C12: 倍率 | D12: 1 | E12: =(D12+F12)/2 -> 0.97 | F12: 0.94 | G12: =(F12+H12)/2 -> 0.91 | H12: 0.88 | J12: 0.73 | K12: =(J12+L12)/2 -> 0.71 | L12: 0.69 | M12: =(L12+N12)/2 -> 0.67 | N12: 0.65
B13: HSbump · 高速增量 | C13: N·s/m | D13: 250 | E13: =(D13+F13)/2 -> 1000 | F13: 1750 | G13: =(F13+H13)/2 -> 2500 | H13: 3250 | J13: 0 | K13: 0 | L13: 0 | M13: 0 | N13: 0
B14: 第二 knee | C14: m/s | D14: 0.34 | E14: 0.345 | F14: 0.35 | G14: 0.355 | H14: 0.36 | J14: =$L$14 -> 0.6 | K14: =$L$14 -> 0.6 | L14: 0.6 | M14: =$L$14 -> 0.6 | N14: =$L$14 -> 0.6
B16: LSR · R（MRA60） | C16: 格 | D16: =(D$6-1)*$D$25 -> -40 | E16: =(E$6-1)*$D$25 -> -30 | F16: =(F$6-1)*$D$25 -> -20 | G16: =(G$6-1)*$D$25 -> -10 | H16: =(H$6-1)*$D$25 -> 0 | J16: =(J$6-1)*$D$25 -> -40 | K16: =(K$6-1)*$D$25 -> -30 | L16: =(L$6-1)*$D$25 -> -20 | M16: =(M$6-1)*$D$25 -> -10 | N16: =(N$6-1)*$D$25 -> 0
B17: rebound | C17: N·s/m | D17: 2100 | E17: =(D17+F17)/2 -> 2850 | F17: 3600 | G17: =(F17+H17)/2 -> 4350 | H17: 5100 | J17: 3000 | K17: =(J17+L17)/2 -> 3750 | L17: 4500 | M17: =(L17+N17)/2 -> 5250 | N17: 6000
B18: Rebound knee | C18: m/s | D18: 0.23 | E18: =(D18+F18)/2 -> 0.24 | F18: 0.25 | G18: =(F18+H18)/2 -> 0.26 | H18: 0.27 | J18: 0.21 | K18: =(J18+L18)/2 -> 0.215 | L18: 0.22 | M18: =(L18+N18)/2 -> 0.225 | N18: 0.23
B19: HSrebound / rebound | C19: 倍率 | D19: 0.92 | E19: =(D19+F19)/2 -> 0.89 | F19: 0.86 | G19: =(F19+H19)/2 -> 0.83 | H19: 0.8 | J19: 0.68 | K19: =(J19+L19)/2 -> 0.65 | L19: 0.62 | M19: =(L19+N19)/2 -> 0.59 | N19: 0.56
B22: Adjusters · 调节格数
B23: LSC · 全系列 | D23: 24 | F23: MRA60 与 MRA80 (Mod)：40 格回弹；MRA80：60 格。Sweep 采用 40 格标尺，型号在计算器选择。
B24: HSC · 全系列 | D24: 20
B25: LSR · MRA60 / 8系改型 | D25: 40
B26: LSR · MRA80 | D26: 60 | F26: 0 为最硬；负数为从全关退出的格数。
B28: Model · 基础阻尼模型
B29: bump2 = bump1 × 中间段倍率；总高速系数 = bump2 + HSbump。
B30: 压缩力 = bump1 × MIN(v, 第一 knee) + bump2 × MAX(0, v − 第一 knee) + HSbump × MAX(0, v − 第二 knee)。
B31: 回弹力 = rebound × MIN(v, Rebound knee) + HSrebound × MAX(0, v − Rebound knee)。
B32: 理论曲线采用连续分段接续假设；仅计算基础阻尼，不包含气体支撑、弹簧、HBS/HRS 或 LRS/DSV。
B33: LSC 只调斜率；Type-A 的 HSC 调第二 knee，Type-B 的 HSC 调第一 knee。
B34: Type-B：HSC 控制第一 knee，无 HS 附加阻尼。Type-A：HSC 控制高速增量和第二 knee。
B35: 研究来源：chatgpt-conversation://6a9ed043-7848-83e8-9d36-6e63c8202898

Sheet Samples
B1: CTM Racing · MRAx0 · LSC Sweep · 读取对应 Sweep 页的阀系选择
B4: 曲线 | C4: c | D4: C | E4: R | F4: bump1 | G4: 第一 knee | H4: bump2 倍率 | I4: bump2 | J4: HSbump | K4: 第二 knee | L4: 总 HS 系数 | M4: rebound | N4: Rebound knee | O4: HSR 倍率 | P4: HSrebound | Q4: LSC 区间 | R4: HSC 区间 | S4: LSR 区间 | T4: LSC 区间位置 | U4: HSC 区间位置 | V4: LSR 区间位置
B5: ="c "&C5 -> c -24 | C5: =Parameters!D7 -> -24 | D5: ='LSC Sweep'!$C$6 -> -10 | E5: =Parameters!D16 -> -40 | F5: =IF('LSC Sweep'!$C$4="Type-B",INDEX(Parameters!$J$10:$N$10,1,Q5)+(INDEX(Parameters!$J$10:$N$10,1,Q5+1)-INDEX(Parameters!$J$10:$N$10,1,Q5))*T5,INDEX(Parameters!$D$10:$H$10,1,Q5)+(INDEX(Parameters!$D$10:$H$10,1,Q5+1)-INDEX(Parameters!$D$10:$H$10,1,Q5))*T5) -> 1850 | G5: =IF('LSC Sweep'!$C$4="Type-B",INDEX(Parameters!$J$11:$N$11,1,R5)+(INDEX(Parameters!$J$11:$N$11,1,R5+1)-INDEX(Parameters!$J$11:$N$11,1,R5))*U5,INDEX(Parameters!$D$11:$H$11,1,Q5)+(INDEX(Parameters!$D$11:$H$11,1,Q5+1)-INDEX(Parameters!$D$11:$H$11,1,Q5))*T5) -> 0.08 | H5: =IF('LSC Sweep'!$C$4="Type-B",INDEX(Parameters!$J$12:$N$12,1,Q5)+(INDEX(Parameters!$J$12:$N$12,1,Q5+1)-INDEX(Parameters!$J$12:$N$12,1,Q5))*T5,INDEX(Parameters!$D$12:$H$12,1,Q5)+(INDEX(Parameters!$D$12:$H$12,1,Q5+1)-INDEX(Parameters!$D$12:$H$12,1,Q5))*T5) -> 1 | I5: =F5*H5 -> 1850 | J5: =IF('LSC Sweep'!$C$4="Type-B",INDEX(Parameters!$J$13:$N$13,1,R5)+(INDEX(Parameters!$J$13:$N$13,1,R5+1)-INDEX(Parameters!$J$13:$N$13,1,R5))*U5,INDEX(Parameters!$D$13:$H$13,1,R5)+(INDEX(Parameters!$D$13:$H$13,1,R5+1)-INDEX(Parameters!$D$13:$H$13,1,R5))*U5) -> 1750 | K5: =IF('LSC Sweep'!$C$4="Type-B",Parameters!$L$14,INDEX(Parameters!$D$14:$H$14,1,R5)+(INDEX(Parameters!$D$14:$H$14,1,R5+1)-INDEX(Parameters!$D$14:$H$14,1,R5))*U5) -> 0.35 | L5: =I5+J5 -> 3600 | M5: =IF('LSC Sweep'!$C$4="Type-B",INDEX(Parameters!$J$17:$N$17,1,S5)+(INDEX(Parameters!$J$17:$N$17,1,S5+1)-INDEX(Parameters!$J$17:$N$17,1,S5))*V5,INDEX(Parameters!$D$17:$H$17,1,S5)+(INDEX(Parameters!$D$17:$H$17,1,S5+1)-INDEX(Parameters!$D$17:$H$17,1,S5))*V5) -> 2100 | N5: =IF('LSC Sweep'!$C$4="Type-B",INDEX(Parameters!$J$18:$N$18,1,S5)+(INDEX(Parameters!$J$18:$N$18,1,S5+1)-INDEX(Parameters!$J$18:$N$18,1,S5))*V5,INDEX(Parameters!$D$18:$H$18,1,S5)+(INDEX(Parameters!$D$18:$H$18,1,S5+1)-INDEX(Parameters!$D$18:$H$18,1,S5))*V5) -> 0.23 | O5: =IF('LSC Sweep'!$C$4="Type-B",INDEX(Parameters!$J$19:$N$19,1,S5)+(INDEX(Parameters!$J$19:$N$19,1,S5+1)-INDEX(Parameters!$J$19:$N$19,1,S5))*V5,INDEX(Parameters!$D$19:$H$19,1,S5)+(INDEX(Parameters!$D$19:$H$19,1,S5+1)-INDEX(Parameters!$D$19:$H$19,1,S5))*V5) -> 0.92 | P5: =M5*O5 -> 1932 | Q5: =MIN(4,MAX(1,INT((1+C5/Parameters!$D$23)*4)+1)) -> 1 | R5: =MIN(4,MAX(1,INT((1+D5/Parameters!$D$24)*4)+1)) -> 3 | S5: =MIN(4,MAX(1,INT((1+E5/Parameters!$D$25)*4)+1)) -> 1 | T5: =MAX(0,MIN(1,(1+C5/Parameters!$D$23)*4-(Q5-1))) -> 0 | U5: =MAX(0,MIN(1,(1+D5/Parameters!$D$24)*4-(R5-1))) -> 0 | V5: =MAX(0,MIN(1,(1+E5/Parameters!$D$25)*4-(S5-1))) -> 0
B6: ="c "&C6 -> c -18 | C6: =Parameters!E7 -> -18 | D6: ='LSC Sweep'!$C$6 -> -10 | E6: =Parameters!E16 -> -30 | F6: =IF('LSC Sweep'!$C$4="Type-B",INDEX(Parameters!$J$10:$N$10,1,Q6)+(INDEX(Parameters!$J$10:$N$10,1,Q6+1)-INDEX(Parameters!$J$10:$N$10,1,Q6))*T6,INDEX(Parameters!$D$10:$H$10,1,Q6)+(INDEX(Parameters!$D$10:$H$10,1,Q6+1)-INDEX(Parameters!$D$10:$H$10,1,Q6))*T6) -> 2750 | G6: =IF('LSC Sweep'!$C$4="Type-B",INDEX(Parameters!$J$11:$N$11,1,R6)+(INDEX(Parameters!$J$11:$N$11,1,R6+1)-INDEX(Parameters!$J$11:$N$11,1,R6))*U6,INDEX(Parameters!$D$11:$H$11,1,Q6)+(INDEX(Parameters!$D$11:$H$11,1,Q6+1)-INDEX(Parameters!$D$11:$H$11,1,Q6))*T6) -> 0.08 | H6: =IF('LSC Sweep'!$C$4="Type-B",INDEX(Parameters!$J$12:$N$12,1,Q6)+(INDEX(Parameters!$J$12:$N$12,1,Q6+1)-INDEX(Parameters!$J$12:$N$12,1,Q6))*T6,INDEX(Parameters!$D$12:$H$12,1,Q6)+(INDEX(Parameters!$D$12:$H$12,1,Q6+1)-INDEX(Parameters!$D$12:$H$12,1,Q6))*T6) -> 0.97 | I6: =F6*H6 -> 2667.5 | J6: =IF('LSC Sweep'!$C$4="Type-B",INDEX(Parameters!$J$13:$N$13,1,R6)+(INDEX(Parameters!$J$13:$N$13,1,R6+1)-INDEX(Parameters!$J$13:$N$13,1,R6))*U6,INDEX(Parameters!$D$13:$H$13,1,R6)+(INDEX(Parameters!$D$13:$H$13,1,R6+1)-INDEX(Parameters!$D$13:$H$13,1,R6))*U6) -> 1750 | K6: =IF('LSC Sweep'!$C$4="Type-B",Parameters!$L$14,INDEX(Parameters!$D$14:$H$14,1,R6)+(INDEX(Parameters!$D$14:$H$14,1,R6+1)-INDEX(Parameters!$D$14:$H$14,1,R6))*U6) -> 0.35 | L6: =I6+J6 -> 4417.5 | M6: =IF('LSC Sweep'!$C$4="Type-B",INDEX(Parameters!$J$17:$N$17,1,S6)+(INDEX(Parameters!$J$17:$N$17,1,S6+1)-INDEX(Parameters!$J$17:$N$17,1,S6))*V6,INDEX(Parameters!$D$17:$H$17,1,S6)+(INDEX(Parameters!$D$17:$H$17,1,S6+1)-INDEX(Parameters!$D$17:$H$17,1,S6))*V6) -> 2850 | N6: =IF('LSC Sweep'!$C$4="Type-B",INDEX(Parameters!$J$18:$N$18,1,S6)+(INDEX(Parameters!$J$18:$N$18,1,S6+1)-INDEX(Parameters!$J$18:$N$18,1,S6))*V6,INDEX(Parameters!$D$18:$H$18,1,S6)+(INDEX(Parameters!$D$18:$H$18,1,S6+1)-INDEX(Parameters!$D$18:$H$18,1,S6))*V6) -> 0.24 | O6: =IF('LSC Sweep'!$C$4="Type-B",INDEX(Parameters!$J$19:$N$19,1,S6)+(INDEX(Parameters!$J$19:$N$19,1,S6+1)-INDEX(Parameters!$J$19:$N$19,1,S6))*V6,INDEX(Parameters!$D$19:$H$19,1,S6)+(INDEX(Parameters!$D$19:$H$19,1,S6+1)-INDEX(Parameters!$D$19:$H$19,1,S6))*V6) -> 0.89 | P6: =M6*O6 -> 2536.5 | Q6: =MIN(4,MAX(1,INT((1+C6/Parameters!$D$23)*4)+1)) -> 2 | R6: =MIN(4,MAX(1,INT((1+D6/Parameters!$D$24)*4)+1)) -> 3 | S6: =MIN(4,MAX(1,INT((1+E6/Parameters!$D$25)*4)+1)) -> 2 | T6: =MAX(0,MIN(1,(1+C6/Parameters!$D$23)*4-(Q6-1))) -> 0 | U6: =MAX(0,MIN(1,(1+D6/Parameters!$D$24)*4-(R6-1))) -> 0 | V6: =MAX(0,MIN(1,(1+E6/Parameters!$D$25)*4-(S6-1))) -> 0
B7: ="c "&C7 -> c -12 | C7: =Parameters!F7 -> -12 | D7: ='LSC Sweep'!$C$6 -> -10 | E7: =Parameters!F16 -> -20 | F7: =IF('LSC Sweep'!$C$4="Type-B",INDEX(Parameters!$J$10:$N$10,1,Q7)+(INDEX(Parameters!$J$10:$N$10,1,Q7+1)-INDEX(Parameters!$J$10:$N$10,1,Q7))*T7,INDEX(Parameters!$D$10:$H$10,1,Q7)+(INDEX(Parameters!$D$10:$H$10,1,Q7+1)-INDEX(Parameters!$D$10:$H$10,1,Q7))*T7) -> 3650 | G7: =IF('LSC Sweep'!$C$4="Type-B",INDEX(Parameters!$J$11:$N$11,1,R7)+(INDEX(Parameters!$J$11:$N$11,1,R7+1)-INDEX(Parameters!$J$11:$N$11,1,R7))*U7,INDEX(Parameters!$D$11:$H$11,1,Q7)+(INDEX(Parameters!$D$11:$H$11,1,Q7+1)-INDEX(Parameters!$D$11:$H$11,1,Q7))*T7) -> 0.08 | H7: =IF('LSC Sweep'!$C$4="Type-B",INDEX(Parameters!$J$12:$N$12,1,Q7)+(INDEX(Parameters!$J$12:$N$12,1,Q7+1)-INDEX(Parameters!$J$12:$N$12,1,Q7))*T7,INDEX(Parameters!$D$12:$H$12,1,Q7)+(INDEX(Parameters!$D$12:$H$12,1,Q7+1)-INDEX(Parameters!$D$12:$H$12,1,Q7))*T7) -> 0.94 | I7: =F7*H7 -> 3431 | J7: =IF('LSC Sweep'!$C$4="Type-B",INDEX(Parameters!$J$13:$N$13,1,R7)+(INDEX(Parameters!$J$13:$N$13,1,R7+1)-INDEX(Parameters!$J$13:$N$13,1,R7))*U7,INDEX(Parameters!$D$13:$H$13,1,R7)+(INDEX(Parameters!$D$13:$H$13,1,R7+1)-INDEX(Parameters!$D$13:$H$13,1,R7))*U7) -> 1750 | K7: =IF('LSC Sweep'!$C$4="Type-B",Parameters!$L$14,INDEX(Parameters!$D$14:$H$14,1,R7)+(INDEX(Parameters!$D$14:$H$14,1,R7+1)-INDEX(Parameters!$D$14:$H$14,1,R7))*U7) -> 0.35 | L7: =I7+J7 -> 5181 | M7: =IF('LSC Sweep'!$C$4="Type-B",INDEX(Parameters!$J$17:$N$17,1,S7)+(INDEX(Parameters!$J$17:$N$17,1,S7+1)-INDEX(Parameters!$J$17:$N$17,1,S7))*V7,INDEX(Parameters!$D$17:$H$17,1,S7)+(INDEX(Parameters!$D$17:$H$17,1,S7+1)-INDEX(Parameters!$D$17:$H$17,1,S7))*V7) -> 3600 | N7: =IF('LSC Sweep'!$C$4="Type-B",INDEX(Parameters!$J$18:$N$18,1,S7)+(INDEX(Parameters!$J$18:$N$18,1,S7+1)-INDEX(Parameters!$J$18:$N$18,1,S7))*V7,INDEX(Parameters!$D$18:$H$18,1,S7)+(INDEX(Parameters!$D$18:$H$18,1,S7+1)-INDEX(Parameters!$D$18:$H$18,1,S7))*V7) -> 0.25 | O7: =IF('LSC Sweep'!$C$4="Type-B",INDEX(Parameters!$J$19:$N$19,1,S7)+(INDEX(Parameters!$J$19:$N$19,1,S7+1)-INDEX(Parameters!$J$19:$N$19,1,S7))*V7,INDEX(Parameters!$D$19:$H$19,1,S7)+(INDEX(Parameters!$D$19:$H$19,1,S7+1)-INDEX(Parameters!$D$19:$H$19,1,S7))*V7) -> 0.86 | P7: =M7*O7 -> 3096 | Q7: =MIN(4,MAX(1,INT((1+C7/Parameters!$D$23)*4)+1)) -> 3 | R7: =MIN(4,MAX(1,INT((1+D7/Parameters!$D$24)*4)+1)) -> 3 | S7: =MIN(4,MAX(1,INT((1+E7/Parameters!$D$25)*4)+1)) -> 3 | T7: =MAX(0,MIN(1,(1+C7/Parameters!$D$23)*4-(Q7-1))) -> 0 | U7: =MAX(0,MIN(1,(1+D7/Parameters!$D$24)*4-(R7-1))) -> 0 | V7: =MAX(0,MIN(1,(1+E7/Parameters!$D$25)*4-(S7-1))) -> 0
B8: ="c "&C8 -> c -6 | C8: =Parameters!G7 -> -6 | D8: ='LSC Sweep'!$C$6 -> -10 | E8: =Parameters!G16 -> -10 | F8: =IF('LSC Sweep'!$C$4="Type-B",INDEX(Parameters!$J$10:$N$10,1,Q8)+(INDEX(Parameters!$J$10:$N$10,1,Q8+1)-INDEX(Parameters!$J$10:$N$10,1,Q8))*T8,INDEX(Parameters!$D$10:$H$10,1,Q8)+(INDEX(Parameters!$D$10:$H$10,1,Q8+1)-INDEX(Parameters!$D$10:$H$10,1,Q8))*T8) -> 4550 | G8: =IF('LSC Sweep'!$C$4="Type-B",INDEX(Parameters!$J$11:$N$11,1,R8)+(INDEX(Parameters!$J$11:$N$11,1,R8+1)-INDEX(Parameters!$J$11:$N$11,1,R8))*U8,INDEX(Parameters!$D$11:$H$11,1,Q8)+(INDEX(Parameters!$D$11:$H$11,1,Q8+1)-INDEX(Parameters!$D$11:$H$11,1,Q8))*T8) -> 0.08 | H8: =IF('LSC Sweep'!$C$4="Type-B",INDEX(Parameters!$J$12:$N$12,1,Q8)+(INDEX(Parameters!$J$12:$N$12,1,Q8+1)-INDEX(Parameters!$J$12:$N$12,1,Q8))*T8,INDEX(Parameters!$D$12:$H$12,1,Q8)+(INDEX(Parameters!$D$12:$H$12,1,Q8+1)-INDEX(Parameters!$D$12:$H$12,1,Q8))*T8) -> 0.91 | I8: =F8*H8 -> 4140.5 | J8: =IF('LSC Sweep'!$C$4="Type-B",INDEX(Parameters!$J$13:$N$13,1,R8)+(INDEX(Parameters!$J$13:$N$13,1,R8+1)-INDEX(Parameters!$J$13:$N$13,1,R8))*U8,INDEX(Parameters!$D$13:$H$13,1,R8)+(INDEX(Parameters!$D$13:$H$13,1,R8+1)-INDEX(Parameters!$D$13:$H$13,1,R8))*U8) -> 1750 | K8: =IF('LSC Sweep'!$C$4="Type-B",Parameters!$L$14,INDEX(Parameters!$D$14:$H$14,1,R8)+(INDEX(Parameters!$D$14:$H$14,1,R8+1)-INDEX(Parameters!$D$14:$H$14,1,R8))*U8) -> 0.35 | L8: =I8+J8 -> 5890.5 | M8: =IF('LSC Sweep'!$C$4="Type-B",INDEX(Parameters!$J$17:$N$17,1,S8)+(INDEX(Parameters!$J$17:$N$17,1,S8+1)-INDEX(Parameters!$J$17:$N$17,1,S8))*V8,INDEX(Parameters!$D$17:$H$17,1,S8)+(INDEX(Parameters!$D$17:$H$17,1,S8+1)-INDEX(Parameters!$D$17:$H$17,1,S8))*V8) -> 4350 | N8: =IF('LSC Sweep'!$C$4="Type-B",INDEX(Parameters!$J$18:$N$18,1,S8)+(INDEX(Parameters!$J$18:$N$18,1,S8+1)-INDEX(Parameters!$J$18:$N$18,1,S8))*V8,INDEX(Parameters!$D$18:$H$18,1,S8)+(INDEX(Parameters!$D$18:$H$18,1,S8+1)-INDEX(Parameters!$D$18:$H$18,1,S8))*V8) -> 0.26 | O8: =IF('LSC Sweep'!$C$4="Type-B",INDEX(Parameters!$J$19:$N$19,1,S8)+(INDEX(Parameters!$J$19:$N$19,1,S8+1)-INDEX(Parameters!$J$19:$N$19,1,S8))*V8,INDEX(Parameters!$D$19:$H$19,1,S8)+(INDEX(Parameters!$D$19:$H$19,1,S8+1)-INDEX(Parameters!$D$19:$H$19,1,S8))*V8) -> 0.83 | P8: =M8*O8 -> 3610.5 | Q8: =MIN(4,MAX(1,INT((1+C8/Parameters!$D$23)*4)+1)) -> 4 | R8: =MIN(4,MAX(1,INT((1+D8/Parameters!$D$24)*4)+1)) -> 3 | S8: =MIN(4,MAX(1,INT((1+E8/Parameters!$D$25)*4)+1)) -> 4 | T8: =MAX(0,MIN(1,(1+C8/Parameters!$D$23)*4-(Q8-1))) -> 0 | U8: =MAX(0,MIN(1,(1+D8/Parameters!$D$24)*4-(R8-1))) -> 0 | V8: =MAX(0,MIN(1,(1+E8/Parameters!$D$25)*4-(S8-1))) -> 0
B9: ="c "&C9 -> c 0 | C9: =Parameters!H7 -> 0 | D9: ='LSC Sweep'!$C$6 -> -10 | E9: =Parameters!H16 -> 0 | F9: =IF('LSC Sweep'!$C$4="Type-B",INDEX(Parameters!$J$10:$N$10,1,Q9)+(INDEX(Parameters!$J$10:$N$10,1,Q9+1)-INDEX(Parameters!$J$10:$N$10,1,Q9))*T9,INDEX(Parameters!$D$10:$H$10,1,Q9)+(INDEX(Parameters!$D$10:$H$10,1,Q9+1)-INDEX(Parameters!$D$10:$H$10,1,Q9))*T9) -> 5450 | G9: =IF('LSC Sweep'!$C$4="Type-B",INDEX(Parameters!$J$11:$N$11,1,R9)+(INDEX(Parameters!$J$11:$N$11,1,R9+1)-INDEX(Parameters!$J$11:$N$11,1,R9))*U9,INDEX(Parameters!$D$11:$H$11,1,Q9)+(INDEX(Parameters!$D$11:$H$11,1,Q9+1)-INDEX(Parameters!$D$11:$H$11,1,Q9))*T9) -> 0.08 | H9: =IF('LSC Sweep'!$C$4="Type-B",INDEX(Parameters!$J$12:$N$12,1,Q9)+(INDEX(Parameters!$J$12:$N$12,1,Q9+1)-INDEX(Parameters!$J$12:$N$12,1,Q9))*T9,INDEX(Parameters!$D$12:$H$12,1,Q9)+(INDEX(Parameters!$D$12:$H$12,1,Q9+1)-INDEX(Parameters!$D$12:$H$12,1,Q9))*T9) -> 0.88 | I9: =F9*H9 -> 4796 | J9: =IF('LSC Sweep'!$C$4="Type-B",INDEX(Parameters!$J$13:$N$13,1,R9)+(INDEX(Parameters!$J$13:$N$13,1,R9+1)-INDEX(Parameters!$J$13:$N$13,1,R9))*U9,INDEX(Parameters!$D$13:$H$13,1,R9)+(INDEX(Parameters!$D$13:$H$13,1,R9+1)-INDEX(Parameters!$D$13:$H$13,1,R9))*U9) -> 1750 | K9: =IF('LSC Sweep'!$C$4="Type-B",Parameters!$L$14,INDEX(Parameters!$D$14:$H$14,1,R9)+(INDEX(Parameters!$D$14:$H$14,1,R9+1)-INDEX(Parameters!$D$14:$H$14,1,R9))*U9) -> 0.35 | L9: =I9+J9 -> 6546 | M9: =IF('LSC Sweep'!$C$4="Type-B",INDEX(Parameters!$J$17:$N$17,1,S9)+(INDEX(Parameters!$J$17:$N$17,1,S9+1)-INDEX(Parameters!$J$17:$N$17,1,S9))*V9,INDEX(Parameters!$D$17:$H$17,1,S9)+(INDEX(Parameters!$D$17:$H$17,1,S9+1)-INDEX(Parameters!$D$17:$H$17,1,S9))*V9) -> 5100 | N9: =IF('LSC Sweep'!$C$4="Type-B",INDEX(Parameters!$J$18:$N$18,1,S9)+(INDEX(Parameters!$J$18:$N$18,1,S9+1)-INDEX(Parameters!$J$18:$N$18,1,S9))*V9,INDEX(Parameters!$D$18:$H$18,1,S9)+(INDEX(Parameters!$D$18:$H$18,1,S9+1)-INDEX(Parameters!$D$18:$H$18,1,S9))*V9) -> 0.27 | O9: =IF('LSC Sweep'!$C$4="Type-B",INDEX(Parameters!$J$19:$N$19,1,S9)+(INDEX(Parameters!$J$19:$N$19,1,S9+1)-INDEX(Parameters!$J$19:$N$19,1,S9))*V9,INDEX(Parameters!$D$19:$H$19,1,S9)+(INDEX(Parameters!$D$19:$H$19,1,S9+1)-INDEX(Parameters!$D$19:$H$19,1,S9))*V9) -> 0.8 | P9: =M9*O9 -> 4080 | Q9: =MIN(4,MAX(1,INT((1+C9/Parameters!$D$23)*4)+1)) -> 4 | R9: =MIN(4,MAX(1,INT((1+D9/Parameters!$D$24)*4)+1)) -> 3 | S9: =MIN(4,MAX(1,INT((1+E9/Parameters!$D$25)*4)+1)) -> 4 | T9: =MAX(0,MIN(1,(1+C9/Parameters!$D$23)*4-(Q9-1))) -> 1 | U9: =MAX(0,MIN(1,(1+D9/Parameters!$D$24)*4-(R9-1))) -> 0 | V9: =MAX(0,MIN(1,(1+E9/Parameters!$D$25)*4-(S9-1))) -> 1
B13: 轴速 (m/s) | C13: =B5 -> c -24 | D13: =B6 -> c -18 | E13: =B7 -> c -12 | F13: =B8 -> c -6 | G13: =B9 -> c 0
B14: 0 | C14: =$F$5*MIN($B14,$G$5)+$I$5*MAX(0,$B14-$G$5)+$J$5*MAX(0,$B14-$K$5) -> 0 | D14: =$F$6*MIN($B14,$G$6)+$I$6*MAX(0,$B14-$G$6)+$J$6*MAX(0,$B14-$K$6) -> 0 | E14: =$F$7*MIN($B14,$G$7)+$I$7*MAX(0,$B14-$G$7)+$J$7*MAX(0,$B14-$K$7) -> 0 | F14: =$F$8*MIN($B14,$G$8)+$I$8*MAX(0,$B14-$G$8)+$J$8*MAX(0,$B14-$K$8) -> 0 | G14: =$F$9*MIN($B14,$G$9)+$I$9*MAX(0,$B14-$G$9)+$J$9*MAX(0,$B14-$K$9) -> 0
B15: 0.05 | C15: =$F$5*MIN($B15,$G$5)+$I$5*MAX(0,$B15-$G$5)+$J$5*MAX(0,$B15-$K$5) -> 92.5 | D15: =$F$6*MIN($B15,$G$6)+$I$6*MAX(0,$B15-$G$6)+$J$6*MAX(0,$B15-$K$6) -> 137.5 | E15: =$F$7*MIN($B15,$G$7)+$I$7*MAX(0,$B15-$G$7)+$J$7*MAX(0,$B15-$K$7) -> 182.5 | F15: =$F$8*MIN($B15,$G$8)+$I$8*MAX(0,$B15-$G$8)+$J$8*MAX(0,$B15-$K$8) -> 227.5 | G15: =$F$9*MIN($B15,$G$9)+$I$9*MAX(0,$B15-$G$9)+$J$9*MAX(0,$B15-$K$9) -> 272.5
B16: 0.1 | C16: =$F$5*MIN($B16,$G$5)+$I$5*MAX(0,$B16-$G$5)+$J$5*MAX(0,$B16-$K$5) -> 185 | D16: =$F$6*MIN($B16,$G$6)+$I$6*MAX(0,$B16-$G$6)+$J$6*MAX(0,$B16-$K$6) -> 273.35 | E16: =$F$7*MIN($B16,$G$7)+$I$7*MAX(0,$B16-$G$7)+$J$7*MAX(0,$B16-$K$7) -> 360.62 | F16: =$F$8*MIN($B16,$G$8)+$I$8*MAX(0,$B16-$G$8)+$J$8*MAX(0,$B16-$K$8) -> 446.81 | G16: =$F$9*MIN($B16,$G$9)+$I$9*MAX(0,$B16-$G$9)+$J$9*MAX(0,$B16-$K$9) -> 531.92
B17: 0.15 | C17: =$F$5*MIN($B17,$G$5)+$I$5*MAX(0,$B17-$G$5)+$J$5*MAX(0,$B17-$K$5) -> 277.5 | D17: =$F$6*MIN($B17,$G$6)+$I$6*MAX(0,$B17-$G$6)+$J$6*MAX(0,$B17-$K$6) -> 406.725 | E17: =$F$7*MIN($B17,$G$7)+$I$7*MAX(0,$B17-$G$7)+$J$7*MAX(0,$B17-$K$7) -> 532.17 | F17: =$F$8*MIN($B17,$G$8)+$I$8*MAX(0,$B17-$G$8)+$J$8*MAX(0,$B17-$K$8) -> 653.835 | G17: =$F$9*MIN($B17,$G$9)+$I$9*MAX(0,$B17-$G$9)+$J$9*MAX(0,$B17-$K$9) -> 771.72
B18: 0.2 | C18: =$F$5*MIN($B18,$G$5)+$I$5*MAX(0,$B18-$G$5)+$J$5*MAX(0,$B18-$K$5) -> 370 | D18: =$F$6*MIN($B18,$G$6)+$I$6*MAX(0,$B18-$G$6)+$J$6*MAX(0,$B18-$K$6) -> 540.1 | E18: =$F$7*MIN($B18,$G$7)+$I$7*MAX(0,$B18-$G$7)+$J$7*MAX(0,$B18-$K$7) -> 703.72 | F18: =$F$8*MIN($B18,$G$8)+$I$8*MAX(0,$B18-$G$8)+$J$8*MAX(0,$B18-$K$8) -> 860.86 | G18: =$F$9*MIN($B18,$G$9)+$I$9*MAX(0,$B18-$G$9)+$J$9*MAX(0,$B18-$K$9) -> 1011.52
B19: 0.25 | C19: =$F$5*MIN($B19,$G$5)+$I$5*MAX(0,$B19-$G$5)+$J$5*MAX(0,$B19-$K$5) -> 462.5 | D19: =$F$6*MIN($B19,$G$6)+$I$6*MAX(0,$B19-$G$6)+$J$6*MAX(0,$B19-$K$6) -> 673.475 | E19: =$F$7*MIN($B19,$G$7)+$I$7*MAX(0,$B19-$G$7)+$J$7*MAX(0,$B19-$K$7) -> 875.27 | F19: =$F$8*MIN($B19,$G$8)+$I$8*MAX(0,$B19-$G$8)+$J$8*MAX(0,$B19-$K$8) -> 1067.885 | G19: =$F$9*MIN($B19,$G$9)+$I$9*MAX(0,$B19-$G$9)+$J$9*MAX(0,$B19-$K$9) -> 1251.32
B20: 0.3 | C20: =$F$5*MIN($B20,$G$5)+$I$5*MAX(0,$B20-$G$5)+$J$5*MAX(0,$B20-$K$5) -> 555 | D20: =$F$6*MIN($B20,$G$6)+$I$6*MAX(0,$B20-$G$6)+$J$6*MAX(0,$B20-$K$6) -> 806.85 | E20: =$F$7*MIN($B20,$G$7)+$I$7*MAX(0,$B20-$G$7)+$J$7*MAX(0,$B20-$K$7) -> 1046.82 | F20: =$F$8*MIN($B20,$G$8)+$I$8*MAX(0,$B20-$G$8)+$J$8*MAX(0,$B20-$K$8) -> 1274.91 | G20: =$F$9*MIN($B20,$G$9)+$I$9*MAX(0,$B20-$G$9)+$J$9*MAX(0,$B20-$K$9) -> 1491.12
B21: 0.35 | C21: =$F$5*MIN($B21,$G$5)+$I$5*MAX(0,$B21-$G$5)+$J$5*MAX(0,$B21-$K$5) -> 647.5 | D21: =$F$6*MIN($B21,$G$6)+$I$6*MAX(0,$B21-$G$6)+$J$6*MAX(0,$B21-$K$6) -> 940.225 | E21: =$F$7*MIN($B21,$G$7)+$I$7*MAX(0,$B21-$G$7)+$J$7*MAX(0,$B21-$K$7) -> 1218.37 | F21: =$F$8*MIN($B21,$G$8)+$I$8*MAX(0,$B21-$G$8)+$J$8*MAX(0,$B21-$K$8) -> 1481.935 | G21: =$F$9*MIN($B21,$G$9)+$I$9*MAX(0,$B21-$G$9)+$J$9*MAX(0,$B21-$K$9) -> 1730.92
B22: 0.4 | C22: =$F$5*MIN($B22,$G$5)+$I$5*MAX(0,$B22-$G$5)+$J$5*MAX(0,$B22-$K$5) -> 827.5 | D22: =$F$6*MIN($B22,$G$6)+$I$6*MAX(0,$B22-$G$6)+$J$6*MAX(0,$B22-$K$6) -> 1161.1 | E22: =$F$7*MIN($B22,$G$7)+$I$7*MAX(0,$B22-$G$7)+$J$7*MAX(0,$B22-$K$7) -> 1477.42 | F22: =$F$8*MIN($B22,$G$8)+$I$8*MAX(0,$B22-$G$8)+$J$8*MAX(0,$B22-$K$8) -> 1776.46 | G22: =$F$9*MIN($B22,$G$9)+$I$9*MAX(0,$B22-$G$9)+$J$9*MAX(0,$B22-$K$9) -> 2058.22
B23: 0.45 | C23: =$F$5*MIN($B23,$G$5)+$I$5*MAX(0,$B23-$G$5)+$J$5*MAX(0,$B23-$K$5) -> 1007.5 | D23: =$F$6*MIN($B23,$G$6)+$I$6*MAX(0,$B23-$G$6)+$J$6*MAX(0,$B23-$K$6) -> 1381.975 | E23: =$F$7*MIN($B23,$G$7)+$I$7*MAX(0,$B23-$G$7)+$J$7*MAX(0,$B23-$K$7) -> 1736.47 | F23: =$F$8*MIN($B23,$G$8)+$I$8*MAX(0,$B23-$G$8)+$J$8*MAX(0,$B23-$K$8) -> 2070.985 | G23: =$F$9*MIN($B23,$G$9)+$I$9*MAX(0,$B23-$G$9)+$J$9*MAX(0,$B23-$K$9) -> 2385.52
B24: 0.5 | C24: =$F$5*MIN($B24,$G$5)+$I$5*MAX(0,$B24-$G$5)+$J$5*MAX(0,$B24-$K$5) -> 1187.5 | D24: =$F$6*MIN($B24,$G$6)+$I$6*MAX(0,$B24-$G$6)+$J$6*MAX(0,$B24-$K$6) -> 1602.85 | E24: =$F$7*MIN($B24,$G$7)+$I$7*MAX(0,$B24-$G$7)+$J$7*MAX(0,$B24-$K$7) -> 1995.52 | F24: =$F$8*MIN($B24,$G$8)+$I$8*MAX(0,$B24-$G$8)+$J$8*MAX(0,$B24-$K$8) -> 2365.51 | G24: =$F$9*MIN($B24,$G$9)+$I$9*MAX(0,$B24-$G$9)+$J$9*MAX(0,$B24-$K$9) -> 2712.82
B25: 0.55 | C25: =$F$5*MIN($B25,$G$5)+$I$5*MAX(0,$B25-$G$5)+$J$5*MAX(0,$B25-$K$5) -> 1367.5 | D25: =$F$6*MIN($B25,$G$6)+$I$6*MAX(0,$B25-$G$6)+$J$6*MAX(0,$B25-$K$6) -> 1823.725 | E25: =$F$7*MIN($B25,$G$7)+$I$7*MAX(0,$B25-$G$7)+$J$7*MAX(0,$B25-$K$7) -> 2254.57 | F25: =$F$8*MIN($B25,$G$8)+$I$8*MAX(0,$B25-$G$8)+$J$8*MAX(0,$B25-$K$8) -> 2660.035 | G25: =$F$9*MIN($B25,$G$9)+$I$9*MAX(0,$B25-$G$9)+$J$9*MAX(0,$B25-$K$9) -> 3040.12
... B34: 1 | C34: =$F$5*MIN($B34,$G$5)+$I$5*MAX(0,$B34-$G$5)+$J$5*MAX(0,$B34-$K$5) -> 2987.5 | D34: =$F$6*MIN($B34,$G$6)+$I$6*MAX(0,$B34-$G$6)+$J$6*MAX(0,$B34-$K$6) -> 3811.6 | E34: =$F$7*MIN($B34,$G$7)+$I$7*MAX(0,$B34-$G$7)+$J$7*MAX(0,$B34-$K$7) -> 4586.02 | F34: =$F$8*MIN($B34,$G$8)+$I$8*MAX(0,$B34-$G$8)+$J$8*MAX(0,$B34-$K$8) -> 5310.76 | G34: =$F$9*MIN($B34,$G$9)+$I$9*MAX(0,$B34-$G$9)+$J$9*MAX(0,$B34-$K$9) -> 5985.82
B41: CTM Racing · MRAx0 · HSC Sweep · 读取对应 Sweep 页的阀系选择
B44: 曲线 | C44: c | D44: C | E44: R | F44: bump1 | G44: 第一 knee | H44: bump2 倍率 | I44: bump2 | J44: HSbump | K44: 第二 knee | L44: 总 HS 系数 | M44: rebound | N44: Rebound knee | O44: HSR 倍率 | P44: HSrebound | Q44: LSC 区间 | R44: HSC 区间 | S44: LSR 区间 | T44: LSC 区间位置 | U44: HSC 区间位置 | V44: LSR 区间位置
B45: ="C "&D45 -> C -20 | C45: ='HSC Sweep'!$C$6 -> -12 | D45: =Parameters!D8 -> -20 | E45: =Parameters!D16 -> -40 | F45: =IF('HSC Sweep'!$C$4="Type-B",INDEX(Parameters!$J$10:$N$10,1,Q45)+(INDEX(Parameters!$J$10:$N$10,1,Q45+1)-INDEX(Parameters!$J$10:$N$10,1,Q45))*T45,INDEX(Parameters!$D$10:$H$10,1,Q45)+(INDEX(Parameters!$D$10:$H$10,1,Q45+1)-INDEX(Parameters!$D$10:$H$10,1,Q45))*T45) -> 4200 | G45: =IF('HSC Sweep'!$C$4="Type-B",INDEX(Parameters!$J$11:$N$11,1,R45)+(INDEX(Parameters!$J$11:$N$11,1,R45+1)-INDEX(Parameters!$J$11:$N$11,1,R45))*U45,INDEX(Parameters!$D$11:$H$11,1,Q45)+(INDEX(Parameters!$D$11:$H$11,1,Q45+1)-INDEX(Parameters!$D$11:$H$11,1,Q45))*T45) -> 0.2 | H45: =IF('HSC Sweep'!$C$4="Type-B",INDEX(Parameters!$J$12:$N$12,1,Q45)+(INDEX(Parameters!$J$12:$N$12,1,Q45+1)-INDEX(Parameters!$J$12:$N$12,1,Q45))*T45,INDEX(Parameters!$D$12:$H$12,1,Q45)+(INDEX(Parameters!$D$12:$H$12,1,Q45+1)-INDEX(Parameters!$D$12:$H$12,1,Q45))*T45) -> 0.69 | I45: =F45*H45 -> 2898 | J45: =IF('HSC Sweep'!$C$4="Type-B",INDEX(Parameters!$J$13:$N$13,1,R45)+(INDEX(Parameters!$J$13:$N$13,1,R45+1)-INDEX(Parameters!$J$13:$N$13,1,R45))*U45,INDEX(Parameters!$D$13:$H$13,1,R45)+(INDEX(Parameters!$D$13:$H$13,1,R45+1)-INDEX(Parameters!$D$13:$H$13,1,R45))*U45) -> 0 | K45: =IF('HSC Sweep'!$C$4="Type-B",Parameters!$L$14,INDEX(Parameters!$D$14:$H$14,1,R45)+(INDEX(Parameters!$D$14:$H$14,1,R45+1)-INDEX(Parameters!$D$14:$H$14,1,R45))*U45) -> 0.6 | L45: =I45+J45 -> 2898 | M45: =IF('HSC Sweep'!$C$4="Type-B",INDEX(Parameters!$J$17:$N$17,1,S45)+(INDEX(Parameters!$J$17:$N$17,1,S45+1)-INDEX(Parameters!$J$17:$N$17,1,S45))*V45,INDEX(Parameters!$D$17:$H$17,1,S45)+(INDEX(Parameters!$D$17:$H$17,1,S45+1)-INDEX(Parameters!$D$17:$H$17,1,S45))*V45) -> 3000 | N45: =IF('HSC Sweep'!$C$4="Type-B",INDEX(Parameters!$J$18:$N$18,1,S45)+(INDEX(Parameters!$J$18:$N$18,1,S45+1)-INDEX(Parameters!$J$18:$N$18,1,S45))*V45,INDEX(Parameters!$D$18:$H$18,1,S45)+(INDEX(Parameters!$D$18:$H$18,1,S45+1)-INDEX(Parameters!$D$18:$H$18,1,S45))*V45) -> 0.21 | O45: =IF('HSC Sweep'!$C$4="Type-B",INDEX(Parameters!$J$19:$N$19,1,S45)+(INDEX(Parameters!$J$19:$N$19,1,S45+1)-INDEX(Parameters!$J$19:$N$19,1,S45))*V45,INDEX(Parameters!$D$19:$H$19,1,S45)+(INDEX(Parameters!$D$19:$H$19,1,S45+1)-INDEX(Parameters!$D$19:$H$19,1,S45))*V45) -> 0.68 | P45: =M45*O45 -> 2040 | Q45: =MIN(4,MAX(1,INT((1+C45/Parameters!$D$23)*4)+1)) -> 3 | R45: =MIN(4,MAX(1,INT((1+D45/Parameters!$D$24)*4)+1)) -> 1 | S45: =MIN(4,MAX(1,INT((1+E45/Parameters!$D$25)*4)+1)) -> 1 | T45: =MAX(0,MIN(1,(1+C45/Parameters!$D$23)*4-(Q45-1))) -> 0 | U45: =MAX(0,MIN(1,(1+D45/Parameters!$D$24)*4-(R45-1))) -> 0 | V45: =MAX(0,MIN(1,(1+E45/Parameters!$D$25)*4-(S45-1))) -> 0
B46: ="C "&D46 -> C -15 | C46: ='HSC Sweep'!$C$6 -> -12 | D46: =Parameters!E8 -> -15 | E46: =Parameters!E16 -> -30 | F46: =IF('HSC Sweep'!$C$4="Type-B",INDEX(Parameters!$J$10:$N$10,1,Q46)+(INDEX(Parameters!$J$10:$N$10,1,Q46+1)-INDEX(Parameters!$J$10:$N$10,1,Q46))*T46,INDEX(Parameters!$D$10:$H$10,1,Q46)+(INDEX(Parameters!$D$10:$H$10,1,Q46+1)-INDEX(Parameters!$D$10:$H$10,1,Q46))*T46) -> 4200 | G46: =IF('HSC Sweep'!$C$4="Type-B",INDEX(Parameters!$J$11:$N$11,1,R46)+(INDEX(Parameters!$J$11:$N$11,1,R46+1)-INDEX(Parameters!$J$11:$N$11,1,R46))*U46,INDEX(Parameters!$D$11:$H$11,1,Q46)+(INDEX(Parameters!$D$11:$H$11,1,Q46+1)-INDEX(Parameters!$D$11:$H$11,1,Q46))*T46) -> 0.25 | H46: =IF('HSC Sweep'!$C$4="Type-B",INDEX(Parameters!$J$12:$N$12,1,Q46)+(INDEX(Parameters!$J$12:$N$12,1,Q46+1)-INDEX(Parameters!$J$12:$N$12,1,Q46))*T46,INDEX(Parameters!$D$12:$H$12,1,Q46)+(INDEX(Parameters!$D$12:$H$12,1,Q46+1)-INDEX(Parameters!$D$12:$H$12,1,Q46))*T46) -> 0.69 | I46: =F46*H46 -> 2898 | J46: =IF('HSC Sweep'!$C$4="Type-B",INDEX(Parameters!$J$13:$N$13,1,R46)+(INDEX(Parameters!$J$13:$N$13,1,R46+1)-INDEX(Parameters!$J$13:$N$13,1,R46))*U46,INDEX(Parameters!$D$13:$H$13,1,R46)+(INDEX(Parameters!$D$13:$H$13,1,R46+1)-INDEX(Parameters!$D$13:$H$13,1,R46))*U46) -> 0 | K46: =IF('HSC Sweep'!$C$4="Type-B",Parameters!$L$14,INDEX(Parameters!$D$14:$H$14,1,R46)+(INDEX(Parameters!$D$14:$H$14,1,R46+1)-INDEX(Parameters!$D$14:$H$14,1,R46))*U46) -> 0.6 | L46: =I46+J46 -> 2898 | M46: =IF('HSC Sweep'!$C$4="Type-B",INDEX(Parameters!$J$17:$N$17,1,S46)+(INDEX(Parameters!$J$17:$N$17,1,S46+1)-INDEX(Parameters!$J$17:$N$17,1,S46))*V46,INDEX(Parameters!$D$17:$H$17,1,S46)+(INDEX(Parameters!$D$17:$H$17,1,S46+1)-INDEX(Parameters!$D$17:$H$17,1,S46))*V46) -> 3750 | N46: =IF('HSC Sweep'!$C$4="Type-B",INDEX(Parameters!$J$18:$N$18,1,S46)+(INDEX(Parameters!$J$18:$N$18,1,S46+1)-INDEX(Parameters!$J$18:$N$18,1,S46))*V46,INDEX(Parameters!$D$18:$H$18,1,S46)+(INDEX(Parameters!$D$18:$H$18,1,S46+1)-INDEX(Parameters!$D$18:$H$18,1,S46))*V46) -> 0.215 | O46: =IF('HSC Sweep'!$C$4="Type-B",INDEX(Parameters!$J$19:$N$19,1,S46)+(INDEX(Parameters!$J$19:$N$19,1,S46+1)-INDEX(Parameters!$J$19:$N$19,1,S46))*V46,INDEX(Parameters!$D$19:$H$19,1,S46)+(INDEX(Parameters!$D$19:$H$19,1,S46+1)-INDEX(Parameters!$D$19:$H$19,1,S46))*V46) -> 0.65 | P46: =M46*O46 -> 2437.5 | Q46: =MIN(4,MAX(1,INT((1+C46/Parameters!$D$23)*4)+1)) -> 3 | R46: =MIN(4,MAX(1,INT((1+D46/Parameters!$D$24)*4)+1)) -> 2 | S46: =MIN(4,MAX(1,INT((1+E46/Parameters!$D$25)*4)+1)) -> 2 | T46: =MAX(0,MIN(1,(1+C46/Parameters!$D$23)*4-(Q46-1))) -> 0 | U46: =MAX(0,MIN(1,(1+D46/Parameters!$D$24)*4-(R46-1))) -> 0 | V46: =MAX(0,MIN(1,(1+E46/Parameters!$D$25)*4-(S46-1))) -> 0
B47: ="C "&D47 -> C -10 | C47: ='HSC Sweep'!$C$6 -> -12 | D47: =Parameters!F8 -> -10 | E47: =Parameters!F16 -> -20 | F47: =IF('HSC Sweep'!$C$4="Type-B",INDEX(Parameters!$J$10:$N$10,1,Q47)+(INDEX(Parameters!$J$10:$N$10,1,Q47+1)-INDEX(Parameters!$J$10:$N$10,1,Q47))*T47,INDEX(Parameters!$D$10:$H$10,1,Q47)+(INDEX(Parameters!$D$10:$H$10,1,Q47+1)-INDEX(Parameters!$D$10:$H$10,1,Q47))*T47) -> 4200 | G47: =IF('HSC Sweep'!$C$4="Type-B",INDEX(Parameters!$J$11:$N$11,1,R47)+(INDEX(Parameters!$J$11:$N$11,1,R47+1)-INDEX(Parameters!$J$11:$N$11,1,R47))*U47,INDEX(Parameters!$D$11:$H$11,1,Q47)+(INDEX(Parameters!$D$11:$H$11,1,Q47+1)-INDEX(Parameters!$D$11:$H$11,1,Q47))*T47) -> 0.3 | H47: =IF('HSC Sweep'!$C$4="Type-B",INDEX(Parameters!$J$12:$N$12,1,Q47)+(INDEX(Parameters!$J$12:$N$12,1,Q47+1)-INDEX(Parameters!$J$12:$N$12,1,Q47))*T47,INDEX(Parameters!$D$12:$H$12,1,Q47)+(INDEX(Parameters!$D$12:$H$12,1,Q47+1)-INDEX(Parameters!$D$12:$H$12,1,Q47))*T47) -> 0.69 | I47: =F47*H47 -> 2898 | J47: =IF('HSC Sweep'!$C$4="Type-B",INDEX(Parameters!$J$13:$N$13,1,R47)+(INDEX(Parameters!$J$13:$N$13,1,R47+1)-INDEX(Parameters!$J$13:$N$13,1,R47))*U47,INDEX(Parameters!$D$13:$H$13,1,R47)+(INDEX(Parameters!$D$13:$H$13,1,R47+1)-INDEX(Parameters!$D$13:$H$13,1,R47))*U47) -> 0 | K47: =IF('HSC Sweep'!$C$4="Type-B",Parameters!$L$14,INDEX(Parameters!$D$14:$H$14,1,R47)+(INDEX(Parameters!$D$14:$H$14,1,R47+1)-INDEX(Parameters!$D$14:$H$14,1,R47))*U47) -> 0.6 | L47: =I47+J47 -> 2898 | M47: =IF('HSC Sweep'!$C$4="Type-B",INDEX(Parameters!$J$17:$N$17,1,S47)+(INDEX(Parameters!$J$17:$N$17,1,S47+1)-INDEX(Parameters!$J$17:$N$17,1,S47))*V47,INDEX(Parameters!$D$17:$H$17,1,S47)+(INDEX(Parameters!$D$17:$H$17,1,S47+1)-INDEX(Parameters!$D$17:$H$17,1,S47))*V47) -> 4500 | N47: =IF('HSC Sweep'!$C$4="Type-B",INDEX(Parameters!$J$18:$N$18,1,S47)+(INDEX(Parameters!$J$18:$N$18,1,S47+1)-INDEX(Parameters!$J$18:$N$18,1,S47))*V47,INDEX(Parameters!$D$18:$H$18,1,S47)+(INDEX(Parameters!$D$18:$H$18,1,S47+1)-INDEX(Parameters!$D$18:$H$18,1,S47))*V47) -> 0.22 | O47: =IF('HSC Sweep'!$C$4="Type-B",INDEX(Parameters!$J$19:$N$19,1,S47)+(INDEX(Parameters!$J$19:$N$19,1,S47+1)-INDEX(Parameters!$J$19:$N$19,1,S47))*V47,INDEX(Parameters!$D$19:$H$19,1,S47)+(INDEX(Parameters!$D$19:$H$19,1,S47+1)-INDEX(Parameters!$D$19:$H$19,1,S47))*V47) -> 0.62 | P47: =M47*O47 -> 2790 | Q47: =MIN(4,MAX(1,INT((1+C47/Parameters!$D$23)*4)+1)) -> 3 | R47: =MIN(4,MAX(1,INT((1+D47/Parameters!$D$24)*4)+1)) -> 3 | S47: =MIN(4,MAX(1,INT((1+E47/Parameters!$D$25)*4)+1)) -> 3 | T47: =MAX(0,MIN(1,(1+C47/Parameters!$D$23)*4-(Q47-1))) -> 0 | U47: =MAX(0,MIN(1,(1+D47/Parameters!$D$24)*4-(R47-1))) -> 0 | V47: =MAX(0,MIN(1,(1+E47/Parameters!$D$25)*4-(S47-1))) -> 0
B48: ="C "&D48 -> C -5 | C48: ='HSC Sweep'!$C$6 -> -12 | D48: =Parameters!G8 -> -5 | E48: =Parameters!G16 -> -10 | F48: =IF('HSC Sweep'!$C$4="Type-B",INDEX(Parameters!$J$10:$N$10,1,Q48)+(INDEX(Parameters!$J$10:$N$10,1,Q48+1)-INDEX(Parameters!$J$10:$N$10,1,Q48))*T48,INDEX(Parameters!$D$10:$H$10,1,Q48)+(INDEX(Parameters!$D$10:$H$10,1,Q48+1)-INDEX(Parameters!$D$10:$H$10,1,Q48))*T48) -> 4200 | G48: =IF('HSC Sweep'!$C$4="Type-B",INDEX(Parameters!$J$11:$N$11,1,R48)+(INDEX(Parameters!$J$11:$N$11,1,R48+1)-INDEX(Parameters!$J$11:$N$11,1,R48))*U48,INDEX(Parameters!$D$11:$H$11,1,Q48)+(INDEX(Parameters!$D$11:$H$11,1,Q48+1)-INDEX(Parameters!$D$11:$H$11,1,Q48))*T48) -> 0.35 | H48: =IF('HSC Sweep'!$C$4="Type-B",INDEX(Parameters!$J$12:$N$12,1,Q48)+(INDEX(Parameters!$J$12:$N$12,1,Q48+1)-INDEX(Parameters!$J$12:$N$12,1,Q48))*T48,INDEX(Parameters!$D$12:$H$12,1,Q48)+(INDEX(Parameters!$D$12:$H$12,1,Q48+1)-INDEX(Parameters!$D$12:$H$12,1,Q48))*T48) -> 0.69 | I48: =F48*H48 -> 2898 | J48: =IF('HSC Sweep'!$C$4="Type-B",INDEX(Parameters!$J$13:$N$13,1,R48)+(INDEX(Parameters!$J$13:$N$13,1,R48+1)-INDEX(Parameters!$J$13:$N$13,1,R48))*U48,INDEX(Parameters!$D$13:$H$13,1,R48)+(INDEX(Parameters!$D$13:$H$13,1,R48+1)-INDEX(Parameters!$D$13:$H$13,1,R48))*U48) -> 0 | K48: =IF('HSC Sweep'!$C$4="Type-B",Parameters!$L$14,INDEX(Parameters!$D$14:$H$14,1,R48)+(INDEX(Parameters!$D$14:$H$14,1,R48+1)-INDEX(Parameters!$D$14:$H$14,1,R48))*U48) -> 0.6 | L48: =I48+J48 -> 2898 | M48: =IF('HSC Sweep'!$C$4="Type-B",INDEX(Parameters!$J$17:$N$17,1,S48)+(INDEX(Parameters!$J$17:$N$17,1,S48+1)-INDEX(Parameters!$J$17:$N$17,1,S48))*V48,INDEX(Parameters!$D$17:$H$17,1,S48)+(INDEX(Parameters!$D$17:$H$17,1,S48+1)-INDEX(Parameters!$D$17:$H$17,1,S48))*V48) -> 5250 | N48: =IF('HSC Sweep'!$C$4="Type-B",INDEX(Parameters!$J$18:$N$18,1,S48)+(INDEX(Parameters!$J$18:$N$18,1,S48+1)-INDEX(Parameters!$J$18:$N$18,1,S48))*V48,INDEX(Parameters!$D$18:$H$18,1,S48)+(INDEX(Parameters!$D$18:$H$18,1,S48+1)-INDEX(Parameters!$D$18:$H$18,1,S48))*V48) -> 0.225 | O48: =IF('HSC Sweep'!$C$4="Type-B",INDEX(Parameters!$J$19:$N$19,1,S48)+(INDEX(Parameters!$J$19:$N$19,1,S48+1)-INDEX(Parameters!$J$19:$N$19,1,S48))*V48,INDEX(Parameters!$D$19:$H$19,1,S48)+(INDEX(Parameters!$D$19:$H$19,1,S48+1)-INDEX(Parameters!$D$19:$H$19,1,S48))*V48) -> 0.59 | P48: =M48*O48 -> 3097.5 | Q48: =MIN(4,MAX(1,INT((1+C48/Parameters!$D$23)*4)+1)) -> 3 | R48: =MIN(4,MAX(1,INT((1+D48/Parameters!$D$24)*4)+1)) -> 4 | S48: =MIN(4,MAX(1,INT((1+E48/Parameters!$D$25)*4)+1)) -> 4 | T48: =MAX(0,MIN(1,(1+C48/Parameters!$D$23)*4-(Q48-1))) -> 0 | U48: =MAX(0,MIN(1,(1+D48/Parameters!$D$24)*4-(R48-1))) -> 0 | V48: =MAX(0,MIN(1,(1+E48/Parameters!$D$25)*4-(S48-1))) -> 0
B49: ="C "&D49 -> C 0 | C49: ='HSC Sweep'!$C$6 -> -12 | D49: =Parameters!H8 -> 0 | E49: =Parameters!H16 -> 0 | F49: =IF('HSC Sweep'!$C$4="Type-B",INDEX(Parameters!$J$10:$N$10,1,Q49)+(INDEX(Parameters!$J$10:$N$10,1,Q49+1)-INDEX(Parameters!$J$10:$N$10,1,Q49))*T49,INDEX(Parameters!$D$10:$H$10,1,Q49)+(INDEX(Parameters!$D$10:$H$10,1,Q49+1)-INDEX(Parameters!$D$10:$H$10,1,Q49))*T49) -> 4200 | G49: =IF('HSC Sweep'!$C$4="Type-B",INDEX(Parameters!$J$11:$N$11,1,R49)+(INDEX(Parameters!$J$11:$N$11,1,R49+1)-INDEX(Parameters!$J$11:$N$11,1,R49))*U49,INDEX(Parameters!$D$11:$H$11,1,Q49)+(INDEX(Parameters!$D$11:$H$11,1,Q49+1)-INDEX(Parameters!$D$11:$H$11,1,Q49))*T49) -> 0.4 | H49: =IF('HSC Sweep'!$C$4="Type-B",INDEX(Parameters!$J$12:$N$12,1,Q49)+(INDEX(Parameters!$J$12:$N$12,1,Q49+1)-INDEX(Parameters!$J$12:$N$12,1,Q49))*T49,INDEX(Parameters!$D$12:$H$12,1,Q49)+(INDEX(Parameters!$D$12:$H$12,1,Q49+1)-INDEX(Parameters!$D$12:$H$12,1,Q49))*T49) -> 0.69 | I49: =F49*H49 -> 2898 | J49: =IF('HSC Sweep'!$C$4="Type-B",INDEX(Parameters!$J$13:$N$13,1,R49)+(INDEX(Parameters!$J$13:$N$13,1,R49+1)-INDEX(Parameters!$J$13:$N$13,1,R49))*U49,INDEX(Parameters!$D$13:$H$13,1,R49)+(INDEX(Parameters!$D$13:$H$13,1,R49+1)-INDEX(Parameters!$D$13:$H$13,1,R49))*U49) -> 0 | K49: =IF('HSC Sweep'!$C$4="Type-B",Parameters!$L$14,INDEX(Parameters!$D$14:$H$14,1,R49)+(INDEX(Parameters!$D$14:$H$14,1,R49+1)-INDEX(Parameters!$D$14:$H$14,1,R49))*U49) -> 0.6 | L49: =I49+J49 -> 2898 | M49: =IF('HSC Sweep'!$C$4="Type-B",INDEX(Parameters!$J$17:$N$17,1,S49)+(INDEX(Parameters!$J$17:$N$17,1,S49+1)-INDEX(Parameters!$J$17:$N$17,1,S49))*V49,INDEX(Parameters!$D$17:$H$17,1,S49)+(INDEX(Parameters!$D$17:$H$17,1,S49+1)-INDEX(Parameters!$D$17:$H$17,1,S49))*V49) -> 6000 | N49: =IF('HSC Sweep'!$C$4="Type-B",INDEX(Parameters!$J$18:$N$18,1,S49)+(INDEX(Parameters!$J$18:$N$18,1,S49+1)-INDEX(Parameters!$J$18:$N$18,1,S49))*V49,INDEX(Parameters!$D$18:$H$18,1,S49)+(INDEX(Parameters!$D$18:$H$18,1,S49+1)-INDEX(Parameters!$D$18:$H$18,1,S49))*V49) -> 0.23 | O49: =IF('HSC Sweep'!$C$4="Type-B",INDEX(Parameters!$J$19:$N$19,1,S49)+(INDEX(Parameters!$J$19:$N$19,1,S49+1)-INDEX(Parameters!$J$19:$N$19,1,S49))*V49,INDEX(Parameters!$D$19:$H$19,1,S49)+(INDEX(Parameters!$D$19:$H$19,1,S49+1)-INDEX(Parameters!$D$19:$H$19,1,S49))*V49) -> 0.56 | P49: =M49*O49 -> 3360 | Q49: =MIN(4,MAX(1,INT((1+C49/Parameters!$D$23)*4)+1)) -> 3 | R49: =MIN(4,MAX(1,INT((1+D49/Parameters!$D$24)*4)+1)) -> 4 | S49: =MIN(4,MAX(1,INT((1+E49/Parameters!$D$25)*4)+1)) -> 4 | T49: =MAX(0,MIN(1,(1+C49/Parameters!$D$23)*4-(Q49-1))) -> 0 | U49: =MAX(0,MIN(1,(1+D49/Parameters!$D$24)*4-(R49-1))) -> 1 | V49: =MAX(0,MIN(1,(1+E49/Parameters!$D$25)*4-(S49-1))) -> 1
B53: 轴速 (m/s) | C53: =B45 -> C -20 | D53: =B46 -> C -15 | E53: =B47 -> C -10 | F53: =B48 -> C -5 | G53: =B49 -> C 0
B54: 0 | C54: =$F$45*MIN($B54,$G$45)+$I$45*MAX(0,$B54-$G$45)+$J$45*MAX(0,$B54-$K$45) -> 0 | D54: =$F$46*MIN($B54,$G$46)+$I$46*MAX(0,$B54-$G$46)+$J$46*MAX(0,$B54-$K$46) -> 0 | E54: =$F$47*MIN($B54,$G$47)+$I$47*MAX(0,$B54-$G$47)+$J$47*MAX(0,$B54-$K$47) -> 0 | F54: =$F$48*MIN($B54,$G$48)+$I$48*MAX(0,$B54-$G$48)+$J$48*MAX(0,$B54-$K$48) -> 0 | G54: =$F$49*MIN($B54,$G$49)+$I$49*MAX(0,$B54-$G$49)+$J$49*MAX(0,$B54-$K$49) -> 0
B55: 0.05 | C55: =$F$45*MIN($B55,$G$45)+$I$45*MAX(0,$B55-$G$45)+$J$45*MAX(0,$B55-$K$45) -> 210 | D55: =$F$46*MIN($B55,$G$46)+$I$46*MAX(0,$B55-$G$46)+$J$46*MAX(0,$B55-$K$46) -> 210 | E55: =$F$47*MIN($B55,$G$47)+$I$47*MAX(0,$B55-$G$47)+$J$47*MAX(0,$B55-$K$47) -> 210 | F55: =$F$48*MIN($B55,$G$48)+$I$48*MAX(0,$B55-$G$48)+$J$48*MAX(0,$B55-$K$48) -> 210 | G55: =$F$49*MIN($B55,$G$49)+$I$49*MAX(0,$B55-$G$49)+$J$49*MAX(0,$B55-$K$49) -> 210
B56: 0.1 | C56: =$F$45*MIN($B56,$G$45)+$I$45*MAX(0,$B56-$G$45)+$J$45*MAX(0,$B56-$K$45) -> 420 | D56: =$F$46*MIN($B56,$G$46)+$I$46*MAX(0,$B56-$G$46)+$J$46*MAX(0,$B56-$K$46) -> 420 | E56: =$F$47*MIN($B56,$G$47)+$I$47*MAX(0,$B56-$G$47)+$J$47*MAX(0,$B56-$K$47) -> 420 | F56: =$F$48*MIN($B56,$G$48)+$I$48*MAX(0,$B56-$G$48)+$J$48*MAX(0,$B56-$K$48) -> 420 | G56: =$F$49*MIN($B56,$G$49)+$I$49*MAX(0,$B56-$G$49)+$J$49*MAX(0,$B56-$K$49) -> 420
B57: 0.15 | C57: =$F$45*MIN($B57,$G$45)+$I$45*MAX(0,$B57-$G$45)+$J$45*MAX(0,$B57-$K$45) -> 630 | D57: =$F$46*MIN($B57,$G$46)+$I$46*MAX(0,$B57-$G$46)+$J$46*MAX(0,$B57-$K$46) -> 630 | E57: =$F$47*MIN($B57,$G$47)+$I$47*MAX(0,$B57-$G$47)+$J$47*MAX(0,$B57-$K$47) -> 630 | F57: =$F$48*MIN($B57,$G$48)+$I$48*MAX(0,$B57-$G$48)+$J$48*MAX(0,$B57-$K$48) -> 630 | G57: =$F$49*MIN($B57,$G$49)+$I$49*MAX(0,$B57-$G$49)+$J$49*MAX(0,$B57-$K$49) -> 630
B58: 0.2 | C58: =$F$45*MIN($B58,$G$45)+$I$45*MAX(0,$B58-$G$45)+$J$45*MAX(0,$B58-$K$45) -> 840 | D58: =$F$46*MIN($B58,$G$46)+$I$46*MAX(0,$B58-$G$46)+$J$46*MAX(0,$B58-$K$46) -> 840 | E58: =$F$47*MIN($B58,$G$47)+$I$47*MAX(0,$B58-$G$47)+$J$47*MAX(0,$B58-$K$47) -> 840 | F58: =$F$48*MIN($B58,$G$48)+$I$48*MAX(0,$B58-$G$48)+$J$48*MAX(0,$B58-$K$48) -> 840 | G58: =$F$49*MIN($B58,$G$49)+$I$49*MAX(0,$B58-$G$49)+$J$49*MAX(0,$B58-$K$49) -> 840
B59: 0.25 | C59: =$F$45*MIN($B59,$G$45)+$I$45*MAX(0,$B59-$G$45)+$J$45*MAX(0,$B59-$K$45) -> 984.9 | D59: =$F$46*MIN($B59,$G$46)+$I$46*MAX(0,$B59-$G$46)+$J$46*MAX(0,$B59-$K$46) -> 1050 | E59: =$F$47*MIN($B59,$G$47)+$I$47*MAX(0,$B59-$G$47)+$J$47*MAX(0,$B59-$K$47) -> 1050 | F59: =$F$48*MIN($B59,$G$48)+$I$48*MAX(0,$B59-$G$48)+$J$48*MAX(0,$B59-$K$48) -> 1050 | G59: =$F$49*MIN($B59,$G$49)+$I$49*MAX(0,$B59-$G$49)+$J$49*MAX(0,$B59-$K$49) -> 1050
B60: 0.3 | C60: =$F$45*MIN($B60,$G$45)+$I$45*MAX(0,$B60-$G$45)+$J$45*MAX(0,$B60-$K$45) -> 1129.8 | D60: =$F$46*MIN($B60,$G$46)+$I$46*MAX(0,$B60-$G$46)+$J$46*MAX(0,$B60-$K$46) -> 1194.9 | E60: =$F$47*MIN($B60,$G$47)+$I$47*MAX(0,$B60-$G$47)+$J$47*MAX(0,$B60-$K$47) -> 1260 | F60: =$F$48*MIN($B60,$G$48)+$I$48*MAX(0,$B60-$G$48)+$J$48*MAX(0,$B60-$K$48) -> 1260 | G60: =$F$49*MIN($B60,$G$49)+$I$49*MAX(0,$B60-$G$49)+$J$49*MAX(0,$B60-$K$49) -> 1260
B61: 0.35 | C61: =$F$45*MIN($B61,$G$45)+$I$45*MAX(0,$B61-$G$45)+$J$45*MAX(0,$B61-$K$45) -> 1274.7 | D61: =$F$46*MIN($B61,$G$46)+$I$46*MAX(0,$B61-$G$46)+$J$46*MAX(0,$B61-$K$46) -> 1339.8 | E61: =$F$47*MIN($B61,$G$47)+$I$47*MAX(0,$B61-$G$47)+$J$47*MAX(0,$B61-$K$47) -> 1404.9 | F61: =$F$48*MIN($B61,$G$48)+$I$48*MAX(0,$B61-$G$48)+$J$48*MAX(0,$B61-$K$48) -> 1470 | G61: =$F$49*MIN($B61,$G$49)+$I$49*MAX(0,$B61-$G$49)+$J$49*MAX(0,$B61-$K$49) -> 1470
B62: 0.4 | C62: =$F$45*MIN($B62,$G$45)+$I$45*MAX(0,$B62-$G$45)+$J$45*MAX(0,$B62-$K$45) -> 1419.6 | D62: =$F$46*MIN($B62,$G$46)+$I$46*MAX(0,$B62-$G$46)+$J$46*MAX(0,$B62-$K$46) -> 1484.7 | E62: =$F$47*MIN($B62,$G$47)+$I$47*MAX(0,$B62-$G$47)+$J$47*MAX(0,$B62-$K$47) -> 1549.8 | F62: =$F$48*MIN($B62,$G$48)+$I$48*MAX(0,$B62-$G$48)+$J$48*MAX(0,$B62-$K$48) -> 1614.9 | G62: =$F$49*MIN($B62,$G$49)+$I$49*MAX(0,$B62-$G$49)+$J$49*MAX(0,$B62-$K$49) -> 1680
B63: 0.45 | C63: =$F$45*MIN($B63,$G$45)+$I$45*MAX(0,$B63-$G$45)+$J$45*MAX(0,$B63-$K$45) -> 1564.5 | D63: =$F$46*MIN($B63,$G$46)+$I$46*MAX(0,$B63-$G$46)+$J$46*MAX(0,$B63-$K$46) -> 1629.6 | E63: =$F$47*MIN($B63,$G$47)+$I$47*MAX(0,$B63-$G$47)+$J$47*MAX(0,$B63-$K$47) -> 1694.7 | F63: =$F$48*MIN($B63,$G$48)+$I$48*MAX(0,$B63-$G$48)+$J$48*MAX(0,$B63-$K$48) -> 1759.8 | G63: =$F$49*MIN($B63,$G$49)+$I$49*MAX(0,$B63-$G$49)+$J$49*MAX(0,$B63-$K$49) -> 1824.9
B64: 0.5 | C64: =$F$45*MIN($B64,$G$45)+$I$45*MAX(0,$B64-$G$45)+$J$45*MAX(0,$B64-$K$45) -> 1709.4 | D64: =$F$46*MIN($B64,$G$46)+$I$46*MAX(0,$B64-$G$46)+$J$46*MAX(0,$B64-$K$46) -> 1774.5 | E64: =$F$47*MIN($B64,$G$47)+$I$47*MAX(0,$B64-$G$47)+$J$47*MAX(0,$B64-$K$47) -> 1839.6 | F64: =$F$48*MIN($B64,$G$48)+$I$48*MAX(0,$B64-$G$48)+$J$48*MAX(0,$B64-$K$48) -> 1904.7 | G64: =$F$49*MIN($B64,$G$49)+$I$49*MAX(0,$B64-$G$49)+$J$49*MAX(0,$B64-$K$49) -> 1969.8
...
