Workbook

Sheet Rally2
B1: Language / 语言 | C1: Language / 语言 | D1: Language / 语言 | E1: 简体中文 | F1: 简体中文 | G1: 简体中文
B2: =VLOOKUP("title.rally2GearingShiftLights",Locale!$A$2:$D$73,4,FALSE) -> Rally2 · 齿比与换挡灯
B5: =VLOOKUP("chart.engineCurve",Locale!$A$2:$D$73,4,FALSE) -> 发动机曲线 | F5: =VLOOKUP("label.calibrationBasis",Locale!$A$2:$D$73,4,FALSE) -> 标定依据 | K5: =VLOOKUP("label.shiftLights",Locale!$A$2:$D$73,4,FALSE) -> 换挡灯
B6: =VLOOKUP("label.peakPowerHp",Locale!$A$2:$D$73,4,FALSE) -> 峰值功率 (hp) | D6: =MAX(Samples!$D$7:$D$19) -> 285.92509 | F6: =VLOOKUP("label.runningMassKg",Locale!$A$2:$D$73,4,FALSE) -> 运行质量 (kg) | I6: 1420.59 | K6: =VLOOKUP("label.neutralFlashRpm",Locale!$A$2:$D$73,4,FALSE) -> 空挡闪烁 (rpm) | O6: 3000
B7: =VLOOKUP("label.powerPeakRpm",Locale!$A$2:$D$73,4,FALSE) -> 功率峰值转速 (rpm) | D7: =INDEX(Samples!$B$7:$B$19,MATCH(D6,Samples!$D$7:$D$19,0)) -> 5275 | F7: =VLOOKUP("label.engineFlywheelInertia",Locale!$A$2:$D$73,4,FALSE) -> 发动机 + 飞轮转动惯量 (kg m²) | I7: 0.12344 | K7: =VLOOKUP("label.topGearLimiterRpm",Locale!$A$2:$D$73,4,FALSE) -> 最高挡 / 限转 (rpm) | O7: 7500
B8: =VLOOKUP("label.peakTorqueNm",Locale!$A$2:$D$73,4,FALSE) -> 峰值扭矩 (Nm) | D8: =MAX(Samples!$C$7:$C$19) -> 425.46588 | F8: =VLOOKUP("label.finalDrive",Locale!$A$2:$D$73,4,FALSE) -> 主减速比 | I8: 4.1333333 | K8: =VLOOKUP("label.lightRangeRpm",Locale!$A$2:$D$73,4,FALSE) -> 亮灯范围 (rpm) | O8: 800
B9: =VLOOKUP("label.torquePeakRpm",Locale!$A$2:$D$73,4,FALSE) -> 峰值扭矩转速 (rpm) | D9: =INDEX(Samples!$B$7:$B$19,MATCH(D8,Samples!$C$7:$C$19,0)) -> 4157 | F9: =VLOOKUP("label.gearboxTorqueLoss",Locale!$A$2:$D$73,4,FALSE) -> 变速箱扭矩损失 | I9: 0.011 | K9: =VLOOKUP("label.roundingRpm",Locale!$A$2:$D$73,4,FALSE) -> 取整步长 (rpm) | O9: 10
B11: =VLOOKUP("note.yellowInputs",Locale!$A$2:$D$73,4,FALSE) -> 黄色单元格为手动输入。
B13: =VLOOKUP("label.groupOneTypeATarmac",Locale!$A$2:$D$73,4,FALSE) -> 第 1 组 · Type-A / 柏油 | J13: =VLOOKUP("label.groupTwoTypeBGravel",Locale!$A$2:$D$73,4,FALSE) -> 第 2 组 · Type-B / 砂石
B14: =VLOOKUP("label.gear",Locale!$A$2:$D$73,4,FALSE) -> 挡位 | C14: =VLOOKUP("label.gearRatio",Locale!$A$2:$D$73,4,FALSE) -> 齿比 | D14: =VLOOKUP("label.flashRpmWrap",Locale!$A$2:$D$73,4,FALSE) -> 闪烁 (rpm) | E14: =VLOOKUP("label.afterShiftRpmWrap",Locale!$A$2:$D$73,4,FALSE) -> 换挡后 (rpm) | F14: =VLOOKUP("label.speedKmhMultiline",Locale!$A$2:$D$73,4,FALSE) -> 车速 (km/h) | G14: =VLOOKUP("label.firstLightRpm",Locale!$A$2:$D$73,4,FALSE) -> 首灯亮起 (rpm) | H14: =VLOOKUP("label.trigger",Locale!$A$2:$D$73,4,FALSE) -> 触发条件 | J14: =VLOOKUP("label.gear",Locale!$A$2:$D$73,4,FALSE) -> 挡位 | K14: =VLOOKUP("label.gearRatio",Locale!$A$2:$D$73,4,FALSE) -> 齿比 | L14: =VLOOKUP("label.flashRpmWrap",Locale!$A$2:$D$73,4,FALSE) -> 闪烁 (rpm) | M14: =VLOOKUP("label.afterShiftRpmWrap",Locale!$A$2:$D$73,4,FALSE) -> 换挡后 (rpm) | N14: =VLOOKUP("label.speedKmhMultiline",Locale!$A$2:$D$73,4,FALSE) -> 车速 (km/h) | O14: =VLOOKUP("label.firstLightRpm",Locale!$A$2:$D$73,4,FALSE) -> 首灯亮起 (rpm) | P14: =VLOOKUP("label.trigger",Locale!$A$2:$D$73,4,FALSE) -> 触发条件
B15: 1 | C15: 3.762 | D15: 6170 | E15: =D15*C16/C15 -> 4411.8288 | F15: =D15*2*PI()/60*$D$22/(C15*$I$8)*3.6 -> 48.616134 | G15: =MAX(0,D15-$O$8) -> 5370 | H15: =VLOOKUP("label.shift",Locale!$A$2:$D$73,4,FALSE) -> 换挡 | J15: 1 | K15: 3.365 | L15: 6460 | M15: =L15*K16/K15 -> 4423.1322 | N15: =L15*2*PI()/60*$L$22/(K15*$I$8)*3.6 -> 56.731354 | O15: =MAX(0,L15-$O$8) -> 5660 | P15: =VLOOKUP("label.shift",Locale!$A$2:$D$73,4,FALSE) -> 换挡
B16: 2 | C16: 2.69 | D16: 6360 | E16: =D16*C17/C16 -> 4636.4164 | F16: =D16*2*PI()/60*$D$22/(C16*$I$8)*3.6 -> 70.084001 | G16: =MAX(0,D16-$O$8) -> 5560 | H16: =VLOOKUP("label.shift",Locale!$A$2:$D$73,4,FALSE) -> 换挡 | J16: 2 | K16: 2.304 | L16: 6210 | M16: =L16*K17/K16 -> 4738.3594 | N16: =L16*2*PI()/60*$L$22/(K16*$I$8)*3.6 -> 79.649825 | O16: =MAX(0,L16-$O$8) -> 5410 | P16: =VLOOKUP("label.shift",Locale!$A$2:$D$73,4,FALSE) -> 换挡
B17: 3 | C17: 1.961 | D17: 6290 | E17: =D17*C18/C17 -> 4779.2453 | F17: =D17*2*PI()/60*$D$22/(C17*$I$8)*3.6 -> 95.079546 | G17: =MAX(0,D17-$O$8) -> 5490 | H17: =VLOOKUP("label.shift",Locale!$A$2:$D$73,4,FALSE) -> 换挡 | J17: 3 | K17: 1.758 | L17: 6150 | M17: =L17*K18/K17 -> 4838.1399 | N17: =L17*2*PI()/60*$L$22/(K17*$I$8)*3.6 -> 103.37891 | O17: =MAX(0,L17-$O$8) -> 5350 | P17: =VLOOKUP("label.shift",Locale!$A$2:$D$73,4,FALSE) -> 换挡
B18: 4 | C18: 1.49 | D18: 6120 | E18: =D18*C19/C18 -> 4883.6779 | F18: =D18*2*PI()/60*$D$22/(C18*$I$8)*3.6 -> 121.75287 | G18: =MAX(0,D18-$O$8) -> 5320 | H18: =VLOOKUP("label.shift",Locale!$A$2:$D$73,4,FALSE) -> 换挡 | J18: 4 | K18: 1.383 | L18: 6080 | M18: =L18*K19/K18 -> 4897.4114 | N18: =L18*2*PI()/60*$L$22/(K18*$I$8)*3.6 -> 129.91434 | O18: =MAX(0,L18-$O$8) -> 5280 | P18: =VLOOKUP("label.shift",Locale!$A$2:$D$73,4,FALSE) -> 换挡
B19: 5 | C19: 1.189 | D19: =$O$7 -> 7500 | E19: — | F19: =D19*2*PI()/60*$D$22/(C19*$I$8)*3.6 -> 186.97927 | G19: =MAX(0,D19-$O$8) -> 6700 | H19: =VLOOKUP("label.limiter",Locale!$A$2:$D$73,4,FALSE) -> 限转 | J19: 5 | K19: 1.114 | L19: =$O$7 -> 7500 | M19: — | N19: =L19*2*PI()/60*$L$22/(K19*$I$8)*3.6 -> 198.95359 | O19: =MAX(0,L19-$O$8) -> 6700 | P19: =VLOOKUP("label.limiter",Locale!$A$2:$D$73,4,FALSE) -> 限转
B22: =VLOOKUP("label.tyreRadiusM",Locale!$A$2:$D$73,4,FALSE) -> 轮胎半径 (m) | D22: 0.325 | F22: =VLOOKUP("label.wheelInertia",Locale!$A$2:$D$73,4,FALSE) -> 车轮转动惯量 I (kg m²) | H22: 5.4748128 | J22: =VLOOKUP("label.tyreRadiusM",Locale!$A$2:$D$73,4,FALSE) -> 轮胎半径 (m) | L22: 0.324 | N22: =VLOOKUP("label.wheelInertia",Locale!$A$2:$D$73,4,FALSE) -> 车轮转动惯量 I (kg m²) | P22: 5.7898435
B23: =VLOOKUP("label.gearboxFriction",Locale!$A$2:$D$73,4,FALSE) -> 变速箱摩擦阻力 (Nm) | D23: 1.65 | F23: =VLOOKUP("label.gearboxDynamicLoss",Locale!$A$2:$D$73,4,FALSE) -> 变速箱动态阻力 (Nm s) | H23: 0.00078 | J23: =VLOOKUP("label.gearboxFriction",Locale!$A$2:$D$73,4,FALSE) -> 变速箱摩擦阻力 (Nm) | L23: =$D$23 -> 1.65 | N23: =VLOOKUP("label.gearboxDynamicLoss",Locale!$A$2:$D$73,4,FALSE) -> 变速箱动态阻力 (Nm s) | P23: =$H$23 -> 0.00078
B53: =VLOOKUP("label.gearGroup",Locale!$A$2:$D$73,4,FALSE) -> 齿轮组 | D53: 1 | E53: =IF(D53=1,VLOOKUP("label.groupOneTypeATarmac",Locale!$A$2:$D$73,4,FALSE),VLOOKUP("label.groupTwoTypeBGravel",Locale!$A$2:$D$73,4,FALSE)) -> 第 1 组 · Type-A / 柏油

Sheet WRC16
B2: =VLOOKUP("title.wrc16GearingShiftLights",Locale!$A$2:$D$73,4,FALSE) -> WRC16 · 齿比与换挡灯
B5: =VLOOKUP("chart.engineCurve",Locale!$A$2:$D$73,4,FALSE) -> 发动机曲线 | F5: =VLOOKUP("label.calibrationBasis",Locale!$A$2:$D$73,4,FALSE) -> 标定依据 | K5: =VLOOKUP("label.shiftLights",Locale!$A$2:$D$73,4,FALSE) -> 换挡灯
B6: =VLOOKUP("label.peakPowerHp",Locale!$A$2:$D$73,4,FALSE) -> 峰值功率 (hp) | D6: =MAX(Samples!$D$37:$D$50) -> 305.30881 | F6: =VLOOKUP("label.runningMassKg",Locale!$A$2:$D$73,4,FALSE) -> 运行质量 (kg) | I6: 1390 | K6: =VLOOKUP("label.neutralFlashRpm",Locale!$A$2:$D$73,4,FALSE) -> 空挡闪烁 (rpm) | O6: 3000
B7: =VLOOKUP("label.powerPeakRpm",Locale!$A$2:$D$73,4,FALSE) -> 功率峰值转速 (rpm) | D7: =INDEX(Samples!$B$37:$B$50,MATCH(D6,Samples!$D$37:$D$50,0)) -> 6060 | F7: =VLOOKUP("label.engineFlywheelInertia",Locale!$A$2:$D$73,4,FALSE) -> 发动机 + 飞轮转动惯量 (kg m²) | I7: 0.121716 | K7: =VLOOKUP("label.topGearLimiterRpm",Locale!$A$2:$D$73,4,FALSE) -> 最高挡 / 限转 (rpm) | O7: 7650
B8: =VLOOKUP("label.peakTorqueNm",Locale!$A$2:$D$73,4,FALSE) -> 峰值扭矩 (Nm) | D8: =MAX(Samples!$C$37:$C$50) -> 409.34482 | F8: =VLOOKUP("label.finalDrive",Locale!$A$2:$D$73,4,FALSE) -> 主减速比 | I8: 4.1333333 | K8: =VLOOKUP("label.lightRangeRpm",Locale!$A$2:$D$73,4,FALSE) -> 亮灯范围 (rpm) | O8: 800
B9: =VLOOKUP("label.torquePeakRpm",Locale!$A$2:$D$73,4,FALSE) -> 峰值扭矩转速 (rpm) | D9: =INDEX(Samples!$B$37:$B$50,MATCH(D8,Samples!$C$37:$C$50,0)) -> 4715 | F9: =VLOOKUP("label.gearboxTorqueLoss",Locale!$A$2:$D$73,4,FALSE) -> 变速箱扭矩损失 | I9: 0.012 | K9: =VLOOKUP("label.roundingRpm",Locale!$A$2:$D$73,4,FALSE) -> 取整步长 (rpm) | O9: 10
B11: =VLOOKUP("note.yellowInputs",Locale!$A$2:$D$73,4,FALSE) -> 黄色单元格为手动输入。
B13: =VLOOKUP("label.groupOneTypeATarmac",Locale!$A$2:$D$73,4,FALSE) -> 第 1 组 · Type-A / 柏油 | J13: =VLOOKUP("label.groupTwoTypeBGravel",Locale!$A$2:$D$73,4,FALSE) -> 第 2 组 · Type-B / 砂石
B14: =VLOOKUP("label.gear",Locale!$A$2:$D$73,4,FALSE) -> 挡位 | C14: =VLOOKUP("label.gearRatio",Locale!$A$2:$D$73,4,FALSE) -> 齿比 | D14: =VLOOKUP("label.flashRpmWrap",Locale!$A$2:$D$73,4,FALSE) -> 闪烁 (rpm) | E14: =VLOOKUP("label.afterShiftRpmWrap",Locale!$A$2:$D$73,4,FALSE) -> 换挡后 (rpm) | F14: =VLOOKUP("label.speedKmhMultiline",Locale!$A$2:$D$73,4,FALSE) -> 车速 (km/h) | G14: =VLOOKUP("label.firstLightRpm",Locale!$A$2:$D$73,4,FALSE) -> 首灯亮起 (rpm) | H14: =VLOOKUP("label.trigger",Locale!$A$2:$D$73,4,FALSE) -> 触发条件 | J14: =VLOOKUP("label.gear",Locale!$A$2:$D$73,4,FALSE) -> 挡位 | K14: =VLOOKUP("label.gearRatio",Locale!$A$2:$D$73,4,FALSE) -> 齿比 | L14: =VLOOKUP("label.flashRpmWrap",Locale!$A$2:$D$73,4,FALSE) -> 闪烁 (rpm) | M14: =VLOOKUP("label.afterShiftRpmWrap",Locale!$A$2:$D$73,4,FALSE) -> 换挡后 (rpm) | N14: =VLOOKUP("label.speedKmhMultiline",Locale!$A$2:$D$73,4,FALSE) -> 车速 (km/h) | O14: =VLOOKUP("label.firstLightRpm",Locale!$A$2:$D$73,4,FALSE) -> 首灯亮起 (rpm) | P14: =VLOOKUP("label.trigger",Locale!$A$2:$D$73,4,FALSE) -> 触发条件
B15: 1 | C15: 3.797 | D15: 6250 | E15: =D15*C16/C15 -> 5086.2523 | F15: =D15*2*PI()/60*$D$22/(C15*$I$8)*3.6 -> 48.792545 | G15: =MAX(0,D15-$O$8) -> 5450 | H15: =VLOOKUP("label.shift",Locale!$A$2:$D$73,4,FALSE) -> 换挡 | J15: 1 | K15: 3.491 | L15: 6350 | M15: =L15*K16/K15 -> 5091.2776 | N15: =L15*2*PI()/60*$L$22/(K15*$I$8)*3.6 -> 53.752612 | O15: =MAX(0,L15-$O$8) -> 5550 | P15: =VLOOKUP("label.shift",Locale!$A$2:$D$73,4,FALSE) -> 换挡
B16: 2 | C16: 3.09 | D16: 6460 | E16: =D16*C17/C16 -> 5182.6343 | F16: =D16*2*PI()/60*$D$22/(C16*$I$8)*3.6 -> 61.970941 | G16: =MAX(0,D16-$O$8) -> 5660 | H16: =VLOOKUP("label.shift",Locale!$A$2:$D$73,4,FALSE) -> 换挡 | J16: 2 | K16: 2.799 | L16: 6510 | M16: =L16*K17/K16 -> 5221.4898 | N16: =L16*2*PI()/60*$L$22/(K16*$I$8)*3.6 -> 68.731178 | O16: =MAX(0,L16-$O$8) -> 5710 | P16: =VLOOKUP("label.shift",Locale!$A$2:$D$73,4,FALSE) -> 换挡
B17: 3 | C17: 2.479 | D17: 6550 | E17: =D17*C18/C17 -> 5276.4623 | F17: =D17*2*PI()/60*$D$22/(C17*$I$8)*3.6 -> 78.321108 | G17: =MAX(0,D17-$O$8) -> 5750 | H17: =VLOOKUP("label.shift",Locale!$A$2:$D$73,4,FALSE) -> 换挡 | J17: 3 | K17: 2.245 | L17: 6560 | M17: =L17*K18/K17 -> 5315.2071 | N17: =L17*2*PI()/60*$L$22/(K17*$I$8)*3.6 -> 86.350169 | O17: =MAX(0,L17-$O$8) -> 5760 | P17: =VLOOKUP("label.shift",Locale!$A$2:$D$73,4,FALSE) -> 换挡
B18: 4 | C18: 1.997 | D18: 6610 | E18: =D18*C19/C18 -> 5332.3535 | F18: =D18*2*PI()/60*$D$22/(C18*$I$8)*3.6 -> 98.11546 | G18: =MAX(0,D18-$O$8) -> 5810 | H18: =VLOOKUP("label.shift",Locale!$A$2:$D$73,4,FALSE) -> 换挡 | J18: 4 | K18: 1.819 | L18: 6580 | M18: =L18*K19/K18 -> 5382.6498 | N18: =L18*2*PI()/60*$L$22/(K18*$I$8)*3.6 -> 106.89783 | O18: =MAX(0,L18-$O$8) -> 5780 | P18: =VLOOKUP("label.shift",Locale!$A$2:$D$73,4,FALSE) -> 换挡
B19: 5 | C19: 1.611 | D19: 6610 | E19: =D19*C20/C19 -> 5399.6027 | F19: =D19*2*PI()/60*$D$22/(C19*$I$8)*3.6 -> 121.62419 | G19: =MAX(0,D19-$O$8) -> 5810 | H19: =VLOOKUP("label.shift",Locale!$A$2:$D$73,4,FALSE) -> 换挡 | J19: 5 | K19: 1.488 | L19: 6590 | M19: =L19*K20/K19 -> 5434.0927 | N19: =L19*2*PI()/60*$L$22/(K19*$I$8)*3.6 -> 130.87545 | O19: =MAX(0,L19-$O$8) -> 5790 | P19: =VLOOKUP("label.shift",Locale!$A$2:$D$73,4,FALSE) -> 换挡
B20: 6 | C20: 1.316 | D20: =$O$7 -> 7650 | E20: — | F20: =D20*2*PI()/60*$D$22/(C20*$I$8)*3.6 -> 172.31362 | G20: =MAX(0,D20-$O$8) -> 6850 | H20: =VLOOKUP("label.limiter",Locale!$A$2:$D$73,4,FALSE) -> 限转 | J20: 6 | K20: 1.227 | L20: =$O$7 -> 7650 | M20: — | N20: =L20*2*PI()/60*$L$22/(K20*$I$8)*3.6 -> 184.24367 | O20: =MAX(0,L20-$O$8) -> 6850 | P20: =VLOOKUP("label.limiter",Locale!$A$2:$D$73,4,FALSE) -> 限转
B22: =VLOOKUP("label.tyreRadiusM",Locale!$A$2:$D$73,4,FALSE) -> 轮胎半径 (m) | D22: 0.325 | F22: =VLOOKUP("label.wheelInertia",Locale!$A$2:$D$73,4,FALSE) -> 车轮转动惯量 I (kg m²) | H22: 5.4748128 | J22: =VLOOKUP("label.tyreRadiusM",Locale!$A$2:$D$73,4,FALSE) -> 轮胎半径 (m) | L22: 0.324 | N22: =VLOOKUP("label.wheelInertia",Locale!$A$2:$D$73,4,FALSE) -> 车轮转动惯量 I (kg m²) | P22: 5.7898435
B23: =VLOOKUP("label.gearboxFriction",Locale!$A$2:$D$73,4,FALSE) -> 变速箱摩擦阻力 (Nm) | D23: 1.85 | F23: =VLOOKUP("label.gearboxDynamicLoss",Locale!$A$2:$D$73,4,FALSE) -> 变速箱动态阻力 (Nm s) | H23: 0.00098 | J23: =VLOOKUP("label.gearboxFriction",Locale!$A$2:$D$73,4,FALSE) -> 变速箱摩擦阻力 (Nm) | L23: =$D$23 -> 1.85 | N23: =VLOOKUP("label.gearboxDynamicLoss",Locale!$A$2:$D$73,4,FALSE) -> 变速箱动态阻力 (Nm s) | P23: =$H$23 -> 0.00098
B53: =VLOOKUP("label.gearGroup",Locale!$A$2:$D$73,4,FALSE) -> 齿轮组 | D53: 1 | E53: =IF(D53=1,VLOOKUP("label.groupOneTypeATarmac",Locale!$A$2:$D$73,4,FALSE),VLOOKUP("label.groupTwoTypeBGravel",Locale!$A$2:$D$73,4,FALSE)) -> 第 1 组 · Type-A / 柏油

Sheet WRC17
B2: =VLOOKUP("title.wrc17GearingShiftLights",Locale!$A$2:$D$73,4,FALSE) -> WRC17 · 齿比与换挡灯
B5: =VLOOKUP("chart.engineCurve",Locale!$A$2:$D$73,4,FALSE) -> 发动机曲线 | F5: =VLOOKUP("label.calibrationBasis",Locale!$A$2:$D$73,4,FALSE) -> 标定依据 | K5: =VLOOKUP("label.shiftLights",Locale!$A$2:$D$73,4,FALSE) -> 换挡灯
B6: =VLOOKUP("label.peakPowerHp",Locale!$A$2:$D$73,4,FALSE) -> 峰值功率 (hp) | D6: =MAX(Samples!$D$67:$D$81) -> 379.61801 | F6: =VLOOKUP("label.runningMassKg",Locale!$A$2:$D$73,4,FALSE) -> 运行质量 (kg) | I6: 1391.01 | K6: =VLOOKUP("label.neutralFlashRpm",Locale!$A$2:$D$73,4,FALSE) -> 空挡闪烁 (rpm) | O6: 3000
B7: =VLOOKUP("label.powerPeakRpm",Locale!$A$2:$D$73,4,FALSE) -> 功率峰值转速 (rpm) | D7: =INDEX(Samples!$B$67:$B$81,MATCH(D6,Samples!$D$67:$D$81,0)) -> 6589 | F7: =VLOOKUP("label.engineFlywheelInertia",Locale!$A$2:$D$73,4,FALSE) -> 发动机 + 飞轮转动惯量 (kg m²) | I7: 0.121716 | K7: =VLOOKUP("label.topGearLimiterRpm",Locale!$A$2:$D$73,4,FALSE) -> 最高挡 / 限转 (rpm) | O7: 8500
B8: =VLOOKUP("label.peakTorqueNm",Locale!$A$2:$D$73,4,FALSE) -> 峰值扭矩 (Nm) | D8: =MAX(Samples!$C$67:$C$81) -> 450.42287 | F8: =VLOOKUP("label.finalDrive",Locale!$A$2:$D$73,4,FALSE) -> 主减速比 | I8: 4.4666667 | K8: =VLOOKUP("label.lightRangeRpm",Locale!$A$2:$D$73,4,FALSE) -> 亮灯范围 (rpm) | O8: 800
B9: =VLOOKUP("label.torquePeakRpm",Locale!$A$2:$D$73,4,FALSE) -> 峰值扭矩转速 (rpm) | D9: =INDEX(Samples!$B$67:$B$81,MATCH(D8,Samples!$C$67:$C$81,0)) -> 5242 | F9: =VLOOKUP("label.gearboxTorqueLoss",Locale!$A$2:$D$73,4,FALSE) -> 变速箱扭矩损失 | I9: 0.012 | K9: =VLOOKUP("label.roundingRpm",Locale!$A$2:$D$73,4,FALSE) -> 取整步长 (rpm) | O9: 10
B11: =VLOOKUP("note.yellowInputs",Locale!$A$2:$D$73,4,FALSE) -> 黄色单元格为手动输入。
B13: =VLOOKUP("label.groupOneTypeATarmac",Locale!$A$2:$D$73,4,FALSE) -> 第 1 组 · Type-A / 柏油 | J13: =VLOOKUP("label.groupTwoTypeBGravel",Locale!$A$2:$D$73,4,FALSE) -> 第 2 组 · Type-B / 砂石
B14: =VLOOKUP("label.gear",Locale!$A$2:$D$73,4,FALSE) -> 挡位 | C14: =VLOOKUP("label.gearRatio",Locale!$A$2:$D$73,4,FALSE) -> 齿比 | D14: =VLOOKUP("label.flashRpmWrap",Locale!$A$2:$D$73,4,FALSE) -> 闪烁 (rpm) | E14: =VLOOKUP("label.afterShiftRpmWrap",Locale!$A$2:$D$73,4,FALSE) -> 换挡后 (rpm) | F14: =VLOOKUP("label.speedKmhMultiline",Locale!$A$2:$D$73,4,FALSE) -> 车速 (km/h) | G14: =VLOOKUP("label.firstLightRpm",Locale!$A$2:$D$73,4,FALSE) -> 首灯亮起 (rpm) | H14: =VLOOKUP("label.trigger",Locale!$A$2:$D$73,4,FALSE) -> 触发条件 | J14: =VLOOKUP("label.gear",Locale!$A$2:$D$73,4,FALSE) -> 挡位 | K14: =VLOOKUP("label.gearRatio",Locale!$A$2:$D$73,4,FALSE) -> 齿比 | L14: =VLOOKUP("label.flashRpmWrap",Locale!$A$2:$D$73,4,FALSE) -> 闪烁 (rpm) | M14: =VLOOKUP("label.afterShiftRpmWrap",Locale!$A$2:$D$73,4,FALSE) -> 换挡后 (rpm) | N14: =VLOOKUP("label.speedKmhMultiline",Locale!$A$2:$D$73,4,FALSE) -> 车速 (km/h) | O14: =VLOOKUP("label.firstLightRpm",Locale!$A$2:$D$73,4,FALSE) -> 首灯亮起 (rpm) | P14: =VLOOKUP("label.trigger",Locale!$A$2:$D$73,4,FALSE) -> 触发条件
B15: 1 | C15: 3.515 | D15: 6970 | E15: =D15*C16/C15 -> 5671.1807 | F15: =D15*2*PI()/60*$D$22/(C15*$I$8)*3.6 -> 54.39242 | G15: =MAX(0,D15-$O$8) -> 6170 | H15: =VLOOKUP("label.shift",Locale!$A$2:$D$73,4,FALSE) -> 换挡 | J15: 1 | K15: 3.235 | L15: 7080 | M15: =L15*K16/K15 -> 5679.3199 | N15: =L15*2*PI()/60*$L$22/(K15*$I$8)*3.6 -> 59.848264 | O15: =MAX(0,L15-$O$8) -> 6280 | P15: =VLOOKUP("label.shift",Locale!$A$2:$D$73,4,FALSE) -> 换挡
B16: 2 | C16: 2.86 | D16: 7180 | E16: =D16*C17/C16 -> 5761.5734 | F16: =D16*2*PI()/60*$D$22/(C16*$I$8)*3.6 -> 68.86354 | G16: =MAX(0,D16-$O$8) -> 6380 | H16: =VLOOKUP("label.shift",Locale!$A$2:$D$73,4,FALSE) -> 换挡 | J16: 2 | K16: 2.595 | L16: 7220 | M16: =L16*K17/K16 -> 5795.4759 | N16: =L16*2*PI()/60*$L$22/(K16*$I$8)*3.6 -> 76.083839 | O16: =MAX(0,L16-$O$8) -> 6420 | P16: =VLOOKUP("label.shift",Locale!$A$2:$D$73,4,FALSE) -> 换挡
B17: 3 | C17: 2.295 | D17: 7250 | E17: =D17*C18/C17 -> 5837.9085 | F17: =D17*2*PI()/60*$D$22/(C17*$I$8)*3.6 -> 86.653529 | G17: =MAX(0,D17-$O$8) -> 6450 | H17: =VLOOKUP("label.shift",Locale!$A$2:$D$73,4,FALSE) -> 换挡 | J17: 3 | K17: 2.083 | L17: 7240 | M17: =L17*K18/K17 -> 5863.6006 | N17: =L17*2*PI()/60*$L$22/(K17*$I$8)*3.6 -> 95.047759 | O17: =MAX(0,L17-$O$8) -> 6440 | P17: =VLOOKUP("label.shift",Locale!$A$2:$D$73,4,FALSE) -> 换挡
B18: 4 | C18: 1.848 | D18: 7290 | E18: =D18*C19/C18 -> 5881.7045 | F18: =D18*2*PI()/60*$D$22/(C18*$I$8)*3.6 -> 108.20728 | G18: =MAX(0,D18-$O$8) -> 6490 | H18: =VLOOKUP("label.shift",Locale!$A$2:$D$73,4,FALSE) -> 换挡 | J18: 4 | K18: 1.687 | L18: 7240 | M18: =L18*K19/K18 -> 5922.4659 | N18: =L18*2*PI()/60*$L$22/(K18*$I$8)*3.6 -> 117.35891 | O18: =MAX(0,L18-$O$8) -> 6440 | P18: =VLOOKUP("label.shift",Locale!$A$2:$D$73,4,FALSE) -> 换挡
B19: 5 | C19: 1.491 | D19: 7270 | E19: =D19*C20/C19 -> 5938.8732 | F19: =D19*2*PI()/60*$D$22/(C19*$I$8)*3.6 -> 133.74813 | G19: =MAX(0,D19-$O$8) -> 6470 | H19: =VLOOKUP("label.shift",Locale!$A$2:$D$73,4,FALSE) -> 换挡 | J19: 5 | K19: 1.38 | L19: 7240 | M19: =L19*K20/K19 -> 5970.3768 | N19: =L19*2*PI()/60*$L$22/(K19*$I$8)*3.6 -> 143.46702 | O19: =MAX(0,L19-$O$8) -> 6440 | P19: =VLOOKUP("label.shift",Locale!$A$2:$D$73,4,FALSE) -> 换挡
B20: 6 | C20: 1.218 | D20: =$O$7 -> 8500 | E20: — | F20: =D20*2*PI()/60*$D$22/(C20*$I$8)*3.6 -> 191.42673 | G20: =MAX(0,D20-$O$8) -> 7700 | H20: =VLOOKUP("label.limiter",Locale!$A$2:$D$73,4,FALSE) -> 限转 | J20: 6 | K20: 1.138 | L20: =$O$7 -> 8500 | M20: — | N20: =L20*2*PI()/60*$L$22/(K20*$I$8)*3.6 -> 204.25338 | O20: =MAX(0,L20-$O$8) -> 7700 | P20: =VLOOKUP("label.limiter",Locale!$A$2:$D$73,4,FALSE) -> 限转
B22: =VLOOKUP("label.tyreRadiusM",Locale!$A$2:$D$73,4,FALSE) -> 轮胎半径 (m) | D22: 0.325 | F22: =VLOOKUP("label.wheelInertia",Locale!$A$2:$D$73,4,FALSE) -> 车轮转动惯量 I (kg m²) | H22: 5.4748128 | J22: =VLOOKUP("label.tyreRadiusM",Locale!$A$2:$D$73,4,FALSE) -> 轮胎半径 (m) | L22: 0.324 | N22: =VLOOKUP("label.wheelInertia",Locale!$A$2:$D$73,4,FALSE) -> 车轮转动惯量 I (kg m²) | P22: 5.7898435
B23: =VLOOKUP("label.gearboxFriction",Locale!$A$2:$D$73,4,FALSE) -> 变速箱摩擦阻力 (Nm) | D23: 1.85 | F23: =VLOOKUP("label.gearboxDynamicLoss",Locale!$A$2:$D$73,4,FALSE) -> 变速箱动态阻力 (Nm s) | H23: 0.00098 | J23: =VLOOKUP("label.gearboxFriction",Locale!$A$2:$D$73,4,FALSE) -> 变速箱摩擦阻力 (Nm) | L23: =$D$23 -> 1.85 | N23: =VLOOKUP("label.gearboxDynamicLoss",Locale!$A$2:$D$73,4,FALSE) -> 变速箱动态阻力 (Nm s) | P23: =$H$23 -> 0.00098
B53: =VLOOKUP("label.gearGroup",Locale!$A$2:$D$73,4,FALSE) -> 齿轮组 | D53: 1 | E53: =IF(D53=1,VLOOKUP("label.groupOneTypeATarmac",Locale!$A$2:$D$73,4,FALSE),VLOOKUP("label.groupTwoTypeBGravel",Locale!$A$2:$D$73,4,FALSE)) -> 第 1 组 · Type-A / 柏油

Sheet 25R1
B2: =VLOOKUP("title.25r1GearingShiftLights",Locale!$A$2:$D$75,4,FALSE) -> 25R1 · 齿比与换挡灯
B5: =VLOOKUP("chart.engineCurve",Locale!$A$2:$D$73,4,FALSE) -> 发动机曲线 | F5: =VLOOKUP("label.calibrationBasis",Locale!$A$2:$D$73,4,FALSE) -> 标定依据 | K5: =VLOOKUP("label.shiftLights",Locale!$A$2:$D$73,4,FALSE) -> 换挡灯
B6: =VLOOKUP("label.peakPowerHp",Locale!$A$2:$D$73,4,FALSE) -> 峰值功率 (hp) | D6: =MAX(Samples!$D$97:$D$111) -> 369.61504 | F6: =VLOOKUP("label.runningMassKg",Locale!$A$2:$D$73,4,FALSE) -> 运行质量 (kg) | I6: 1380 | K6: =VLOOKUP("label.neutralFlashRpm",Locale!$A$2:$D$73,4,FALSE) -> 空挡闪烁 (rpm) | O6: 3000
B7: =VLOOKUP("label.powerPeakRpm",Locale!$A$2:$D$73,4,FALSE) -> 功率峰值转速 (rpm) | D7: =INDEX(Samples!$B$97:$B$111,MATCH(D6,Samples!$D$97:$D$111,0)) -> 7023 | F7: =VLOOKUP("label.engineFlywheelInertia",Locale!$A$2:$D$73,4,FALSE) -> 发动机 + 飞轮转动惯量 (kg m²) | I7: 0.121716 | K7: =VLOOKUP("label.topGearLimiterRpm",Locale!$A$2:$D$73,4,FALSE) -> 最高挡 / 限转 (rpm) | O7: 8500
B8: =VLOOKUP("label.peakTorqueNm",Locale!$A$2:$D$73,4,FALSE) -> 峰值扭矩 (Nm) | D8: =MAX(Samples!$C$97:$C$111) -> 440.45937 | F8: =VLOOKUP("label.finalDrive",Locale!$A$2:$D$73,4,FALSE) -> 主减速比 | I8: 4.1333333 | K8: =VLOOKUP("label.lightRangeRpm",Locale!$A$2:$D$73,4,FALSE) -> 亮灯范围 (rpm) | O8: 800
B9: =VLOOKUP("label.torquePeakRpm",Locale!$A$2:$D$73,4,FALSE) -> 峰值扭矩转速 (rpm) | D9: =INDEX(Samples!$B$97:$B$111,MATCH(D8,Samples!$C$97:$C$111,0)) -> 4978 | F9: =VLOOKUP("label.gearboxTorqueLoss",Locale!$A$2:$D$73,4,FALSE) -> 变速箱扭矩损失 | I9: 0.011 | K9: =VLOOKUP("label.roundingRpm",Locale!$A$2:$D$73,4,FALSE) -> 取整步长 (rpm) | O9: 10
B11: =VLOOKUP("note.yellowInputs",Locale!$A$2:$D$73,4,FALSE) -> 黄色单元格为手动输入。
B13: =VLOOKUP("label.groupOneTypeATarmac",Locale!$A$2:$D$73,4,FALSE) -> 第 1 组 · Type-A / 柏油 | J13: =VLOOKUP("label.groupTwoTypeBGravel",Locale!$A$2:$D$73,4,FALSE) -> 第 2 组 · Type-B / 砂石
B14: =VLOOKUP("label.gear",Locale!$A$2:$D$73,4,FALSE) -> 挡位 | C14: =VLOOKUP("label.gearRatio",Locale!$A$2:$D$73,4,FALSE) -> 齿比 | D14: =VLOOKUP("label.flashRpmWrap",Locale!$A$2:$D$73,4,FALSE) -> 闪烁 (rpm) | E14: =VLOOKUP("label.afterShiftRpmWrap",Locale!$A$2:$D$73,4,FALSE) -> 换挡后 (rpm) | F14: =VLOOKUP("label.speedKmhMultiline",Locale!$A$2:$D$73,4,FALSE) -> 车速 (km/h) | G14: =VLOOKUP("label.firstLightRpm",Locale!$A$2:$D$73,4,FALSE) -> 首灯亮起 (rpm) | H14: =VLOOKUP("label.trigger",Locale!$A$2:$D$73,4,FALSE) -> 触发条件 | J14: =VLOOKUP("label.gear",Locale!$A$2:$D$73,4,FALSE) -> 挡位 | K14: =VLOOKUP("label.gearRatio",Locale!$A$2:$D$73,4,FALSE) -> 齿比 | L14: =VLOOKUP("label.flashRpmWrap",Locale!$A$2:$D$73,4,FALSE) -> 闪烁 (rpm) | M14: =VLOOKUP("label.afterShiftRpmWrap",Locale!$A$2:$D$73,4,FALSE) -> 换挡后 (rpm) | N14: =VLOOKUP("label.speedKmhMultiline",Locale!$A$2:$D$73,4,FALSE) -> 车速 (km/h) | O14: =VLOOKUP("label.firstLightRpm",Locale!$A$2:$D$73,4,FALSE) -> 首灯亮起 (rpm) | P14: =VLOOKUP("label.trigger",Locale!$A$2:$D$73,4,FALSE) -> 触发条件
B15: 1 | C15: 4.253 | D15: 7550 | E15: =D15*C16/C15 -> 5394.886 | F15: =D15*2*PI()/60*$D$22/(C15*$I$8)*3.6 -> 52.62179 | G15: =MAX(0,D15-$O$8) -> 6750 | H15: =VLOOKUP("label.shift",Locale!$A$2:$D$73,4,FALSE) -> 换挡 | J15: 1 | K15: 3.689 | L15: 7860 | M15: =L15*K16/K15 -> 5382.0439 | N15: =L15*2*PI()/60*$L$22/(K15*$I$8)*3.6 -> 62.963606 | O15: =MAX(0,L15-$O$8) -> 7060 | P15: =VLOOKUP("label.shift",Locale!$A$2:$D$73,4,FALSE) -> 换挡
B16: 2 | C16: 3.039 | D16: 7770 | E16: =D16*C17/C16 -> 5668.3416 | F16: =D16*2*PI()/60*$D$22/(C16*$I$8)*3.6 -> 75.788684 | G16: =MAX(0,D16-$O$8) -> 6970 | H16: =VLOOKUP("label.shift",Locale!$A$2:$D$73,4,FALSE) -> 换挡 | J16: 2 | K16: 2.526 | L16: 7750 | M16: =L16*K17/K16 -> 5807.8979 | N16: =L16*2*PI()/60*$L$22/(K16*$I$8)*3.6 -> 90.665916 | O16: =MAX(0,L16-$O$8) -> 6950 | P16: =VLOOKUP("label.shift",Locale!$A$2:$D$73,4,FALSE) -> 换挡
B17: 3 | C17: 2.217 | D17: 7550 | E17: =D17*C18/C17 -> 5986.8742 | F17: =D17*2*PI()/60*$D$22/(C17*$I$8)*3.6 -> 100.94744 | G17: =MAX(0,D17-$O$8) -> 6750 | H17: =VLOOKUP("label.shift",Locale!$A$2:$D$73,4,FALSE) -> 换挡 | J17: 3 | K17: 1.893 | L17: 7560 | M17: =L17*K18/K17 -> 6054.3899 | N17: =L17*2*PI()/60*$L$22/(K17*$I$8)*3.6 -> 118.01763 | O17: =MAX(0,L17-$O$8) -> 6760 | P17: =VLOOKUP("label.shift",Locale!$A$2:$D$73,4,FALSE) -> 换挡
B18: 4 | C18: 1.758 | D18: 7780 | E18: =D18*C19/C18 -> 5947.8498 | F18: =D18*2*PI()/60*$D$22/(C18*$I$8)*3.6 -> 131.18216 | G18: =MAX(0,D18-$O$8) -> 6980 | H18: =VLOOKUP("label.shift",Locale!$A$2:$D$73,4,FALSE) -> 换挡 | J18: 4 | K18: 1.516 | L18: 7600 | M18: =L18*K19/K18 -> 6126.1214 | N18: =L18*2*PI()/60*$L$22/(K18*$I$8)*3.6 -> 148.14605 | O18: =MAX(0,L18-$O$8) -> 6800 | P18: =VLOOKUP("label.shift",Locale!$A$2:$D$73,4,FALSE) -> 换挡
B19: 5 | C19: 1.344 | D19: =$O$7 -> 8500 | E19: — | F19: =D19*2*PI()/60*$D$22/(C19*$I$8)*3.6 -> 187.47083 | G19: =MAX(0,D19-$O$8) -> 7700 | H19: =VLOOKUP("label.limiter",Locale!$A$2:$D$73,4,FALSE) -> 限转 | J19: 5 | K19: 1.222 | L19: =$O$7 -> 8500 | M19: — | N19: =L19*2*PI()/60*$L$22/(K19*$I$8)*3.6 -> 205.55281 | O19: =MAX(0,L19-$O$8) -> 7700 | P19: =VLOOKUP("label.limiter",Locale!$A$2:$D$73,4,FALSE) -> 限转
B22: =VLOOKUP("label.tyreRadiusM",Locale!$A$2:$D$73,4,FALSE) -> 轮胎半径 (m) | D22: 0.325 | F22: =VLOOKUP("label.wheelInertia",Locale!$A$2:$D$73,4,FALSE) -> 车轮转动惯量 I (kg m²) | H22: 5.4748128 | J22: =VLOOKUP("label.tyreRadiusM",Locale!$A$2:$D$73,4,FALSE) -> 轮胎半径 (m) | L22: 0.324 | N22: =VLOOKUP("label.wheelInertia",Locale!$A$2:$D$73,4,FALSE) -> 车轮转动惯量 I (kg m²) | P22: 5.7898435
B23: =VLOOKUP("label.gearboxFriction",Locale!$A$2:$D$73,4,FALSE) -> 变速箱摩擦阻力 (Nm) | D23: 1.65 | F23: =VLOOKUP("label.gearboxDynamicLoss",Locale!$A$2:$D$73,4,FALSE) -> 变速箱动态阻力 (Nm s) | H23: 0.00078 | J23: =VLOOKUP("label.gearboxFriction",Locale!$A$2:$D$73,4,FALSE) -> 变速箱摩擦阻力 (Nm) | L23: =$D$23 -> 1.65 | N23: =VLOOKUP("label.gearboxDynamicLoss",Locale!$A$2:$D$73,4,FALSE) -> 变速箱动态阻力 (Nm s) | P23: =$H$23 -> 0.00078
B53: =VLOOKUP("label.gearGroup",Locale!$A$2:$D$73,4,FALSE) -> 齿轮组 | D53: 1 | E53: =IF(D53=1,VLOOKUP("label.groupOneTypeATarmac",Locale!$A$2:$D$73,4,FALSE),VLOOKUP("label.groupTwoTypeBGravel",Locale!$A$2:$D$73,4,FALSE)) -> 第 1 组 · Type-A / 柏油

Sheet Rally1
B2: =VLOOKUP("title.rally1GearingShiftLights",Locale!$A$2:$D$73,4,FALSE) -> Rally1 · 齿比与换挡灯
B3: =VLOOKUP("note.rally1Calibration",Locale!$A$2:$D$73,4,FALSE) -> 2022 预测曲线
B5: =VLOOKUP("chart.engineCurve",Locale!$A$2:$D$73,4,FALSE) -> 发动机曲线 | F5: =VLOOKUP("label.calibrationBasis",Locale!$A$2:$D$73,4,FALSE) -> 标定依据 | K5: =VLOOKUP("label.shiftLights",Locale!$A$2:$D$73,4,FALSE) -> 换挡灯
B6: =VLOOKUP("label.peakPowerHp",Locale!$A$2:$D$73,4,FALSE) -> 峰值功率 (hp) | D6: =MAX(Samples!$D$437:$D$451) -> 379.08312 | F6: =VLOOKUP("label.runningMassKg",Locale!$A$2:$D$73,4,FALSE) -> 运行质量 (kg) | I6: 1460 | K6: =VLOOKUP("label.neutralFlashRpm",Locale!$A$2:$D$73,4,FALSE) -> 空挡闪烁 (rpm) | O6: 3000
B7: =VLOOKUP("label.powerPeakRpm",Locale!$A$2:$D$73,4,FALSE) -> 功率峰值转速 (rpm) | D7: =INDEX(Samples!$B$437:$B$451,MATCH(D6,Samples!$D$437:$D$451,0)) -> 6843 | F7: =VLOOKUP("label.engineFlywheelInertia",Locale!$A$2:$D$73,4,FALSE) -> 发动机 + 飞轮转动惯量 (kg m²) | I7: 0.121716 | K7: =VLOOKUP("label.topGearLimiterRpm",Locale!$A$2:$D$73,4,FALSE) -> 最高挡 / 限转 (rpm) | O7: 8500
B8: =VLOOKUP("label.peakTorqueNm",Locale!$A$2:$D$73,4,FALSE) -> 峰值扭矩 (Nm) | D8: =MAX(Samples!$C$437:$C$451) -> 443.46249 | F8: =VLOOKUP("label.finalDrive",Locale!$A$2:$D$73,4,FALSE) -> 主减速比 | I8: 4.1333333 | K8: =VLOOKUP("label.lightRangeRpm",Locale!$A$2:$D$73,4,FALSE) -> 亮灯范围 (rpm) | O8: 800
B9: =VLOOKUP("label.torquePeakRpm",Locale!$A$2:$D$73,4,FALSE) -> 峰值扭矩转速 (rpm) | D9: =INDEX(Samples!$B$437:$B$451,MATCH(D8,Samples!$C$437:$C$451,0)) -> 5189 | F9: =VLOOKUP("label.gearboxTorqueLoss",Locale!$A$2:$D$73,4,FALSE) -> 变速箱扭矩损失 | I9: 0.011 | K9: =VLOOKUP("label.roundingRpm",Locale!$A$2:$D$73,4,FALSE) -> 取整步长 (rpm) | O9: 10
B11: =VLOOKUP("note.yellowInputs",Locale!$A$2:$D$73,4,FALSE) -> 黄色单元格为手动输入。
B13: =VLOOKUP("label.groupOneTypeATarmac",Locale!$A$2:$D$73,4,FALSE) -> 第 1 组 · Type-A / 柏油 | J13: =VLOOKUP("label.groupTwoTypeBGravel",Locale!$A$2:$D$73,4,FALSE) -> 第 2 组 · Type-B / 砂石
B14: =VLOOKUP("label.gear",Locale!$A$2:$D$73,4,FALSE) -> 挡位 | C14: =VLOOKUP("label.gearRatio",Locale!$A$2:$D$73,4,FALSE) -> 齿比 | D14: =VLOOKUP("label.flashRpmWrap",Locale!$A$2:$D$73,4,FALSE) -> 闪烁 (rpm) | E14: =VLOOKUP("label.afterShiftRpmWrap",Locale!$A$2:$D$73,4,FALSE) -> 换挡后 (rpm) | F14: =VLOOKUP("label.speedKmhMultiline",Locale!$A$2:$D$73,4,FALSE) -> 车速 (km/h) | G14: =VLOOKUP("label.firstLightRpm",Locale!$A$2:$D$73,4,FALSE) -> 首灯亮起 (rpm) | H14: =VLOOKUP("label.trigger",Locale!$A$2:$D$73,4,FALSE) -> 触发条件 | J14: =VLOOKUP("label.gear",Locale!$A$2:$D$73,4,FALSE) -> 挡位 | K14: =VLOOKUP("label.gearRatio",Locale!$A$2:$D$73,4,FALSE) -> 齿比 | L14: =VLOOKUP("label.flashRpmWrap",Locale!$A$2:$D$73,4,FALSE) -> 闪烁 (rpm) | M14: =VLOOKUP("label.afterShiftRpmWrap",Locale!$A$2:$D$73,4,FALSE) -> 换挡后 (rpm) | N14: =VLOOKUP("label.speedKmhMultiline",Locale!$A$2:$D$73,4,FALSE) -> 车速 (km/h) | O14: =VLOOKUP("label.firstLightRpm",Locale!$A$2:$D$73,4,FALSE) -> 首灯亮起 (rpm) | P14: =VLOOKUP("label.trigger",Locale!$A$2:$D$73,4,FALSE) -> 触发条件
B15: 1 | C15: 4.253 | D15: 7710 | E15: =D15*C16/C15 -> 5509.2147 | F15: =D15*2*PI()/60*$D$22/(C15*$I$8)*3.6 -> 53.736954 | G15: =MAX(0,D15-$O$8) -> 6910 | H15: =VLOOKUP("label.shift",Locale!$A$2:$D$73,4,FALSE) -> 换挡 | J15: 1 | K15: 3.689 | L15: 8010 | M15: =L15*K16/K15 -> 5484.7547 | N15: =L15*2*PI()/60*$L$22/(K15*$I$8)*3.6 -> 64.165201 | O15: =MAX(0,L15-$O$8) -> 7210 | P15: =VLOOKUP("label.shift",Locale!$A$2:$D$73,4,FALSE) -> 换挡
B16: 2 | C16: 3.039 | D16: 7890 | E16: =D16*C17/C16 -> 5755.8835 | F16: =D16*2*PI()/60*$D$22/(C16*$I$8)*3.6 -> 76.959166 | G16: =MAX(0,D16-$O$8) -> 7090 | H16: =VLOOKUP("label.shift",Locale!$A$2:$D$73,4,FALSE) -> 换挡 | J16: 2 | K16: 2.526 | L16: 7850 | M16: =L16*K17/K16 -> 5882.8385 | N16: =L16*2*PI()/60*$L$22/(K16*$I$8)*3.6 -> 91.835799 | O16: =MAX(0,L16-$O$8) -> 7050 | P16: =VLOOKUP("label.shift",Locale!$A$2:$D$73,4,FALSE) -> 换挡
B17: 3 | C17: 2.217 | D17: 7630 | E17: =D17*C18/C17 -> 6050.3112 | F17: =D17*2*PI()/60*$D$22/(C17*$I$8)*3.6 -> 102.01708 | G17: =MAX(0,D17-$O$8) -> 6830 | H17: =VLOOKUP("label.shift",Locale!$A$2:$D$73,4,FALSE) -> 换挡 | J17: 3 | K17: 1.893 | L17: 7640 | M17: =L17*K18/K17 -> 6118.4575 | N17: =L17*2*PI()/60*$L$22/(K17*$I$8)*3.6 -> 119.26649 | O17: =MAX(0,L17-$O$8) -> 6840 | P17: =VLOOKUP("label.shift",Locale!$A$2:$D$73,4,FALSE) -> 换挡
B18: 4 | C18: 1.758 | D18: 7870 | E18: =D18*C19/C18 -> 6016.6553 | F18: =D18*2*PI()/60*$D$22/(C18*$I$8)*3.6 -> 132.69969 | G18: =MAX(0,D18-$O$8) -> 7070 | H18: =VLOOKUP("label.shift",Locale!$A$2:$D$73,4,FALSE) -> 换挡 | J18: 4 | K18: 1.516 | L18: 7670 | M18: =L18*K19/K18 -> 6182.5462 | N18: =L18*2*PI()/60*$L$22/(K18*$I$8)*3.6 -> 149.51056 | O18: =MAX(0,L18-$O$8) -> 6870 | P18: =VLOOKUP("label.shift",Locale!$A$2:$D$73,4,FALSE) -> 换挡
B19: 5 | C19: 1.344 | D19: =$O$7 -> 8500 | E19: — | F19: =D19*2*PI()/60*$D$22/(C19*$I$8)*3.6 -> 187.47083 | G19: =MAX(0,D19-$O$8) -> 7700 | H19: =VLOOKUP("label.limiter",Locale!$A$2:$D$73,4,FALSE) -> 限转 | J19: 5 | K19: 1.222 | L19: =$O$7 -> 8500 | M19: — | N19: =L19*2*PI()/60*$L$22/(K19*$I$8)*3.6 -> 205.55281 | O19: =MAX(0,L19-$O$8) -> 7700 | P19: =VLOOKUP("label.limiter",Locale!$A$2:$D$73,4,FALSE) -> 限转
B22: =VLOOKUP("label.tyreRadiusM",Locale!$A$2:$D$73,4,FALSE) -> 轮胎半径 (m) | D22: 0.325 | F22: =VLOOKUP("label.wheelInertia",Locale!$A$2:$D$73,4,FALSE) -> 车轮转动惯量 I (kg m²) | H22: 5.4748128 | J22: =VLOOKUP("label.tyreRadiusM",Locale!$A$2:$D$73,4,FALSE) -> 轮胎半径 (m) | L22: 0.324 | N22: =VLOOKUP("label.wheelInertia",Locale!$A$2:$D$73,4,FALSE) -> 车轮转动惯量 I (kg m²) | P22: 5.7898435
B23: =VLOOKUP("label.gearboxFriction",Locale!$A$2:$D$73,4,FALSE) -> 变速箱摩擦阻力 (Nm) | D23: 1.65 | F23: =VLOOKUP("label.gearboxDynamicLoss",Locale!$A$2:$D$73,4,FALSE) -> 变速箱动态阻力 (Nm s) | H23: 0.00078 | J23: =VLOOKUP("label.gearboxFriction",Locale!$A$2:$D$73,4,FALSE) -> 变速箱摩擦阻力 (Nm) | L23: =$D$23 -> 1.65 | N23: =VLOOKUP("label.gearboxDynamicLoss",Locale!$A$2:$D$73,4,FALSE) -> 变速箱动态阻力 (Nm s) | P23: =$H$23 -> 0.00078
B53: =VLOOKUP("label.gearGroup",Locale!$A$2:$D$73,4,FALSE) -> 齿轮组 | D53: 1 | E53: =IF(D53=1,VLOOKUP("label.groupOneTypeATarmac",Locale!$A$2:$D$73,4,FALSE),VLOOKUP("label.groupTwoTypeBGravel",Locale!$A$2:$D$73,4,FALSE)) -> 第 1 组 · Type-A / 柏油

Sheet RX1
B2: =VLOOKUP("title.rx1GearingShiftLights",Locale!$A$2:$D$73,4,FALSE) -> RX1 · 齿比与换挡灯
B5: =VLOOKUP("chart.engineCurve",Locale!$A$2:$D$73,4,FALSE) -> 发动机曲线 | F5: =VLOOKUP("label.calibrationBasis",Locale!$A$2:$D$73,4,FALSE) -> 标定依据 | K5: =VLOOKUP("label.shiftLights",Locale!$A$2:$D$73,4,FALSE) -> 换挡灯
B6: =VLOOKUP("label.peakPowerHp",Locale!$A$2:$D$73,4,FALSE) -> 峰值功率 (hp) | D6: =MAX(Samples!$D$127:$D$141) -> 595.02817 | F6: =VLOOKUP("label.runningMassKg",Locale!$A$2:$D$73,4,FALSE) -> 运行质量 (kg) | I6: 1306 | K6: =VLOOKUP("label.neutralFlashRpm",Locale!$A$2:$D$73,4,FALSE) -> 空挡闪烁 (rpm) | O6: 3000
B7: =VLOOKUP("label.powerPeakRpm",Locale!$A$2:$D$73,4,FALSE) -> 功率峰值转速 (rpm) | D7: =INDEX(Samples!$B$127:$B$141,MATCH(D6,Samples!$D$127:$D$141,0)) -> 5690 | F7: =VLOOKUP("label.engineFlywheelInertia",Locale!$A$2:$D$73,4,FALSE) -> 发动机 + 飞轮转动惯量 (kg m²) | I7: 0.128 | K7: =VLOOKUP("label.topGearLimiterRpm",Locale!$A$2:$D$73,4,FALSE) -> 最高挡 / 限转 (rpm) | O7: 8500
B8: =VLOOKUP("label.peakTorqueNm",Locale!$A$2:$D$73,4,FALSE) -> 峰值扭矩 (Nm) | D8: =MAX(Samples!$C$127:$C$141) -> 849.65874 | F8: =VLOOKUP("label.finalDrive",Locale!$A$2:$D$73,4,FALSE) -> 主减速比 | I8: 4 | K8: =VLOOKUP("label.lightRangeRpm",Locale!$A$2:$D$73,4,FALSE) -> 亮灯范围 (rpm) | O8: 800
B9: =VLOOKUP("label.torquePeakRpm",Locale!$A$2:$D$73,4,FALSE) -> 峰值扭矩转速 (rpm) | D9: =INDEX(Samples!$B$127:$B$141,MATCH(D8,Samples!$C$127:$C$141,0)) -> 4141 | F9: =VLOOKUP("label.gearboxTorqueLoss",Locale!$A$2:$D$73,4,FALSE) -> 变速箱扭矩损失 | I9: 0.012 | K9: =VLOOKUP("label.roundingRpm",Locale!$A$2:$D$73,4,FALSE) -> 取整步长 (rpm) | O9: 10
B11: =VLOOKUP("note.yellowInputs",Locale!$A$2:$D$73,4,FALSE) -> 黄色单元格为手动输入。
B13: =VLOOKUP("label.groupOneRx1",Locale!$A$2:$D$73,4,FALSE) -> 第 1 组 · RX1
B14: =VLOOKUP("label.gear",Locale!$A$2:$D$73,4,FALSE) -> 挡位 | C14: =VLOOKUP("label.gearRatio",Locale!$A$2:$D$73,4,FALSE) -> 齿比 | D14: =VLOOKUP("label.flashRpmWrap",Locale!$A$2:$D$73,4,FALSE) -> 闪烁 (rpm) | E14: =VLOOKUP("label.afterShiftRpmWrap",Locale!$A$2:$D$73,4,FALSE) -> 换挡后 (rpm) | F14: =VLOOKUP("label.speedKmhMultiline",Locale!$A$2:$D$73,4,FALSE) -> 车速 (km/h) | G14: =VLOOKUP("label.firstLightRpm",Locale!$A$2:$D$73,4,FALSE) -> 首灯亮起 (rpm) | H14: =VLOOKUP("label.trigger",Locale!$A$2:$D$73,4,FALSE) -> 触发条件
B15: 1 | C15: 3.24 | D15: 6000 | E15: =D15*C16/C15 -> 4812.963 | F15: =D15*2*PI()/60*$D$22/(C15*$I$8)*3.6 -> 55.850536 | G15: =MAX(0,D15-$O$8) -> 5200 | H15: =VLOOKUP("label.shift",Locale!$A$2:$D$73,4,FALSE) -> 换挡
B16: 2 | C16: 2.599 | D16: 6170 | E16: =D16*C17/C16 -> 4952.1431 | F16: =D16*2*PI()/60*$D$22/(C16*$I$8)*3.6 -> 71.597852 | G16: =MAX(0,D16-$O$8) -> 5370 | H16: =VLOOKUP("label.shift",Locale!$A$2:$D$73,4,FALSE) -> 换挡
B17: 3 | C17: 2.086 | D17: 6220 | E17: =D17*C18/C17 -> 5039.2138 | F17: =D17*2*PI()/60*$D$22/(C17*$I$8)*3.6 -> 89.928466 | G17: =MAX(0,D17-$O$8) -> 5420 | H17: =VLOOKUP("label.shift",Locale!$A$2:$D$73,4,FALSE) -> 换挡
B18: 4 | C18: 1.69 | D18: 6250 | E18: =D18*C19/C18 -> 5110.9467 | F18: =D18*2*PI()/60*$D$22/(C18*$I$8)*3.6 -> 111.53583 | G18: =MAX(0,D18-$O$8) -> 5450 | H18: =VLOOKUP("label.shift",Locale!$A$2:$D$73,4,FALSE) -> 换挡
B19: 5 | C19: 1.382 | D19: 6260 | E19: =D19*C20/C19 -> 5163.8205 | F19: =D19*2*PI()/60*$D$22/(C19*$I$8)*3.6 -> 136.61154 | G19: =MAX(0,D19-$O$8) -> 5460 | H19: =VLOOKUP("label.shift",Locale!$A$2:$D$73,4,FALSE) -> 换挡
B20: 6 | C20: 1.14 | D20: =$O$7 -> 8500 | E20: — | F20: =D20*2*PI()/60*$D$22/(C20*$I$8)*3.6 -> 224.8719 | G20: =MAX(0,D20-$O$8) -> 7700 | H20: =VLOOKUP("label.limiter",Locale!$A$2:$D$73,4,FALSE) -> 限转
B22: =VLOOKUP("label.tyreRadiusM",Locale!$A$2:$D$73,4,FALSE) -> 轮胎半径 (m) | D22: 0.32 | F22: =VLOOKUP("label.wheelInertia",Locale!$A$2:$D$73,4,FALSE) -> 车轮转动惯量 I (kg m²) | H22: 5.2788544
B23: =VLOOKUP("label.gearboxFriction",Locale!$A$2:$D$73,4,FALSE) -> 变速箱摩擦阻力 (Nm) | D23: 1.85 | F23: =VLOOKUP("label.gearboxDynamicLoss",Locale!$A$2:$D$73,4,FALSE) -> 变速箱动态阻力 (Nm s) | H23: 0.00098
B53: =VLOOKUP("label.gearGroup",Locale!$A$2:$D$73,4,FALSE) -> 齿轮组 | D53: 1 | E53: =VLOOKUP("label.groupOneRx1",Locale!$A$2:$D$73,4,FALSE) -> 第 1 组 · RX1

Sheet RX3
B2: =VLOOKUP("title.rx3GearingShiftLights",Locale!$A$2:$D$73,4,FALSE) -> RX3 · 齿比与换挡灯
B3: =VLOOKUP("note.rx1FiveSpeedPlaceholder",Locale!$A$2:$D$73,4,FALSE) -> RX1 占位 · 五挡
B5: =VLOOKUP("chart.engineCurve",Locale!$A$2:$D$73,4,FALSE) -> 发动机曲线 | F5: =VLOOKUP("label.calibrationBasis",Locale!$A$2:$D$73,4,FALSE) -> 标定依据 | K5: =VLOOKUP("label.shiftLights",Locale!$A$2:$D$73,4,FALSE) -> 换挡灯
B6: =VLOOKUP("label.peakPowerHp",Locale!$A$2:$D$73,4,FALSE) -> 峰值功率 (hp) | D6: =MAX(Samples!$D$157:$D$171) -> 595.02817 | F6: =VLOOKUP("label.runningMassKg",Locale!$A$2:$D$73,4,FALSE) -> 运行质量 (kg) | I6: 1306 | K6: =VLOOKUP("label.neutralFlashRpm",Locale!$A$2:$D$73,4,FALSE) -> 空挡闪烁 (rpm) | O6: 3000
B7: =VLOOKUP("label.powerPeakRpm",Locale!$A$2:$D$73,4,FALSE) -> 功率峰值转速 (rpm) | D7: =INDEX(Samples!$B$157:$B$171,MATCH(D6,Samples!$D$157:$D$171,0)) -> 5690 | F7: =VLOOKUP("label.engineFlywheelInertia",Locale!$A$2:$D$73,4,FALSE) -> 发动机 + 飞轮转动惯量 (kg m²) | I7: 0.128 | K7: =VLOOKUP("label.topGearLimiterRpm",Locale!$A$2:$D$73,4,FALSE) -> 最高挡 / 限转 (rpm) | O7: 8500
B8: =VLOOKUP("label.peakTorqueNm",Locale!$A$2:$D$73,4,FALSE) -> 峰值扭矩 (Nm) | D8: =MAX(Samples!$C$157:$C$171) -> 849.65874 | F8: =VLOOKUP("label.finalDrive",Locale!$A$2:$D$73,4,FALSE) -> 主减速比 | I8: 4 | K8: =VLOOKUP("label.lightRangeRpm",Locale!$A$2:$D$73,4,FALSE) -> 亮灯范围 (rpm) | O8: 800
B9: =VLOOKUP("label.torquePeakRpm",Locale!$A$2:$D$73,4,FALSE) -> 峰值扭矩转速 (rpm) | D9: =INDEX(Samples!$B$157:$B$171,MATCH(D8,Samples!$C$157:$C$171,0)) -> 4141 | F9: =VLOOKUP("label.gearboxTorqueLoss",Locale!$A$2:$D$73,4,FALSE) -> 变速箱扭矩损失 | I9: 0.012 | K9: =VLOOKUP("label.roundingRpm",Locale!$A$2:$D$73,4,FALSE) -> 取整步长 (rpm) | O9: 10
B11: =VLOOKUP("note.yellowInputs",Locale!$A$2:$D$73,4,FALSE) -> 黄色单元格为手动输入。
B13: =VLOOKUP("label.groupOneRx1",Locale!$A$2:$D$73,4,FALSE) -> 第 1 组 · RX1
B14: =VLOOKUP("label.gear",Locale!$A$2:$D$73,4,FALSE) -> 挡位 | C14: =VLOOKUP("label.gearRatio",Locale!$A$2:$D$73,4,FALSE) -> 齿比 | D14: =VLOOKUP("label.flashRpmWrap",Locale!$A$2:$D$73,4,FALSE) -> 闪烁 (rpm) | E14: =VLOOKUP("label.afterShiftRpmWrap",Locale!$A$2:$D$73,4,FALSE) -> 换挡后 (rpm) | F14: =VLOOKUP("label.speedKmhMultiline",Locale!$A$2:$D$73,4,FALSE) -> 车速 (km/h) | G14: =VLOOKUP("label.firstLightRpm",Locale!$A$2:$D$73,4,FALSE) -> 首灯亮起 (rpm) | H14: =VLOOKUP("label.trigger",Locale!$A$2:$D$73,4,FALSE) -> 触发条件
B15: 1 | C15: 3.24 | D15: 6000 | E15: =D15*C16/C15 -> 4812.963 | F15: =D15*2*PI()/60*$D$22/(C15*$I$8)*3.6 -> 55.850536 | G15: =MAX(0,D15-$O$8) -> 5200 | H15: =VLOOKUP("label.shift",Locale!$A$2:$D$73,4,FALSE) -> 换挡
B16: 2 | C16: 2.599 | D16: 6170 | E16: =D16*C17/C16 -> 4952.1431 | F16: =D16*2*PI()/60*$D$22/(C16*$I$8)*3.6 -> 71.597852 | G16: =MAX(0,D16-$O$8) -> 5370 | H16: =VLOOKUP("label.shift",Locale!$A$2:$D$73,4,FALSE) -> 换挡
B17: 3 | C17: 2.086 | D17: 6220 | E17: =D17*C18/C17 -> 5039.2138 | F17: =D17*2*PI()/60*$D$22/(C17*$I$8)*3.6 -> 89.928466 | G17: =MAX(0,D17-$O$8) -> 5420 | H17: =VLOOKUP("label.shift",Locale!$A$2:$D$73,4,FALSE) -> 换挡
B18: 4 | C18: 1.69 | D18: 6250 | E18: =D18*C19/C18 -> 5110.9467 | F18: =D18*2*PI()/60*$D$22/(C18*$I$8)*3.6 -> 111.53583 | G18: =MAX(0,D18-$O$8) -> 5450 | H18: =VLOOKUP("label.shift",Locale!$A$2:$D$73,4,FALSE) -> 换挡
B19: 5 | C19: 1.382 | D19: =$O$7 -> 8500 | E19: — | F19: =D19*2*PI()/60*$D$22/(C19*$I$8)*3.6 -> 185.49491 | G19: =MAX(0,D19-$O$8) -> 7700 | H19: =VLOOKUP("label.limiter",Locale!$A$2:$D$73,4,FALSE) -> 限转
B22: =VLOOKUP("label.tyreRadiusM",Locale!$A$2:$D$73,4,FALSE) -> 轮胎半径 (m) | D22: 0.32 | F22: =VLOOKUP("label.wheelInertia",Locale!$A$2:$D$73,4,FALSE) -> 车轮转动惯量 I (kg m²) | H22: 5.2788544
B23: =VLOOKUP("label.gearboxFriction",Locale!$A$2:$D$73,4,FALSE) -> 变速箱摩擦阻力 (Nm) | D23: 1.85 | F23: =VLOOKUP("label.gearboxDynamicLoss",Locale!$A$2:$D$73,4,FALSE) -> 变速箱动态阻力 (Nm s) | H23: 0.00098
B53: =VLOOKUP("label.gearGroup",Locale!$A$2:$D$73,4,FALSE) -> 齿轮组 | D53: 1 | E53: =VLOOKUP("label.groupOneRx1Placeholder",Locale!$A$2:$D$73,4,FALSE) -> 第 1 组 · RX1 占位

Sheet Locale
A1: key | B1: en-US | C1: zh-CN | D1: Active
A2: chart.engineCurve | B2: Engine curve | C2: 发动机曲线 | D2: =IF(Rally2!$E$1="English",B2,C2) -> 发动机曲线
A3: chart.gearPositions | B3: Gear positions | C3: 挡位分布 | D3: =IF(Rally2!$E$1="English",B3,C3) -> 挡位分布
A4: chart.rally1GearPositions | B4: Rally1 · gear position chart | C4: Rally1 · 挡位图 | D4: =IF(Rally2!$E$1="English",B4,C4) -> Rally1 · 挡位图
A5: chart.rally2GearPositions | B5: Rally2 · gear position chart | C5: Rally2 · 挡位图 | D5: =IF(Rally2!$E$1="English",B5,C5) -> Rally2 · 挡位图
A6: chart.rx1GearPositions | B6: RX1 · gear position chart | C6: RX1 · 挡位图 | D6: =IF(Rally2!$E$1="English",B6,C6) -> RX1 · 挡位图
A7: chart.rx3GearPositions | B7: RX3 · gear position chart | C7: RX3 · 挡位图 | D7: =IF(Rally2!$E$1="English",B7,C7) -> RX3 · 挡位图
A8: chart.torqueAndPower | B8: Torque and power | C8: 扭矩与功率 | D8: =IF(Rally2!$E$1="English",B8,C8) -> 扭矩与功率
A9: chart.wrc16GearPositions | B9: WRC16 · gear position chart | C9: WRC16 · 挡位图 | D9: =IF(Rally2!$E$1="English",B9,C9) -> WRC16 · 挡位图
A10: chart.wrc17GearPositions | B10: WRC17 · gear position chart | C10: WRC17 · 挡位图 | D10: =IF(Rally2!$E$1="English",B10,C10) -> WRC17 · 挡位图
A11: label.afterShiftRpm | B11: After (rpm) | C11: 换挡后 (rpm) | D11: =IF(Rally2!$E$1="English",B11,C11) -> 换挡后 (rpm)
A12: label.afterShiftRpmWrap | B12: After shift (rpm) | C12: 换挡后 (rpm) | D12: =IF(Rally2!$E$1="English",B12,C12) -> 换挡后 (rpm)
A13: label.calibrationBasis | B13: Calibration basis | C13: 标定依据 | D13: =IF(Rally2!$E$1="English",B13,C13) -> 标定依据
... A75: chart.25r1GearPositions | B75: 25R1 · gear position chart | C75: 25R1 · 档位图 | D75: =IF(Rally2!$E$1="English",B75,C75) -> 25R1 · 档位图

Sheet Samples
B1: =VLOOKUP("label.engineCurveSamples",Locale!$A$2:$D$73,4,FALSE) -> 发动机曲线采样
B2: =VLOOKUP("note.rpmSampleSpacing",Locale!$A$2:$D$73,4,FALSE) -> 500 rpm 间隔 · 保留峰值点
B5: Rally2
B6: RPM | C6: =VLOOKUP("label.torqueNm",Locale!$A$2:$D$73,4,FALSE) -> 扭矩 (Nm) | D6: =VLOOKUP("label.powerHp",Locale!$A$2:$D$73,4,FALSE) -> 功率 (hp)
B7: 2500 | C7: 393.18991 | D7: =138.04359997421*735.49875/745.69987158227 -> 136.15517
B8: 3000 | C8: 409.57589 | D8: =172.55579164507*735.49875/745.69987158227 -> 170.19524
B9: 3500 | C9: 421.65445 | D9: =207.25195358344*735.49875/745.69987158227 -> 204.41676
B10: 4000 | C10: 425.29867 | D10: =238.90647605524*735.49875/745.69987158227 -> 235.63825
B11: 4157 | C11: 425.46588 | D11: =248.38116946764*735.49875/745.69987158227 -> 244.98333
B12: 4500 | C12: 423.16782 | D12: =267.42318069882*735.49875/745.69987158227 -> 263.76485
B13: 5000 | C13: 409.08668 | D13: =287.24947668298*735.49875/745.69987158227 -> 283.31992
B14: 5275 | C14: 391.32539 | D14: =289.89077243111*735.49875/745.69987158227 -> 285.92509
B15: 5500 | C15: 374.92208 | D15: =289.58603337593*735.49875/745.69987158227 -> 285.62452
B16: 6000 | C16: 341.53645 | D16: =287.78106597026*735.49875/745.69987158227 -> 283.84424
B17: 6500 | C17: 312.76661 | D17: =285.50100817999*735.49875/745.69987158227 -> 281.59537
B18: 7000 | C18: 286.00977 | D18: =281.1595310888*735.49875/745.69987158227 -> 277.31329
B19: 7499 | C19: 259.39156 | D19: =273.17005871031*735.49875/745.69987158227 -> 269.43311
B35: WRC16
B36: RPM | C36: =VLOOKUP("label.torqueNm",Locale!$A$2:$D$73,4,FALSE) -> 扭矩 (Nm) | D36: =VLOOKUP("label.powerHp",Locale!$A$2:$D$73,4,FALSE) -> 功率 (hp)
B37: 2500 | C37: 375.5388 | D37: =131.84653604271*735.49875/745.69987158227 -> 130.04288
B38: 3000 | C38: 393.4743 | D38: =165.77213383362*735.49875/745.69987158227 -> 163.50438
B39: 3500 | C39: 403.52795 | D39: =198.34240038888*735.49875/745.69987158227 -> 195.62909
B40: 4000 | C40: 407.20472 | D40: =228.74241133674*735.49875/745.69987158227 -> 225.61323
B41: 4500 | C41: 409.12826 | D41: =258.55080923323*735.49875/745.69987158227 -> 255.01385
B42: 4715 | C42: 409.34482 | D42: =271.0471857995*735.49875/745.69987158227 -> 267.33928
B43: 5000 | C43: 407.45144 | D43: =286.10125326961*735.49875/745.69987158227 -> 282.18741
B44: 5500 | C44: 392.98684 | D44: =303.53906979173*735.49875/745.69987158227 -> 299.38668
B45: 6000 | C45: 367.2587 | D45: =309.45481801453*735.49875/745.69987158227 -> 305.2215
B46: 6060 | C46: 363.7265 | D46: =309.54334185874*735.49875/745.69987158227 -> 305.30881
B47: 6500 | C47: 335.54735 | D47: =306.29582624471*735.49875/745.69987158227 -> 302.10572
B48: 7000 | C48: 303.45837 | D48: =298.31223803498*735.49875/745.69987158227 -> 294.23135
B49: 7500 | C49: 268.94344 | D49: =283.26709107139*735.49875/745.69987158227 -> 279.39202
B50: 7649 | C50: 256.53471 | D50: =275.56540749578*735.49875/745.69987158227 -> 271.79569
B65: WRC17
B66: RPM | C66: =VLOOKUP("label.torqueNm",Locale!$A$2:$D$73,4,FALSE) -> 扭矩 (Nm) | D66: =VLOOKUP("label.powerHp",Locale!$A$2:$D$73,4,FALSE) -> 功率 (hp)
B67: 2500 | C67: 401.07452 | D67: =140.81177807125*735.49875/745.69987158227 -> 138.88548
B68: 3000 | C68: 420.15433 | D68: =177.01252513491*735.49875/745.69987158227 -> 174.59101
B69: 3500 | C69: 434.59304 | D69: =213.61154136407*735.49875/745.69987158227 -> 210.68935
B70: 4000 | C70: 445.04599 | D70: =249.99929472476*735.49875/745.69987158227 -> 246.57932
B71: 4500 | C71: 449.37292 | D71: =283.98363618441*735.49875/745.69987158227 -> 280.09876
...
