Workbook

Sheet Rally2
B2: Rally2 · Shift lights
B5: Engine curve | F5: Calibration basis | K5: Shift lights
B6: Peak power (hp) | D6: =MAX(Samples!$D$7:$D$24) -> 292.91312 | F6: Running mass (kg) | I6: 1420.59 | K6: Neutral flash (rpm) | O6: 6000
B7: Power peak (rpm) | D7: =INDEX(Samples!$B$7:$B$24,MATCH(D6,Samples!$D$7:$D$24,0)) -> 5610 | F7: Engine + flywheel I (kg m²) | I7: 0.12344 | K7: Top gear / limiter (rpm) | O7: 7500
B8: Peak torque (Nm) | D8: =MAX(Samples!$C$7:$C$24) -> 425.2142 | F8: Final drive | I8: 4.1333333 | K8: Light range (rpm) | O8: 800
B9: Torque peak (rpm) | D9: =INDEX(Samples!$B$7:$B$24,MATCH(D8,Samples!$C$7:$C$24,0)) -> 3740 | F9: Gearbox torque loss | I9: 0.011 | K9: Rounding (rpm) | O9: 10
B11: 黄色单元格为手动输入。
B13: Group 1 · Type-A / Tarmac | J13: Group 2 · Type-B / Gravel
B14: Gear | C14: Ratio | D14: Flash (rpm) | E14: After shift (rpm) | F14: Speed (km/h) | G14: First light (rpm) | H14: Trigger | J14: Gear | K14: Ratio | L14: Flash (rpm) | M14: After shift (rpm) | N14: Speed (km/h) | O14: First light (rpm) | P14: Trigger
B15: 1 | C15: 3.762 | D15: 6250 | E15: =D15*C16/C15 -> 4469.0324 | F15: =D15*2*PI()/60*$D$22/(C15*$I$8)*3.6 -> 49.246489 | G15: =MAX(0,D15-$O$8) -> 5450 | H15: Shift | J15: 1 | K15: 3.365 | L15: 6490 | M15: =L15*K16/K15 -> 4443.6731 | N15: =L15*2*PI()/60*$L$22/(K15*$I$8)*3.6 -> 56.994812 | O15: =MAX(0,L15-$O$8) -> 5690 | P15: Shift
B16: 2 | C16: 2.69 | D16: 6400 | E16: =D16*C17/C16 -> 4665.5762 | F16: =D16*2*PI()/60*$D$22/(C16*$I$8)*3.6 -> 70.524781 | G16: =MAX(0,D16-$O$8) -> 5600 | H16: Shift | J16: 2 | K16: 2.304 | L16: 6270 | M16: =L16*K17/K16 -> 4784.1406 | N16: =L16*2*PI()/60*$L$22/(K16*$I$8)*3.6 -> 80.419388 | O16: =MAX(0,L16-$O$8) -> 5470 | P16: Shift
B17: 3 | C17: 1.961 | D17: 6330 | E17: =D17*C18/C17 -> 4809.6379 | F17: =D17*2*PI()/60*$D$22/(C17*$I$8)*3.6 -> 95.684186 | G17: =MAX(0,D17-$O$8) -> 5530 | H17: Shift | J17: 3 | K17: 1.758 | L17: 6210 | M17: =L17*K18/K17 -> 4885.3413 | N17: =L17*2*PI()/60*$L$22/(K17*$I$8)*3.6 -> 104.38748 | O17: =MAX(0,L17-$O$8) -> 5410 | P17: Shift
B18: 4 | C18: 1.49 | D18: 6190 | E18: =D18*C19/C18 -> 4939.5369 | F18: =D18*2*PI()/60*$D$22/(C18*$I$8)*3.6 -> 123.14547 | G18: =MAX(0,D18-$O$8) -> 5390 | H18: Shift | J18: 4 | K18: 1.383 | L18: 6160 | M18: =L18*K19/K18 -> 4961.851 | N18: =L18*2*PI()/60*$L$22/(K18*$I$8)*3.6 -> 131.62374 | O18: =MAX(0,L18-$O$8) -> 5360 | P18: Shift
B19: 5 | C19: 1.189 | D19: =$O$7 -> 7500 | E19: — | F19: =D19*2*PI()/60*$D$22/(C19*$I$8)*3.6 -> 186.97927 | G19: =MAX(0,D19-$O$8) -> 6700 | H19: Limiter | J19: 5 | K19: 1.114 | L19: =$O$7 -> 7500 | M19: — | N19: =L19*2*PI()/60*$L$22/(K19*$I$8)*3.6 -> 198.95359 | O19: =MAX(0,L19-$O$8) -> 6700 | P19: Limiter
B22: Tyre radius (m) | D22: 0.325 | F22: Wheel I (kg m²) | H22: 5.4748128 | J22: Tyre radius (m) | L22: 0.324 | N22: Wheel I (kg m²) | P22: 5.7898435
B23: GB friction (Nm) | D23: 1.65 | F23: GB dyn. (Nm s) | H23: 0.00078 | J23: GB friction (Nm) | L23: =$D$23 -> 1.65 | N23: GB dyn. (Nm s) | P23: =$H$23 -> 0.00078

Sheet WRC16
B2: WRC16 · Shift lights
B5: Engine curve | F5: Calibration basis | K5: Shift lights
B6: Peak power (hp) | D6: =MAX(Samples!$D$37:$D$55) -> 308.1318 | F6: Running mass (kg) | I6: 1390 | K6: Neutral flash (rpm) | O6: 6350
B7: Power peak (rpm) | D7: =INDEX(Samples!$B$37:$B$55,MATCH(D6,Samples!$D$37:$D$55,0)) -> 5960 | F7: Engine + flywheel I (kg m²) | I7: 0.121716 | K7: Top gear / limiter (rpm) | O7: 7650
B8: Peak torque (Nm) | D8: =MAX(Samples!$C$37:$C$55) -> 409.78853 | F8: Final drive | I8: 4.1333333 | K8: Light range (rpm) | O8: 800
B9: Torque peak (rpm) | D9: =INDEX(Samples!$B$37:$B$55,MATCH(D8,Samples!$C$37:$C$55,0)) -> 4170 | F9: Gearbox torque loss | I9: 0.012 | K9: Rounding (rpm) | O9: 10
B11: 黄色单元格为手动输入。
B13: Group 1 · Type-A / Tarmac | J13: Group 2 · Type-B / Gravel
B14: Gear | C14: Ratio | D14: Flash (rpm) | E14: After shift (rpm) | F14: Speed (km/h) | G14: First light (rpm) | H14: Trigger | J14: Gear | K14: Ratio | L14: Flash (rpm) | M14: After shift (rpm) | N14: Speed (km/h) | O14: First light (rpm) | P14: Trigger
B15: 1 | C15: 3.797 | D15: 6190 | E15: =D15*C16/C15 -> 5037.4243 | F15: =D15*2*PI()/60*$D$22/(C15*$I$8)*3.6 -> 48.324136 | G15: =MAX(0,D15-$O$8) -> 5390 | H15: Shift | J15: 1 | K15: 3.491 | L15: 6290 | M15: =L15*K16/K15 -> 5043.171 | N15: =L15*2*PI()/60*$L$22/(K15*$I$8)*3.6 -> 53.244714 | O15: =MAX(0,L15-$O$8) -> 5490 | P15: Shift
B16: 2 | C16: 3.09 | D16: 6380 | E16: =D16*C17/C16 -> 5118.4531 | F16: =D16*2*PI()/60*$D$22/(C16*$I$8)*3.6 -> 61.203499 | G16: =MAX(0,D16-$O$8) -> 5580 | H16: Shift | J16: 2 | K16: 2.799 | L16: 6420 | M16: =L16*K17/K16 -> 5149.3033 | N16: =L16*2*PI()/60*$L$22/(K16*$I$8)*3.6 -> 67.780978 | O16: =MAX(0,L16-$O$8) -> 5620 | P16: Shift
B17: 3 | C17: 2.479 | D17: 6450 | E17: =D17*C18/C17 -> 5195.9056 | F17: =D17*2*PI()/60*$D$22/(C17*$I$8)*3.6 -> 77.125366 | G17: =MAX(0,D17-$O$8) -> 5650 | H17: Shift | J17: 3 | K17: 2.245 | L17: 6460 | M17: =L17*K18/K17 -> 5234.1826 | N17: =L17*2*PI()/60*$L$22/(K17*$I$8)*3.6 -> 85.033856 | O17: =MAX(0,L17-$O$8) -> 5660 | P17: Shift
B18: 4 | C18: 1.997 | D18: 6500 | E18: =D18*C19/C18 -> 5243.6154 | F18: =D18*2*PI()/60*$D$22/(C18*$I$8)*3.6 -> 96.482676 | G18: =MAX(0,D18-$O$8) -> 5700 | H18: Shift | J18: 4 | K18: 1.819 | L18: 6470 | M18: =L18*K19/K18 -> 5292.6663 | N18: =L18*2*PI()/60*$L$22/(K18*$I$8)*3.6 -> 105.11079 | O18: =MAX(0,L18-$O$8) -> 5670 | P18: Shift
B19: 5 | C19: 1.611 | D19: 6500 | E19: =D19*C20/C19 -> 5309.7455 | F19: =D19*2*PI()/60*$D$22/(C19*$I$8)*3.6 -> 119.60019 | G19: =MAX(0,D19-$O$8) -> 5700 | H19: Shift | J19: 5 | K19: 1.488 | L19: 6480 | M19: =L19*K20/K19 -> 5343.3871 | N19: =L19*2*PI()/60*$L$22/(K19*$I$8)*3.6 -> 128.69088 | O19: =MAX(0,L19-$O$8) -> 5680 | P19: Shift
B20: 6 | C20: 1.316 | D20: =$O$7 -> 7650 | E20: — | F20: =D20*2*PI()/60*$D$22/(C20*$I$8)*3.6 -> 172.31362 | G20: =MAX(0,D20-$O$8) -> 6850 | H20: Limiter | J20: 6 | K20: 1.227 | L20: =$O$7 -> 7650 | M20: — | N20: =L20*2*PI()/60*$L$22/(K20*$I$8)*3.6 -> 184.24367 | O20: =MAX(0,L20-$O$8) -> 6850 | P20: Limiter
B22: Tyre radius (m) | D22: 0.325 | F22: Wheel I (kg m²) | H22: 5.4748128 | J22: Tyre radius (m) | L22: 0.324 | N22: Wheel I (kg m²) | P22: 5.7898435
B23: GB friction (Nm) | D23: 1.85 | F23: GB dyn. (Nm s) | H23: 0.00098 | J23: GB friction (Nm) | L23: =$D$23 -> 1.85 | N23: GB dyn. (Nm s) | P23: =$H$23 -> 0.00098

Sheet WRC17
B2: WRC17 · Shift lights
B5: Engine curve | F5: Calibration basis | K5: Shift lights
B6: Peak power (hp) | D6: =MAX(Samples!$D$67:$D$86) -> 385.29452 | F6: Running mass (kg) | I6: 1391.01 | K6: Neutral flash (rpm) | O6: 7100
B7: Power peak (rpm) | D7: =INDEX(Samples!$B$67:$B$86,MATCH(D6,Samples!$D$67:$D$86,0)) -> 6840 | F7: Engine + flywheel I (kg m²) | I7: 0.121716 | K7: Top gear / limiter (rpm) | O7: 8500
B8: Peak torque (Nm) | D8: =MAX(Samples!$C$67:$C$86) -> 448.2357 | F8: Final drive | I8: 4.4666667 | K8: Light range (rpm) | O8: 800
B9: Torque peak (rpm) | D9: =INDEX(Samples!$B$67:$B$86,MATCH(D8,Samples!$C$67:$C$86,0)) -> 4760 | F9: Gearbox torque loss | I9: 0.012 | K9: Rounding (rpm) | O9: 10
B11: 黄色单元格为手动输入。
B13: Group 1 · Type-A / Tarmac | J13: Group 2 · Type-B / Gravel
B14: Gear | C14: Ratio | D14: Flash (rpm) | E14: After shift (rpm) | F14: Speed (km/h) | G14: First light (rpm) | H14: Trigger | J14: Gear | K14: Ratio | L14: Flash (rpm) | M14: After shift (rpm) | N14: Speed (km/h) | O14: First light (rpm) | P14: Trigger
B15: 1 | C15: 3.515 | D15: 7130 | E15: =D15*C16/C15 -> 5801.3656 | F15: =D15*2*PI()/60*$D$22/(C15*$I$8)*3.6 -> 55.641027 | G15: =MAX(0,D15-$O$8) -> 6330 | H15: Shift | J15: 1 | K15: 3.235 | L15: 7250 | M15: =L15*K16/K15 -> 5815.6878 | N15: =L15*2*PI()/60*$L$22/(K15*$I$8)*3.6 -> 61.285299 | O15: =MAX(0,L15-$O$8) -> 6450 | P15: Shift
B16: 2 | C16: 2.86 | D16: 7370 | E16: =D16*C17/C16 -> 5914.0385 | F16: =D16*2*PI()/60*$D$22/(C16*$I$8)*3.6 -> 70.685835 | G16: =MAX(0,D16-$O$8) -> 6570 | H16: Shift | J16: 2 | K16: 2.595 | L16: 7410 | M16: =L16*K17/K16 -> 5947.9884 | N16: =L16*2*PI()/60*$L$22/(K16*$I$8)*3.6 -> 78.086046 | O16: =MAX(0,L16-$O$8) -> 6610 | P16: Shift
B17: 3 | C17: 2.295 | D17: 7450 | E17: =D17*C18/C17 -> 5998.9542 | F17: =D17*2*PI()/60*$D$22/(C17*$I$8)*3.6 -> 89.043971 | G17: =MAX(0,D17-$O$8) -> 6650 | H17: Shift | J17: 3 | K17: 2.083 | L17: 7460 | M17: =L17*K18/K17 -> 6041.7763 | N17: =L17*2*PI()/60*$L$22/(K17*$I$8)*3.6 -> 97.935951 | O17: =MAX(0,L17-$O$8) -> 6660 | P17: Shift
B18: 4 | C18: 1.848 | D18: 7510 | E18: =D18*C19/C18 -> 6059.2045 | F18: =D18*2*PI()/60*$D$22/(C18*$I$8)*3.6 -> 111.4728 | G18: =MAX(0,D18-$O$8) -> 6710 | H18: Shift | J18: 4 | K18: 1.687 | L18: 7480 | M18: =L18*K19/K18 -> 6118.7908 | N18: =L18*2*PI()/60*$L$22/(K18*$I$8)*3.6 -> 121.24926 | O18: =MAX(0,L18-$O$8) -> 6680 | P18: Shift
B19: 5 | C19: 1.491 | D19: 7500 | E19: =D19*C20/C19 -> 6126.7606 | F19: =D19*2*PI()/60*$D$22/(C19*$I$8)*3.6 -> 137.9795 | G19: =MAX(0,D19-$O$8) -> 6700 | H19: Shift | J19: 5 | K19: 1.38 | L19: 7480 | M19: =L19*K20/K19 -> 6168.2899 | N19: =L19*2*PI()/60*$L$22/(K19*$I$8)*3.6 -> 148.22283 | O19: =MAX(0,L19-$O$8) -> 6680 | P19: Shift
B20: 6 | C20: 1.218 | D20: =$O$7 -> 8500 | E20: — | F20: =D20*2*PI()/60*$D$22/(C20*$I$8)*3.6 -> 191.42673 | G20: =MAX(0,D20-$O$8) -> 7700 | H20: Limiter | J20: 6 | K20: 1.138 | L20: =$O$7 -> 8500 | M20: — | N20: =L20*2*PI()/60*$L$22/(K20*$I$8)*3.6 -> 204.25338 | O20: =MAX(0,L20-$O$8) -> 7700 | P20: Limiter
B22: Tyre radius (m) | D22: 0.325 | F22: Wheel I (kg m²) | H22: 5.4748128 | J22: Tyre radius (m) | L22: 0.324 | N22: Wheel I (kg m²) | P22: 5.7898435
B23: GB friction (Nm) | D23: 1.85 | F23: GB dyn. (Nm s) | H23: 0.00098 | J23: GB friction (Nm) | L23: =$D$23 -> 1.85 | N23: GB dyn. (Nm s) | P23: =$H$23 -> 0.00098

Sheet Rally1
B2: Rally1 · Shift lights
B3: 2025 calibration · shared with 2022
B5: Engine curve | F5: Calibration basis | K5: Shift lights
B6: Peak power (hp) | D6: =MAX(Samples!$D$97:$D$116) -> 374.43649 | F6: Running mass (kg) | I6: 1380 | K6: Neutral flash (rpm) | O6: 7650
B7: Power peak (rpm) | D7: =INDEX(Samples!$B$97:$B$116,MATCH(D6,Samples!$D$97:$D$116,0)) -> 6670 | F7: Engine + flywheel I (kg m²) | I7: 0.121716 | K7: Top gear / limiter (rpm) | O7: 8500
B8: Peak torque (Nm) | D8: =MAX(Samples!$C$97:$C$116) -> 445.97739 | F8: Final drive | I8: 4.1333333 | K8: Light range (rpm) | O8: 800
B9: Torque peak (rpm) | D9: =INDEX(Samples!$B$97:$B$116,MATCH(D8,Samples!$C$97:$C$116,0)) -> 4860 | F9: Gearbox torque loss | I9: 0.011 | K9: Rounding (rpm) | O9: 10
B11: 黄色单元格为手动输入。
B13: Group 1 · Type-A / Tarmac | J13: Group 2 · Type-B / Gravel
B14: Gear | C14: Ratio | D14: Flash (rpm) | E14: After shift (rpm) | F14: Speed (km/h) | G14: First light (rpm) | H14: Trigger | J14: Gear | K14: Ratio | L14: Flash (rpm) | M14: After shift (rpm) | N14: Speed (km/h) | O14: First light (rpm) | P14: Trigger
B15: 1 | C15: 4.253 | D15: 7340 | E15: =D15*C16/C15 -> 5244.8295 | F15: =D15*2*PI()/60*$D$22/(C15*$I$8)*3.6 -> 51.158138 | G15: =MAX(0,D15-$O$8) -> 6540 | H15: Shift | J15: 1 | K15: 3.689 | L15: 7590 | M15: =L15*K16/K15 -> 5197.1645 | N15: =L15*2*PI()/60*$L$22/(K15*$I$8)*3.6 -> 60.800734 | O15: =MAX(0,L15-$O$8) -> 6790 | P15: Shift
B16: 2 | C16: 3.039 | D16: 7520 | E16: =D16*C17/C16 -> 5485.9625 | F16: =D16*2*PI()/60*$D$22/(C16*$I$8)*3.6 -> 73.350181 | G16: =MAX(0,D16-$O$8) -> 6720 | H16: Shift | J16: 2 | K16: 2.526 | L16: 7500 | M16: =L16*K17/K16 -> 5620.5463 | N16: =L16*2*PI()/60*$L$22/(K16*$I$8)*3.6 -> 87.741209 | O16: =MAX(0,L16-$O$8) -> 6700 | P16: Shift
B17: 3 | C17: 2.217 | D17: 7340 | E17: =D17*C18/C17 -> 5820.3518 | F17: =D17*2*PI()/60*$D$22/(C17*$I$8)*3.6 -> 98.13963 | G17: =MAX(0,D17-$O$8) -> 6540 | H17: Shift | J17: 3 | K17: 1.893 | L17: 7340 | M17: =L17*K18/K17 -> 5878.2039 | N17: =L17*2*PI()/60*$L$22/(K17*$I$8)*3.6 -> 114.58325 | O17: =MAX(0,L17-$O$8) -> 6540 | P17: Shift
B18: 4 | C18: 1.758 | D18: 7520 | E18: =D18*C19/C18 -> 5749.0785 | F18: =D18*2*PI()/60*$D$22/(C18*$I$8)*3.6 -> 126.79818 | G18: =MAX(0,D18-$O$8) -> 6720 | H18: Shift | J18: 4 | K18: 1.516 | L18: 7350 | M18: =L18*K19/K18 -> 5924.6042 | N18: =L18*2*PI()/60*$L$22/(K18*$I$8)*3.6 -> 143.27283 | O18: =MAX(0,L18-$O$8) -> 6550 | P18: Shift
B19: 5 | C19: 1.344 | D19: =$O$7 -> 8500 | E19: — | F19: =D19*2*PI()/60*$D$22/(C19*$I$8)*3.6 -> 187.47083 | G19: =MAX(0,D19-$O$8) -> 7700 | H19: Limiter | J19: 5 | K19: 1.222 | L19: =$O$7 -> 8500 | M19: — | N19: =L19*2*PI()/60*$L$22/(K19*$I$8)*3.6 -> 205.55281 | O19: =MAX(0,L19-$O$8) -> 7700 | P19: Limiter
B22: Tyre radius (m) | D22: 0.325 | F22: Wheel I (kg m²) | H22: 5.4748128 | J22: Tyre radius (m) | L22: 0.324 | N22: Wheel I (kg m²) | P22: 5.7898435
B23: GB friction (Nm) | D23: 1.65 | F23: GB dyn. (Nm s) | H23: 0.00078 | J23: GB friction (Nm) | L23: =$D$23 -> 1.65 | N23: GB dyn. (Nm s) | P23: =$H$23 -> 0.00078

Sheet RX1
B2: RX1 · Shift lights
B5: Engine curve | F5: Calibration basis | K5: Shift lights
B6: Peak power (hp) | D6: =MAX(Samples!$D$127:$D$146) -> 603.26802 | F6: Running mass (kg) | I6: 1306 | K6: Neutral flash (rpm) | O6: 6400
B7: Power peak (rpm) | D7: =INDEX(Samples!$B$127:$B$146,MATCH(D6,Samples!$D$127:$D$146,0)) -> 5690 | F7: Engine + flywheel I (kg m²) | I7: 0.128 | K7: Top gear / limiter (rpm) | O7: 8500
B8: Peak torque (Nm) | D8: =MAX(Samples!$C$127:$C$146) -> 849.65873 | F8: Final drive | I8: 4 | K8: Light range (rpm) | O8: 800
B9: Torque peak (rpm) | D9: =INDEX(Samples!$B$127:$B$146,MATCH(D8,Samples!$C$127:$C$146,0)) -> 4140 | F9: Gearbox torque loss | I9: 0.012 | K9: Rounding (rpm) | O9: 10
B11: 黄色单元格为手动输入。
B13: Group 1 · RX1
B14: Gear | C14: Ratio | D14: Flash (rpm) | E14: After shift (rpm) | F14: Speed (km/h) | G14: First light (rpm) | H14: Trigger
B15: 1 | C15: 3.24 | D15: 6000 | E15: =D15*C16/C15 -> 4812.963 | F15: =D15*2*PI()/60*$D$22/(C15*$I$8)*3.6 -> 55.850536 | G15: =MAX(0,D15-$O$8) -> 5200 | H15: Shift
B16: 2 | C16: 2.599 | D16: 6170 | E16: =D16*C17/C16 -> 4952.1431 | F16: =D16*2*PI()/60*$D$22/(C16*$I$8)*3.6 -> 71.597852 | G16: =MAX(0,D16-$O$8) -> 5370 | H16: Shift
B17: 3 | C17: 2.086 | D17: 6220 | E17: =D17*C18/C17 -> 5039.2138 | F17: =D17*2*PI()/60*$D$22/(C17*$I$8)*3.6 -> 89.928466 | G17: =MAX(0,D17-$O$8) -> 5420 | H17: Shift
B18: 4 | C18: 1.69 | D18: 6250 | E18: =D18*C19/C18 -> 5110.9467 | F18: =D18*2*PI()/60*$D$22/(C18*$I$8)*3.6 -> 111.53583 | G18: =MAX(0,D18-$O$8) -> 5450 | H18: Shift
B19: 5 | C19: 1.382 | D19: 6260 | E19: =D19*C20/C19 -> 5163.8205 | F19: =D19*2*PI()/60*$D$22/(C19*$I$8)*3.6 -> 136.61154 | G19: =MAX(0,D19-$O$8) -> 5460 | H19: Shift
B20: 6 | C20: 1.14 | D20: =$O$7 -> 8500 | E20: — | F20: =D20*2*PI()/60*$D$22/(C20*$I$8)*3.6 -> 224.8719 | G20: =MAX(0,D20-$O$8) -> 7700 | H20: Limiter
B22: Tyre radius (m) | D22: 0.32 | F22: Wheel I (kg m²) | H22: 5.2788544
B23: GB friction (Nm) | D23: 1.85 | F23: GB dyn. (Nm s) | H23: 0.00098

Sheet RX3
B2: RX3 · Shift lights
B3: RX1 placeholder · five-speed
B5: Engine curve | F5: Calibration basis | K5: Shift lights
B6: Peak power (hp) | D6: =MAX(Samples!$D$157:$D$176) -> 603.26802 | F6: Running mass (kg) | I6: 1306 | K6: Neutral flash (rpm) | O6: 6400
B7: Power peak (rpm) | D7: =INDEX(Samples!$B$157:$B$176,MATCH(D6,Samples!$D$157:$D$176,0)) -> 5690 | F7: Engine + flywheel I (kg m²) | I7: 0.128 | K7: Top gear / limiter (rpm) | O7: 8500
B8: Peak torque (Nm) | D8: =MAX(Samples!$C$157:$C$176) -> 849.65873 | F8: Final drive | I8: 4 | K8: Light range (rpm) | O8: 800
B9: Torque peak (rpm) | D9: =INDEX(Samples!$B$157:$B$176,MATCH(D8,Samples!$C$157:$C$176,0)) -> 4140 | F9: Gearbox torque loss | I9: 0.012 | K9: Rounding (rpm) | O9: 10
B11: 黄色单元格为手动输入。
B13: Group 1 · RX1
B14: Gear | C14: Ratio | D14: Flash (rpm) | E14: After shift (rpm) | F14: Speed (km/h) | G14: First light (rpm) | H14: Trigger
B15: 1 | C15: 3.24 | D15: 6000 | E15: =D15*C16/C15 -> 4812.963 | F15: =D15*2*PI()/60*$D$22/(C15*$I$8)*3.6 -> 55.850536 | G15: =MAX(0,D15-$O$8) -> 5200 | H15: Shift
B16: 2 | C16: 2.599 | D16: 6170 | E16: =D16*C17/C16 -> 4952.1431 | F16: =D16*2*PI()/60*$D$22/(C16*$I$8)*3.6 -> 71.597852 | G16: =MAX(0,D16-$O$8) -> 5370 | H16: Shift
B17: 3 | C17: 2.086 | D17: 6220 | E17: =D17*C18/C17 -> 5039.2138 | F17: =D17*2*PI()/60*$D$22/(C17*$I$8)*3.6 -> 89.928466 | G17: =MAX(0,D17-$O$8) -> 5420 | H17: Shift
B18: 4 | C18: 1.69 | D18: 6250 | E18: =D18*C19/C18 -> 5110.9467 | F18: =D18*2*PI()/60*$D$22/(C18*$I$8)*3.6 -> 111.53583 | G18: =MAX(0,D18-$O$8) -> 5450 | H18: Shift
B19: 5 | C19: 1.382 | D19: =$O$7 -> 8500 | E19: — | F19: =D19*2*PI()/60*$D$22/(C19*$I$8)*3.6 -> 185.49491 | G19: =MAX(0,D19-$O$8) -> 7700 | H19: Limiter
B22: Tyre radius (m) | D22: 0.32 | F22: Wheel I (kg m²) | H22: 5.2788544
B23: GB friction (Nm) | D23: 1.85 | F23: GB dyn. (Nm s) | H23: 0.00098

Sheet Samples
B1: Engine curve samples
B2: 500 rpm spacing · peak points retained
B5: Rally2
B6: RPM | C6: Torque (Nm) | D6: Power (hp)
B7: 0 | C7: -11.7 | D7: =C7*B7*2*PI()/(60*745.69987158227) -> 0
B8: 500 | C8: 38.00556 | D8: =C8*B8*2*PI()/(60*745.69987158227) -> 2.668589
B9: 1000 | C9: 144.68644 | D9: =C9*B9*2*PI()/(60*745.69987158227) -> 20.318535
B10: 1500 | C10: 295.31453 | D10: =C10*B10*2*PI()/(60*745.69987158227) -> 62.207195
B11: 2000 | C11: 372.03214 | D11: =C11*B11*2*PI()/(60*745.69987158227) -> 104.49007
B12: 2500 | C12: 390.99389 | D12: =C12*B12*2*PI()/(60*745.69987158227) -> 137.26965
B13: 3000 | C13: 411.25037 | D13: =C13*B13*2*PI()/(60*745.69987158227) -> 173.25752
B14: 3500 | C14: 423.80703 | D14: =C14*B14*2*PI()/(60*745.69987158227) -> 208.30551
B15: 3740 | C15: 425.2142 | D15: =C15*B15*2*PI()/(60*745.69987158227) -> 223.32838
B16: 4000 | C16: 424.44212 | D16: =C16*B16*2*PI()/(60*745.69987158227) -> 238.42019
B17: 4500 | C17: 419.64479 | D17: =C17*B17*2*PI()/(60*745.69987158227) -> 265.19107
B18: 5000 | C18: 409.7859 | D18: =C18*B18*2*PI()/(60*745.69987158227) -> 287.73425
... B24: 7499 | C24: 238.59697 | D24: =C24*B24*2*PI()/(60*745.69987158227) -> 251.26548
B35: WRC16
B36: RPM | C36: Torque (Nm) | D36: Power (hp)
B37: 0 | C37: -12.15 | D37: =C37*B37*2*PI()/(60*745.69987158227) -> 0
B38: 500 | C38: 37.607653 | D38: =C38*B38*2*PI()/(60*745.69987158227) -> 2.6406497
B39: 1000 | C39: 141.56102 | D39: =C39*B39*2*PI()/(60*745.69987158227) -> 19.879627
B40: 1500 | C40: 283.07918 | D40: =C40*B40*2*PI()/(60*745.69987158227) -> 59.629854
B41: 2000 | C41: 357.87665 | D41: =C41*B41*2*PI()/(60*745.69987158227) -> 100.51431
B42: 2500 | C42: 375.5388 | D42: =C42*B42*2*PI()/(60*745.69987158227) -> 131.8437
B43: 3000 | C43: 393.4743 | D43: =C43*B43*2*PI()/(60*745.69987158227) -> 165.76856
B44: 3500 | C44: 403.52795 | D44: =C44*B44*2*PI()/(60*745.69987158227) -> 198.33813
B45: 4000 | C45: 409.35787 | D45: =C45*B45*2*PI()/(60*745.69987158227) -> 229.94697
B46: 4170 | C46: 409.78853 | D46: =C46*B46*2*PI()/(60*745.69987158227) -> 239.97191
B47: 4500 | C47: 409.12827 | D47: =C47*B47*2*PI()/(60*745.69987158227) -> 258.54524
B48: 5000 | C48: 407.45144 | D48: =C48*B48*2*PI()/(60*745.69987158227) -> 286.09509
... B55: 7649 | C55: 238.07887 | D55: =C55*B55*2*PI()/(60*745.69987158227) -> 255.73494
B65: WRC17
B66: RPM | C66: Torque (Nm) | D66: Power (hp)
B67: 0 | C67: -12.15 | D67: =C67*B67*2*PI()/(60*745.69987158227) -> 0
B68: 500 | C68: 37.60796 | D68: =C68*B68*2*PI()/(60*745.69987158227) -> 2.6406712
B69: 1000 | C69: 141.03569 | D69: =C69*B69*2*PI()/(60*745.69987158227) -> 19.805854
B70: 1500 | C70: 278.88279 | D70: =C70*B70*2*PI()/(60*745.69987158227) -> 58.745894
B71: 2000 | C71: 377.97203 | D71: =C71*B71*2*PI()/(60*745.69987158227) -> 106.15836
B72: 2500 | C72: 401.07452 | D72: =C72*B72*2*PI()/(60*745.69987158227) -> 140.80875
...
